Workbook
Name Index: 'Muc luc'!$A$1

Sheet Muc luc
A1: DANH SACH CAC SHEET | C1: Ấn vào tên lớp để nhảy ra sheet danh sách | F1: Ấn vào logo VIAGS để trở về mục lục
A2: STT | B2: Lớp học | C2: Ngày học | D2: Địa điểm | E2: Giáo viên
A3: 1 | B3: ='1'!$D$7 -> An toàn hàng không | C3: ='1'!$D$9 -> 0 | D3: ='1'!$D$10 -> TTĐT MB | E3: ='1'!$D$11 -> 0
A4: 2 | B4: ='2'!$D$7 -> Yếu tố con người | C4: ='2'!$D9 -> 0 | D4: ='2'!$D$10 -> TTĐT MB | E4: ='2'!$D$11 -> 0
A5: 3 | B5: ='3'!$D$7 -> Công tác khẩn nguy tại cảng hàng không, sân bay | C5: ='3'!$D9 -> 0 | D5: ='3'!$D$10 -> TTĐT MB | E5: ='3'!$D$11 -> 0
A6: 4 | B6: ='4'!$D$7 -> Pháp luật về hàng không dân dụng | C6: ='4'!$D9 -> 0 | D6: ='4'!$D$10 -> TTĐT MB | E6: ='4'!$D$11 -> 0
A7: 5 | B7: ='5'!$D$7 -> An ninh hàng không dành cho nhân viên phục vụ kỹ thuật thương mại mặt đất của các đơn vị cung cấp dịch vụ hàng không tại cảng hàng không, sân bay | C7: ='5'!$D$9 -> 0 | D7: ='5'!$D$10 -> TTĐT MB | E7: ='5'!$D$11 -> 0
A8: 6 | B8: ='6'!$D$7 -> Hàng nguy hiểm dành cho người thực hiện nhiệm vụ có tiếp xúc trực tiếp với hành khách tại sân bay | C8: ='6'!$D$9 -> 0 | D8: ='6'!$D$10 -> TTĐT MB | E8: ='6'!$D$11 -> 0
A9: 7 | B9: ='7'!$D$7 -> HNH dành cho người chịu trách nhiệm chấp nhận hành lý của hành khách và tổ bay, kiểm soát khu vực cửa khởi hành | C9: ='7'!$D$9 -> 0 | D9: ='7'!$D$10 -> TTĐT MB | E9: ='7'!$D$11 -> 0
A10: 8 | B10: ='8'!$D$7 -> Nghiệp vụ làm thủ tục hành khách QN | C10: ='8'!$D$9 -> 0 | D10: ='8'!$D$10 -> TTĐT MB | E10: ='8'!$D$11 -> 0
A11: 9 | B11: ='9'!$D$7 -> Nghiệp vụ làm thủ tục hành khách Quốc tế | C11: ='9'!$D$9 -> 0 | D11: ='9'!$D$10 -> TTĐT MB | E11: ='9'!$D$11 -> 0
A12: 10 | B12: ='10'!$D$7 -> 0 | C12: ='10'!$D$9 -> 0 | D12: ='10'!$D$10 -> TTĐT MB | E12: ='10'!$D$11 -> 0
A13: 11 | B13: ='11'!$D$7 -> An toàn hàng không | C13: ='11'!$D$9 -> 0 | D13: ='11'!$D$10 -> TTĐT MB | E13: ='11'!$D$11 -> 0
A14: 12 | B14: ='12'!$D$7 -> 0 | C14: ='12'!$D$9 -> 0 | D14: ='12'!$D$10 -> TTĐT MB | E14: ='12'!$D$11 -> 0
A15: 13 | B15: ='13'!$D$7 -> 0 | C15: ='13'!$D$9 -> 0 | D15: ='13'!$D$10 -> TTĐT MB | E15: ='13'!$D$11 -> 0
A16: 14 | B16: ='14'!$D$7 -> 0 | C16: ='14'!$D$9 -> 0 | D16: ='14'!$D$10 -> TTĐT MB | E16: ='14'!$D$11 -> 0
A17: 15 | B17: ='15'!$D$7 -> 0 | C17: ='15'!$D$9 -> 0 | D17: ='15'!$D$10 -> TTĐT MB | E17: ='15'!$D$11 -> 0
A18: 16 | B18: ='16'!$D$7 -> 0 | C18: ='16'!$D$9 -> 0 | D18: ='16'!$D$10 -> TTĐT MB | E18: ='16'!$D$11 -> 0
A19: 17 | B19: ='17'!$D$7 -> 0 | C19: ='17'!$D$9 -> 0 | D19: ='17'!$D$10 -> TTĐT MB | E19: ='17'!$D11 -> 0
A20: 18 | B20: ='18'!$D$7 -> 0 | C20: ='18'!$D$9 -> 0 | D20: ='18'!$D$10 -> TTĐT MB | E20: ='18'!$D$11 -> 0
A21: 19 | B21: ='19'!$D$7 -> 0 | C21: ='19'!$D$9 -> 0 | D21: ='19'!$D$10 -> TTĐT MB | E21: ='19'!$D$11 -> 0
A22: 20 | B22: ='20'!$D$7 -> 0 | C22: ='20'!$D$9 -> 0 | D22: ='20'!$D$10 -> TTĐT MB | E22: ='20'!$D$11 -> 0
A23: 21 | B23: ='21'!$D$7 -> 0 | C23: ='21'!$D$9 -> 0 | D23: ='21'!$D$10 -> TTĐT MB | E23: ='21'!$D$11 -> 0
A24: 22 | B24: ='22'!$D$7 -> 0 | C24: ='22'!$D$9 -> 0 | D24: ='22'!$D$10 -> TTĐT MB | E24: ='22'!$D$11 -> 0
A25: 23 | B25: ='23'!$D$7 -> 0 | C25: ='23'!$D$9 -> 0 | D25: ='23'!$D$10 -> TTĐT MB | E25: ='23'!$D$11 -> 0
A26: 24 | B26: ='24'!$D$7 -> 0 | C26: ='24'!$D$9 -> 0 | D26: ='24'!$D$10 -> TTĐT MB | E26: ='24'!$D$11 -> 0
A27: 25 | B27: ='25'!$D$7 -> 0 | C27: ='25'!$D$9 -> 0 | D27: ='25'!$D$10 -> TTĐT MB | E27: ='25'!$D$11 -> 0
A28: 26 | B28: ='26'!$D$7 -> 0 | C28: ='26'!$D$9 -> 0 | D28: ='26'!$D$10 -> TTĐT MB | E28: ='26'!$D$11 -> 0
A29: 27 | B29: ='27'!$D$7 -> 0 | C29: ='27'!$D$9 -> 0 | D29: ='27'!$D$10 -> TTĐT MB | E29: ='27'!$D$11 -> 0
A30: 28 | B30: ='28'!$D$7 -> 0 | C30: ='28'!$D$9 -> 0 | D30: ='28'!$D$10 -> TTĐT MB | E30: ='28'!$D$11 -> 0
A31: 29 | B31: ='29'!$D$7 -> 0 | C31: ='29'!$D$9 -> 0 | D31: ='29'!$D$10 -> TTĐT MB | E31: ='29'!$D$11 -> 0
A32: 30 | B32: ='30'!$D$7 -> 0 | C32: ='30'!$D$9 -> 0 | D32: ='30'!$D$10 -> TTĐT MB | E32: ='30'!$D$11 -> 0
A33: 31 | B33: ='31'!$D$7 -> 0 | C33: ='31'!$D$9 -> 0 | D33: ='31'!$D$10 -> TTĐT MB | E33: ='31'!$D$11 -> 0
A34: 32 | B34: ='32'!$D$7 -> 0 | C34: ='32'!$D$9 -> 0 | D34: ='32'!$D$10 -> TTĐT MB | E34: ='32'!$D$11 -> 0
A35: 33 | B35: ='33'!$D$7 -> 0 | C35: ='33'!$D$9 -> 0 | D35: ='33'!$D$10 -> TTĐT MB | E35: ='33'!$D$11 -> 0
A36: 34 | B36: ='34'!$D$7 -> 0 | C36: ='34'!$D$9 -> 0 | D36: ='34'!$D$10 -> TTĐT MB | E36: ='34'!$D$11 -> 0
A37: 35 | B37: ='35'!$D$7 -> 0 | C37: ='35'!$D$9 -> 0 | D37: ='35'!$D$10 -> TTĐT MB | E37: ='35'!$D$11 -> 0
A38: 36 | B38: ='36'!$D$7 -> 0 | C38: ='36'!$D$9 -> 0 | D38: ='36'!$D$10 -> TTĐT MB | E38: ='36'!$D$11 -> 0
A39: 37 | B39: ='37'!$D$7 -> 0 | C39: ='37'!$D$9 -> 0 | D39: ='37'!$D$10 -> TTĐT MB | E39: ='37'!$D$11 -> 0
A40: 38 | B40: ='38'!$D$7 -> 0 | C40: ='38'!$D$9 -> 0 | D40: ='38'!$D$10 -> TTĐT MB | E40: ='38'!$D$11 -> 0
...

Sheet 1
E2: DANH SÁCH HỌC VIÊN | J2: Biểu mẫu | N2: Mã số: V.TMM-F10 | S2: Biểu mẫu | W2: Mã số: V.TMM-F05a
J3: ĐIỂM DANH HỌC VIÊN | N3: Ban hành: 04 | S3: KẾT QUẢ ĐÀO TẠO | W3: Ban hành: 04
N4: Hiệu lực: 28/12/2024 | W4: Hiệu lực: 28/12/2024
N5: Trang: 1/1 | W5: Trang: 1/1
B7: - Môn/Khóa học: | D7: An toàn hàng không | G7: - Môn/Khóa học: | I7: =D7 -> An toàn hàng không | P7: - Môn/Khóa học: | R7: =I7 -> An toàn hàng không | Y7: Xóa bớt HV bằng cách xóa cả dòng
B8: - Loại hình/hình thức đào tạo: Phục hồi/Trực tiếp | G8: =B8 -> - Loại hình/hình thức đào tạo: Phục hồi/Trực tiếp | P8: =G8 -> - Loại hình/hình thức đào tạo: Phục hồi/Trực tiếp | Y8: Thêm HV bằng cách copy cả dòng-->bấm phải chuột-->insert copied cells
B9: - Thời gian: | G9: =B9 -> - Thời gian: | I9: =D9 -> 0 | P9: =G9 -> - Thời gian: | R9: =I9 -> 0 | Y9: Điểm trung bình xếp loại, ghi chú, số học viên tham dự tự động điền sau khi nhập điểm LT, TH
B10: - Địa điểm: | D10: TTĐT MB | G10: =B10 -> - Địa điểm: | I10: =D10 -> TTĐT MB | P10: =G10 -> - Địa điểm: | R10: =I10 -> TTĐT MB | Y10: Bôi tất cả các dòng có HV-->Custom Sort theo cột V, cột W
B11: - Giáo viên: | G11: - Số học viên tham dự/tổng số học viên: | K11: =COUNTIF($L$14:$L43,"x")&"/"&COUNTA($L$14:$L43) -> 0/0 | P11: =G11 -> - Số học viên tham dự/tổng số học viên: | T11: =K11 -> 0/0 | Y11: Nhập điểm các lần thi ở đây
B12: STT | C12: Mã NV | D12: Họ tên | E12: Đơn vị | F12: Ghi chú | G12: STT | H12: Mã nhân viên | I12: Họ tên | K12: Đơn vị | L12: Ngày | M12: Ngày | N12: Ngày | O12: Ghi chú | P12: STT | Q12: Mã nhân viên | R12: Họ tên | T12: Đơn vị | U12: Điểm | V12: Xếp loại | W12: Ghi chú | Y12: L1 | Z12: L2 | AA12: L3
L13: =I9 -> 0
B14: =ROW()-13 -> 1 | G14: =B14 -> 1 | H14: =C14 -> 0 | I14: =D14 -> 0 | K14: =E14 -> 0 | P14: =$B14 -> 1 | Q14: =C14 -> 0 | R14: =D14 -> 0 | T14: =E14 -> 0 | U14: =IF($Y14=0,"-",IF(ISBLANK($AA14),IF(ISBLANK($Z14),$Y14,$Y14&"/"&$Z14),$Y14&"/"&$Z14&"/"&$AA14)) -> - | V14: =IF($Y14=0,"-",IF(AND($Y14<80,$Z14<80,$AA14<80),"Không đạt",IF($Y14<95,"Đạt","Xuất sắc"))) -> - | W14: =IF($Y14=0,"Vắng",IF($AA14<>0,"Kiểm tra lần 1/2/3",IF($Z14<>0,"Kiểm tra lần 1/2",""))) -> Vắng
B15: =ROW()-13 -> 2 | G15: =B15 -> 2 | H15: =C15 -> 0 | I15: =D15 -> 0 | K15: =E15 -> 0 | P15: =$B15 -> 2 | Q15: =C15 -> 0 | R15: =D15 -> 0 | T15: =E15 -> 0 | U15: =IF($Y15=0,"-",IF(ISBLANK($AA15),IF(ISBLANK($Z15),$Y15,$Y15&"/"&$Z15),$Y15&"/"&$Z15&"/"&$AA15)) -> - | V15: =IF($Y15=0,"-",IF(AND($Y15<80,$Z15<80,$AA15<80),"Không đạt",IF($Y15<95,"Đạt","Xuất sắc"))) -> - | W15: =IF($Y15=0,"Vắng",IF($AA15<>0,"Kiểm tra lần 1/2/3",IF($Z15<>0,"Kiểm tra lần 1/2",""))) -> Vắng
B16: =ROW()-13 -> 3 | G16: =B16 -> 3 | H16: =C16 -> 0 | I16: =D16 -> 0 | K16: =E16 -> 0 | P16: =$B16 -> 3 | Q16: =C16 -> 0 | R16: =D16 -> 0 | T16: =E16 -> 0 | U16: =IF($Y16=0,"-",IF(ISBLANK($AA16),IF(ISBLANK($Z16),$Y16,$Y16&"/"&$Z16),$Y16&"/"&$Z16&"/"&$AA16)) -> - | V16: =IF($Y16=0,"-",IF(AND($Y16<80,$Z16<80,$AA16<80),"Không đạt",IF($Y16<95,"Đạt","Xuất sắc"))) -> - | W16: =IF($Y16=0,"Vắng",IF($AA16<>0,"Kiểm tra lần 1/2/3",IF($Z16<>0,"Kiểm tra lần 1/2",""))) -> Vắng
B17: =ROW()-13 -> 4 | G17: =B17 -> 4 | H17: =C17 -> 0 | I17: =D17 -> 0 | K17: =E17 -> 0 | P17: =$B17 -> 4 | Q17: =C17 -> 0 | R17: =D17 -> 0 | T17: =E17 -> 0 | U17: =IF($Y17=0,"-",IF(ISBLANK($AA17),IF(ISBLANK($Z17),$Y17,$Y17&"/"&$Z17),$Y17&"/"&$Z17&"/"&$AA17)) -> - | V17: =IF($Y17=0,"-",IF(AND($Y17<80,$Z17<80,$AA17<80),"Không đạt",IF($Y17<95,"Đạt","Xuất sắc"))) -> - | W17: =IF($Y17=0,"Vắng",IF($AA17<>0,"Kiểm tra lần 1/2/3",IF($Z17<>0,"Kiểm tra lần 1/2",""))) -> Vắng
B18: =ROW()-13 -> 5 | G18: =B18 -> 5 | H18: =C18 -> 0 | I18: =D18 -> 0 | K18: =E18 -> 0 | P18: =$B18 -> 5 | Q18: =C18 -> 0 | R18: =D18 -> 0 | T18: =E18 -> 0 | U18: =IF($Y18=0,"-",IF(ISBLANK($AA18),IF(ISBLANK($Z18),$Y18,$Y18&"/"&$Z18),$Y18&"/"&$Z18&"/"&$AA18)) -> - | V18: =IF($Y18=0,"-",IF(AND($Y18<80,$Z18<80,$AA18<80),"Không đạt",IF($Y18<95,"Đạt","Xuất sắc"))) -> - | W18: =IF($Y18=0,"Vắng",IF($AA18<>0,"Kiểm tra lần 1/2/3",IF($Z18<>0,"Kiểm tra lần 1/2",""))) -> Vắng
B19: =ROW()-13 -> 6 | G19: =B19 -> 6 | H19: =C19 -> 0 | I19: =D19 -> 0 | K19: =E19 -> 0 | P19: =$B19 -> 6 | Q19: =C19 -> 0 | R19: =D19 -> 0 | T19: =E19 -> 0 | U19: =IF($Y19=0,"-",IF(ISBLANK($AA19),IF(ISBLANK($Z19),$Y19,$Y19&"/"&$Z19),$Y19&"/"&$Z19&"/"&$AA19)) -> - | V19: =IF($Y19=0,"-",IF(AND($Y19<80,$Z19<80,$AA19<80),"Không đạt",IF($Y19<95,"Đạt","Xuất sắc"))) -> - | W19: =IF($Y19=0,"Vắng",IF($AA19<>0,"Kiểm tra lần 1/2/3",IF($Z19<>0,"Kiểm tra lần 1/2",""))) -> Vắng
B20: =ROW()-13 -> 7 | G20: =B20 -> 7 | H20: =C20 -> 0 | I20: =D20 -> 0 | K20: =E20 -> 0 | P20: =$B20 -> 7 | Q20: =C20 -> 0 | R20: =D20 -> 0 | T20: =E20 -> 0 | U20: =IF($Y20=0,"-",IF(ISBLANK($AA20),IF(ISBLANK($Z20),$Y20,$Y20&"/"&$Z20),$Y20&"/"&$Z20&"/"&$AA20)) -> - | V20: =IF($Y20=0,"-",IF(AND($Y20<80,$Z20<80,$AA20<80),"Không đạt",IF($Y20<95,"Đạt","Xuất sắc"))) -> - | W20: =IF($Y20=0,"Vắng",IF($AA20<>0,"Kiểm tra lần 1/2/3",IF($Z20<>0,"Kiểm tra lần 1/2",""))) -> Vắng
B21: =ROW()-13 -> 8 | G21: =B21 -> 8 | H21: =C21 -> 0 | I21: =D21 -> 0 | K21: =E21 -> 0 | P21: =$B21 -> 8 | Q21: =C21 -> 0 | R21: =D21 -> 0 | T21: =E21 -> 0 | U21: =IF($Y21=0,"-",IF(ISBLANK($AA21),IF(ISBLANK($Z21),$Y21,$Y21&"/"&$Z21),$Y21&"/"&$Z21&"/"&$AA21)) -> - | V21: =IF($Y21=0,"-",IF(AND($Y21<80,$Z21<80,$AA21<80),"Không đạt",IF($Y21<95,"Đạt","Xuất sắc"))) -> - | W21: =IF($Y21=0,"Vắng",IF($AA21<>0,"Kiểm tra lần 1/2/3",IF($Z21<>0,"Kiểm tra lần 1/2",""))) -> Vắng
B22: =ROW()-13 -> 9 | G22: =B22 -> 9 | H22: =C22 -> 0 | I22: =D22 -> 0 | K22: =E22 -> 0 | P22: =$B22 -> 9 | Q22: =C22 -> 0 | R22: =D22 -> 0 | T22: =E22 -> 0 | U22: =IF($Y22=0,"-",IF(ISBLANK($AA22),IF(ISBLANK($Z22),$Y22,$Y22&"/"&$Z22),$Y22&"/"&$Z22&"/"&$AA22)) -> - | V22: =IF($Y22=0,"-",IF(AND($Y22<80,$Z22<80,$AA22<80),"Không đạt",IF($Y22<95,"Đạt","Xuất sắc"))) -> - | W22: =IF($Y22=0,"Vắng",IF($AA22<>0,"Kiểm tra lần 1/2/3",IF($Z22<>0,"Kiểm tra lần 1/2",""))) -> Vắng
B23: =ROW()-13 -> 10 | G23: =B23 -> 10 | H23: =C23 -> 0 | I23: =D23 -> 0 | K23: =E23 -> 0 | P23: =$B23 -> 10 | Q23: =C23 -> 0 | R23: =D23 -> 0 | T23: =E23 -> 0 | U23: =IF($Y23=0,"-",IF(ISBLANK($AA23),IF(ISBLANK($Z23),$Y23,$Y23&"/"&$Z23),$Y23&"/"&$Z23&"/"&$AA23)) -> - | V23: =IF($Y23=0,"-",IF(AND($Y23<80,$Z23<80,$AA23<80),"Không đạt",IF($Y23<95,"Đạt","Xuất sắc"))) -> - | W23: =IF($Y23=0,"Vắng",IF($AA23<>0,"Kiểm tra lần 1/2/3",IF($Z23<>0,"Kiểm tra lần 1/2",""))) -> Vắng
B24: =ROW()-13 -> 11 | G24: =B24 -> 11 | H24: =C24 -> 0 | I24: =D24 -> 0 | K24: =E24 -> 0 | P24: =$B24 -> 11 | Q24: =C24 -> 0 | R24: =D24 -> 0 | T24: =E24 -> 0 | U24: =IF($Y24=0,"-",IF(ISBLANK($AA24),IF(ISBLANK($Z24),$Y24,$Y24&"/"&$Z24),$Y24&"/"&$Z24&"/"&$AA24)) -> - | V24: =IF($Y24=0,"-",IF(AND($Y24<80,$Z24<80,$AA24<80),"Không đạt",IF($Y24<95,"Đạt","Xuất sắc"))) -> - | W24: =IF($Y24=0,"Vắng",IF($AA24<>0,"Kiểm tra lần 1/2/3",IF($Z24<>0,"Kiểm tra lần 1/2",""))) -> Vắng
B25: =ROW()-13 -> 12 | G25: =B25 -> 12 | H25: =C25 -> 0 | I25: =D25 -> 0 | K25: =E25 -> 0 | P25: =$B25 -> 12 | Q25: =C25 -> 0 | R25: =D25 -> 0 | T25: =E25 -> 0 | U25: =IF($Y25=0,"-",IF(ISBLANK($AA25),IF(ISBLANK($Z25),$Y25,$Y25&"/"&$Z25),$Y25&"/"&$Z25&"/"&$AA25)) -> - | V25: =IF($Y25=0,"-",IF(AND($Y25<80,$Z25<80,$AA25<80),"Không đạt",IF($Y25<95,"Đạt","Xuất sắc"))) -> - | W25: =IF($Y25=0,"Vắng",IF($AA25<>0,"Kiểm tra lần 1/2/3",IF($Z25<>0,"Kiểm tra lần 1/2",""))) -> Vắng
... B29: =ROW()-13 -> 16 | G29: =B29 -> 16 | H29: =C29 -> 0 | I29: =D29 -> 0 | K29: =E29 -> 0 | P29: =$B29 -> 16 | Q29: =C29 -> 0 | R29: =D29 -> 0 | T29: =E29 -> 0 | U29: =IF($Y29=0,"-",IF(ISBLANK($AA29),IF(ISBLANK($Z29),$Y29,$Y29&"/"&$Z29),$Y29&"/"&$Z29&"/"&$AA29)) -> - | V29: =IF($Y29=0,"-",IF(AND($Y29<80,$Z29<80,$AA29<80),"Không đạt",IF($Y29<95,"Đạt","Xuất sắc"))) -> - | W29: =IF($Y29=0,"Vắng",IF($AA29<>0,"Kiểm tra lần 1/2/3",IF($Z29<>0,"Kiểm tra lần 1/2",""))) -> Vắng
C30: Trưởng Trung tâm đào tạo | F30: Người lập | H30: Chữ ký giáo viên: | P30: Giáo viên hướng dẫn: | S30: Trưởng bộ môn: | V30: Trưởng TTĐT:
G32: Lưu ý:
G33: - Giáo viên điểm danh theo ngày và đánh dấu: X: có mặt; V: vắng mặt
C34: Nguyễn Chí Kiên | F34: Nguyễn Cao Bình | G34: - Trang thiết bị thực hành (áp dụng đối với nội dung thực hành Nghiệp vụ điều khiển/vận hành thiết bị): | P34: Họ tên: | S34: Họ tên: | V34: Họ tên: Nguyễn Chí Kiên
G35: …………………………………………………………………………………............................................ | P35: Ngày: | S35: Ngày: | V35: Ngày :

Sheet 2
E2: DANH SÁCH HỌC VIÊN | J2: Biểu mẫu | N2: Mã số: V.TMM-F10 | S2: Biểu mẫu | W2: Mã số: V.TMM-F05a
J3: ĐIỂM DANH HỌC VIÊN | N3: Ban hành: 04 | S3: KẾT QUẢ ĐÀO TẠO | W3: Ban hành: 04
N4: Hiệu lực: 28/12/2024 | W4: Hiệu lực: 28/12/2024
N5: Trang: 1/1 | W5: Trang: 1/1
B7: - Môn/Khóa học: | D7: Yếu tố con người | G7: - Môn/Khóa học: | I7: =D7 -> Yếu tố con người | P7: - Môn/Khóa học: | R7: =I7 -> Yếu tố con người | Y7: Xóa bớt HV bằng cách xóa cả dòng
B8: - Loại hình/hình thức đào tạo: Phục hồi/Trực tiếp | G8: =B8 -> - Loại hình/hình thức đào tạo: Phục hồi/Trực tiếp | P8: =G8 -> - Loại hình/hình thức đào tạo: Phục hồi/Trực tiếp | Y8: Thêm HV bằng cách copy cả dòng-->bấm phải chuột-->insert copied cells
B9: - Thời gian: | G9: =B9 -> - Thời gian: | I9: =D9 -> 0 | P9: =G9 -> - Thời gian: | R9: =I9 -> 0 | Y9: Điểm trung bình xếp loại, ghi chú, số học viên tham dự tự động điền sau khi nhập điểm LT, TH
B10: - Địa điểm: | D10: TTĐT MB | G10: =B10 -> - Địa điểm: | I10: =D10 -> TTĐT MB | P10: =G10 -> - Địa điểm: | R10: =I10 -> TTĐT MB | Y10: Bôi tất cả các dòng có HV-->Custom Sort theo cột V, cột W
B11: - Giáo viên: | G11: - Số học viên tham dự/tổng số học viên: | K11: =COUNTIF($L$14:$L43,"x")&"/"&COUNTA($L$14:$L43) -> 0/0 | P11: =G11 -> - Số học viên tham dự/tổng số học viên: | T11: =K11 -> 0/0 | Y11: Nhập điểm các lần thi ở đây
B12: STT | C12: Mã NV | D12: Họ tên | E12: Đơn vị | F12: Ghi chú | G12: STT | H12: Mã nhân viên | I12: Họ tên | K12: Đơn vị | L12: Ngày | M12: Ngày | N12: Ngày | O12: Ghi chú | P12: STT | Q12: Mã nhân viên | R12: Họ tên | T12: Đơn vị | U12: Điểm | V12: Xếp loại | W12: Ghi chú | Y12: L1 | Z12: L2 | AA12: L3
L13: =I9 -> 0
B14: =ROW()-13 -> 1 | G14: =B14 -> 1 | H14: =C14 -> 0 | I14: =D14 -> 0 | K14: =E14 -> 0 | P14: =$B14 -> 1 | Q14: =C14 -> 0 | R14: =D14 -> 0 | T14: =E14 -> 0 | U14: =IF($Y14=0,"-",IF(ISBLANK($AA14),IF(ISBLANK($Z14),$Y14,$Y14&"/"&$Z14),$Y14&"/"&$Z14&"/"&$AA14)) -> - | V14: =IF($Y14=0,"-",IF(AND($Y14<80,$Z14<80,$AA14<80),"Không đạt",IF($Y14<95,"Đạt","Xuất sắc"))) -> - | W14: =IF($Y14=0,"Vắng",IF($AA14<>0,"Kiểm tra lần 1/2/3",IF($Z14<>0,"Kiểm tra lần 1/2",""))) -> Vắng
B15: =ROW()-13 -> 2 | G15: =B15 -> 2 | H15: =C15 -> 0 | I15: =D15 -> 0 | K15: =E15 -> 0 | P15: =$B15 -> 2 | Q15: =C15 -> 0 | R15: =D15 -> 0 | T15: =E15 -> 0 | U15: =IF($Y15=0,"-",IF(ISBLANK($AA15),IF(ISBLANK($Z15),$Y15,$Y15&"/"&$Z15),$Y15&"/"&$Z15&"/"&$AA15)) -> - | V15: =IF($Y15=0,"-",IF(AND($Y15<80,$Z15<80,$AA15<80),"Không đạt",IF($Y15<95,"Đạt","Xuất sắc"))) -> - | W15: =IF($Y15=0,"Vắng",IF($AA15<>0,"Kiểm tra lần 1/2/3",IF($Z15<>0,"Kiểm tra lần 1/2",""))) -> Vắng
B16: =ROW()-13 -> 3 | G16: =B16 -> 3 | H16: =C16 -> 0 | I16: =D16 -> 0 | K16: =E16 -> 0 | P16: =$B16 -> 3 | Q16: =C16 -> 0 | R16: =D16 -> 0 | T16: =E16 -> 0 | U16: =IF($Y16=0,"-",IF(ISBLANK($AA16),IF(ISBLANK($Z16),$Y16,$Y16&"/"&$Z16),$Y16&"/"&$Z16&"/"&$AA16)) -> - | V16: =IF($Y16=0,"-",IF(AND($Y16<80,$Z16<80,$AA16<80),"Không đạt",IF($Y16<95,"Đạt","Xuất sắc"))) -> - | W16: =IF($Y16=0,"Vắng",IF($AA16<>0,"Kiểm tra lần 1/2/3",IF($Z16<>0,"Kiểm tra lần 1/2",""))) -> Vắng
B17: =ROW()-13 -> 4 | G17: =B17 -> 4 | H17: =C17 -> 0 | I17: =D17 -> 0 | K17: =E17 -> 0 | P17: =$B17 -> 4 | Q17: =C17 -> 0 | R17: =D17 -> 0 | T17: =E17 -> 0 | U17: =IF($Y17=0,"-",IF(ISBLANK($AA17),IF(ISBLANK($Z17),$Y17,$Y17&"/"&$Z17),$Y17&"/"&$Z17&"/"&$AA17)) -> - | V17: =IF($Y17=0,"-",IF(AND($Y17<80,$Z17<80,$AA17<80),"Không đạt",IF($Y17<95,"Đạt","Xuất sắc"))) -> - | W17: =IF($Y17=0,"Vắng",IF($AA17<>0,"Kiểm tra lần 1/2/3",IF($Z17<>0,"Kiểm tra lần 1/2",""))) -> Vắng
B18: =ROW()-13 -> 5 | G18: =B18 -> 5 | H18: =C18 -> 0 | I18: =D18 -> 0 | K18: =E18 -> 0 | P18: =$B18 -> 5 | Q18: =C18 -> 0 | R18: =D18 -> 0 | T18: =E18 -> 0 | U18: =IF($Y18=0,"-",IF(ISBLANK($AA18),IF(ISBLANK($Z18),$Y18,$Y18&"/"&$Z18),$Y18&"/"&$Z18&"/"&$AA18)) -> - | V18: =IF($Y18=0,"-",IF(AND($Y18<80,$Z18<80,$AA18<80),"Không đạt",IF($Y18<95,"Đạt","Xuất sắc"))) -> - | W18: =IF($Y18=0,"Vắng",IF($AA18<>0,"Kiểm tra lần 1/2/3",IF($Z18<>0,"Kiểm tra lần 1/2",""))) -> Vắng
B19: =ROW()-13 -> 6 | G19: =B19 -> 6 | H19: =C19 -> 0 | I19: =D19 -> 0 | K19: =E19 -> 0 | P19: =$B19 -> 6 | Q19: =C19 -> 0 | R19: =D19 -> 0 | T19: =E19 -> 0 | U19: =IF($Y19=0,"-",IF(ISBLANK($AA19),IF(ISBLANK($Z19),$Y19,$Y19&"/"&$Z19),$Y19&"/"&$Z19&"/"&$AA19)) -> - | V19: =IF($Y19=0,"-",IF(AND($Y19<80,$Z19<80,$AA19<80),"Không đạt",IF($Y19<95,"Đạt","Xuất sắc"))) -> - | W19: =IF($Y19=0,"Vắng",IF($AA19<>0,"Kiểm tra lần 1/2/3",IF($Z19<>0,"Kiểm tra lần 1/2",""))) -> Vắng
B20: =ROW()-13 -> 7 | G20: =B20 -> 7 | H20: =C20 -> 0 | I20: =D20 -> 0 | K20: =E20 -> 0 | P20: =$B20 -> 7 | Q20: =C20 -> 0 | R20: =D20 -> 0 | T20: =E20 -> 0 | U20: =IF($Y20=0,"-",IF(ISBLANK($AA20),IF(ISBLANK($Z20),$Y20,$Y20&"/"&$Z20),$Y20&"/"&$Z20&"/"&$AA20)) -> - | V20: =IF($Y20=0,"-",IF(AND($Y20<80,$Z20<80,$AA20<80),"Không đạt",IF($Y20<95,"Đạt","Xuất sắc"))) -> - | W20: =IF($Y20=0,"Vắng",IF($AA20<>0,"Kiểm tra lần 1/2/3",IF($Z20<>0,"Kiểm tra lần 1/2",""))) -> Vắng
B21: =ROW()-13 -> 8 | G21: =B21 -> 8 | H21: =C21 -> 0 | I21: =D21 -> 0 | K21: =E21 -> 0 | P21: =$B21 -> 8 | Q21: =C21 -> 0 | R21: =D21 -> 0 | T21: =E21 -> 0 | U21: =IF($Y21=0,"-",IF(ISBLANK($AA21),IF(ISBLANK($Z21),$Y21,$Y21&"/"&$Z21),$Y21&"/"&$Z21&"/"&$AA21)) -> - | V21: =IF($Y21=0,"-",IF(AND($Y21<80,$Z21<80,$AA21<80),"Không đạt",IF($Y21<95,"Đạt","Xuất sắc"))) -> - | W21: =IF($Y21=0,"Vắng",IF($AA21<>0,"Kiểm tra lần 1/2/3",IF($Z21<>0,"Kiểm tra lần 1/2",""))) -> Vắng
B22: =ROW()-13 -> 9 | G22: =B22 -> 9 | H22: =C22 -> 0 | I22: =D22 -> 0 | K22: =E22 -> 0 | P22: =$B22 -> 9 | Q22: =C22 -> 0 | R22: =D22 -> 0 | T22: =E22 -> 0 | U22: =IF($Y22=0,"-",IF(ISBLANK($AA22),IF(ISBLANK($Z22),$Y22,$Y22&"/"&$Z22),$Y22&"/"&$Z22&"/"&$AA22)) -> - | V22: =IF($Y22=0,"-",IF(AND($Y22<80,$Z22<80,$AA22<80),"Không đạt",IF($Y22<95,"Đạt","Xuất sắc"))) -> - | W22: =IF($Y22=0,"Vắng",IF($AA22<>0,"Kiểm tra lần 1/2/3",IF($Z22<>0,"Kiểm tra lần 1/2",""))) -> Vắng
B23: =ROW()-13 -> 10 | G23: =B23 -> 10 | H23: =C23 -> 0 | I23: =D23 -> 0 | K23: =E23 -> 0 | P23: =$B23 -> 10 | Q23: =C23 -> 0 | R23: =D23 -> 0 | T23: =E23 -> 0 | U23: =IF($Y23=0,"-",IF(ISBLANK($AA23),IF(ISBLANK($Z23),$Y23,$Y23&"/"&$Z23),$Y23&"/"&$Z23&"/"&$AA23)) -> - | V23: =IF($Y23=0,"-",IF(AND($Y23<80,$Z23<80,$AA23<80),"Không đạt",IF($Y23<95,"Đạt","Xuất sắc"))) -> - | W23: =IF($Y23=0,"Vắng",IF($AA23<>0,"Kiểm tra lần 1/2/3",IF($Z23<>0,"Kiểm tra lần 1/2",""))) -> Vắng
B24: =ROW()-13 -> 11 | G24: =B24 -> 11 | H24: =C24 -> 0 | I24: =D24 -> 0 | K24: =E24 -> 0 | P24: =$B24 -> 11 | Q24: =C24 -> 0 | R24: =D24 -> 0 | T24: =E24 -> 0 | U24: =IF($Y24=0,"-",IF(ISBLANK($AA24),IF(ISBLANK($Z24),$Y24,$Y24&"/"&$Z24),$Y24&"/"&$Z24&"/"&$AA24)) -> - | V24: =IF($Y24=0,"-",IF(AND($Y24<80,$Z24<80,$AA24<80),"Không đạt",IF($Y24<95,"Đạt","Xuất sắc"))) -> - | W24: =IF($Y24=0,"Vắng",IF($AA24<>0,"Kiểm tra lần 1/2/3",IF($Z24<>0,"Kiểm tra lần 1/2",""))) -> Vắng
B25: =ROW()-13 -> 12 | G25: =B25 -> 12 | H25: =C25 -> 0 | I25: =D25 -> 0 | K25: =E25 -> 0 | P25: =$B25 -> 12 | Q25: =C25 -> 0 | R25: =D25 -> 0 | T25: =E25 -> 0 | U25: =IF($Y25=0,"-",IF(ISBLANK($AA25),IF(ISBLANK($Z25),$Y25,$Y25&"/"&$Z25),$Y25&"/"&$Z25&"/"&$AA25)) -> - | V25: =IF($Y25=0,"-",IF(AND($Y25<80,$Z25<80,$AA25<80),"Không đạt",IF($Y25<95,"Đạt","Xuất sắc"))) -> - | W25: =IF($Y25=0,"Vắng",IF($AA25<>0,"Kiểm tra lần 1/2/3",IF($Z25<>0,"Kiểm tra lần 1/2",""))) -> Vắng
... B29: =ROW()-13 -> 16 | G29: =B29 -> 16 | H29: =C29 -> 0 | I29: =D29 -> 0 | K29: =E29 -> 0 | P29: =$B29 -> 16 | Q29: =C29 -> 0 | R29: =D29 -> 0 | T29: =E29 -> 0 | U29: =IF($Y29=0,"-",IF(ISBLANK($AA29),IF(ISBLANK($Z29),$Y29,$Y29&"/"&$Z29),$Y29&"/"&$Z29&"/"&$AA29)) -> - | V29: =IF($Y29=0,"-",IF(AND($Y29<80,$Z29<80,$AA29<80),"Không đạt",IF($Y29<95,"Đạt","Xuất sắc"))) -> - | W29: =IF($Y29=0,"Vắng",IF($AA29<>0,"Kiểm tra lần 1/2/3",IF($Z29<>0,"Kiểm tra lần 1/2",""))) -> Vắng
C30: Trưởng Trung tâm đào tạo | F30: Người lập | H30: Chữ ký giáo viên: | P30: Giáo viên hướng dẫn: | S30: Trưởng bộ môn: | V30: Trưởng TTĐT:
G32: Lưu ý:
G33: - Giáo viên điểm danh theo ngày và đánh dấu: X: có mặt; V: vắng mặt
C34: Nguyễn Chí Kiên | F34: Nguyễn Cao Bình | G34: - Trang thiết bị thực hành (áp dụng đối với nội dung thực hành Nghiệp vụ điều khiển/vận hành thiết bị): | P34: Họ tên: | S34: Họ tên: | V34: Họ tên: Nguyễn Chí Kiên
G35: …………………………………………………………………………………............................................ | P35: Ngày: | S35: Ngày: | V35: Ngày :

Sheet 3
E2: DANH SÁCH HỌC VIÊN | J2: Biểu mẫu | N2: Mã số: V.TMM-F10 | S2: Biểu mẫu | W2: Mã số: V.TMM-F05a
J3: ĐIỂM DANH HỌC VIÊN | N3: Ban hành: 04 | S3: KẾT QUẢ ĐÀO TẠO | W3: Ban hành: 04
N4: Hiệu lực: 28/12/2024 | W4: Hiệu lực: 28/12/2024
N5: Trang: 1/1 | W5: Trang: 1/1
B7: - Môn/Khóa học: | D7: Công tác khẩn nguy tại cảng hàng không, sân bay | G7: - Môn/Khóa học: | I7: =D7 -> Công tác khẩn nguy tại cảng hàng không, sân bay | P7: - Môn/Khóa học: | R7: =I7 -> Công tác khẩn nguy tại cảng hàng không, sân bay | Y7: Xóa bớt HV bằng cách xóa cả dòng
B8: - Loại hình/hình thức đào tạo: Phục hồi/Trực tiếp | G8: =B8 -> - Loại hình/hình thức đào tạo: Phục hồi/Trực tiếp | P8: =G8 -> - Loại hình/hình thức đào tạo: Phục hồi/Trực tiếp | Y8: Thêm HV bằng cách copy cả dòng-->bấm phải chuột-->insert copied cells
B9: - Thời gian: | G9: =B9 -> - Thời gian: | I9: =D9 -> 0 | P9: =G9 -> - Thời gian: | R9: =I9 -> 0 | Y9: Điểm trung bình xếp loại, ghi chú, số học viên tham dự tự động điền sau khi nhập điểm LT, TH
B10: - Địa điểm: | D10: TTĐT MB | G10: =B10 -> - Địa điểm: | I10: =D10 -> TTĐT MB | P10: =G10 -> - Địa điểm: | R10: =I10 -> TTĐT MB | Y10: Bôi tất cả các dòng có HV-->Custom Sort theo cột V, cột W
B11: - Giáo viên: | G11: - Số học viên tham dự/tổng số học viên: | K11: =COUNTIF($L$14:$L43,"x")&"/"&COUNTA($L$14:$L43) -> 0/0 | P11: =G11 -> - Số học viên tham dự/tổng số học viên: | T11: =K11 -> 0/0 | Y11: Nhập điểm các lần thi ở đây
B12: STT | C12: Mã NV | D12: Họ tên | E12: Đơn vị | F12: Ghi chú | G12: STT | H12: Mã nhân viên | I12: Họ tên | K12: Đơn vị | L12: Ngày | M12: Ngày | N12: Ngày | O12: Ghi chú | P12: STT | Q12: Mã nhân viên | R12: Họ tên | T12: Đơn vị | U12: Điểm | V12: Xếp loại | W12: Ghi chú | Y12: L1 | Z12: L2 | AA12: L3
L13: =I9 -> 0
B14: =ROW()-13 -> 1 | G14: =B14 -> 1 | H14: =C14 -> 0 | I14: =D14 -> 0 | K14: =E14 -> 0 | P14: =$B14 -> 1 | Q14: =C14 -> 0 | R14: =D14 -> 0 | T14: =E14 -> 0 | U14: =IF($Y14=0,"-",IF(ISBLANK($AA14),IF(ISBLANK($Z14),$Y14,$Y14&"/"&$Z14),$Y14&"/"&$Z14&"/"&$AA14)) -> - | V14: =IF($Y14=0,"-",IF(AND($Y14<80,$Z14<80,$AA14<80),"Không đạt",IF($Y14<95,"Đạt","Xuất sắc"))) -> - | W14: =IF($Y14=0,"Vắng",IF($AA14<>0,"Kiểm tra lần 1/2/3",IF($Z14<>0,"Kiểm tra lần 1/2",""))) -> Vắng
B15: =ROW()-13 -> 2 | G15: =B15 -> 2 | H15: =C15 -> 0 | I15: =D15 -> 0 | K15: =E15 -> 0 | P15: =$B15 -> 2 | Q15: =C15 -> 0 | R15: =D15 -> 0 | T15: =E15 -> 0 | U15: =IF($Y15=0,"-",IF(ISBLANK($AA15),IF(ISBLANK($Z15),$Y15,$Y15&"/"&$Z15),$Y15&"/"&$Z15&"/"&$AA15)) -> - | V15: =IF($Y15=0,"-",IF(AND($Y15<80,$Z15<80,$AA15<80),"Không đạt",IF($Y15<95,"Đạt","Xuất sắc"))) -> - | W15: =IF($Y15=0,"Vắng",IF($AA15<>0,"Kiểm tra lần 1/2/3",IF($Z15<>0,"Kiểm tra lần 1/2",""))) -> Vắng
B16: =ROW()-13 -> 3 | G16: =B16 -> 3 | H16: =C16 -> 0 | I16: =D16 -> 0 | K16: =E16 -> 0 | P16: =$B16 -> 3 | Q16: =C16 -> 0 | R16: =D16 -> 0 | T16: =E16 -> 0 | U16: =IF($Y16=0,"-",IF(ISBLANK($AA16),IF(ISBLANK($Z16),$Y16,$Y16&"/"&$Z16),$Y16&"/"&$Z16&"/"&$AA16)) -> - | V16: =IF($Y16=0,"-",IF(AND($Y16<80,$Z16<80,$AA16<80),"Không đạt",IF($Y16<95,"Đạt","Xuất sắc"))) -> - | W16: =IF($Y16=0,"Vắng",IF($AA16<>0,"Kiểm tra lần 1/2/3",IF($Z16<>0,"Kiểm tra lần 1/2",""))) -> Vắng
B17: =ROW()-13 -> 4 | G17: =B17 -> 4 | H17: =C17 -> 0 | I17: =D17 -> 0 | K17: =E17 -> 0 | P17: =$B17 -> 4 | Q17: =C17 -> 0 | R17: =D17 -> 0 | T17: =E17 -> 0 | U17: =IF($Y17=0,"-",IF(ISBLANK($AA17),IF(ISBLANK($Z17),$Y17,$Y17&"/"&$Z17),$Y17&"/"&$Z17&"/"&$AA17)) -> - | V17: =IF($Y17=0,"-",IF(AND($Y17<80,$Z17<80,$AA17<80),"Không đạt",IF($Y17<95,"Đạt","Xuất sắc"))) -> - | W17: =IF($Y17=0,"Vắng",IF($AA17<>0,"Kiểm tra lần 1/2/3",IF($Z17<>0,"Kiểm tra lần 1/2",""))) -> Vắng
B18: =ROW()-13 -> 5 | G18: =B18 -> 5 | H18: =C18 -> 0 | I18: =D18 -> 0 | K18: =E18 -> 0 | P18: =$B18 -> 5 | Q18: =C18 -> 0 | R18: =D18 -> 0 | T18: =E18 -> 0 | U18: =IF($Y18=0,"-",IF(ISBLANK($AA18),IF(ISBLANK($Z18),$Y18,$Y18&"/"&$Z18),$Y18&"/"&$Z18&"/"&$AA18)) -> - | V18: =IF($Y18=0,"-",IF(AND($Y18<80,$Z18<80,$AA18<80),"Không đạt",IF($Y18<95,"Đạt","Xuất sắc"))) -> - | W18: =IF($Y18=0,"Vắng",IF($AA18<>0,"Kiểm tra lần 1/2/3",IF($Z18<>0,"Kiểm tra lần 1/2",""))) -> Vắng
B19: =ROW()-13 -> 6 | G19: =B19 -> 6 | H19: =C19 -> 0 | I19: =D19 -> 0 | K19: =E19 -> 0 | P19: =$B19 -> 6 | Q19: =C19 -> 0 | R19: =D19 -> 0 | T19: =E19 -> 0 | U19: =IF($Y19=0,"-",IF(ISBLANK($AA19),IF(ISBLANK($Z19),$Y19,$Y19&"/"&$Z19),$Y19&"/"&$Z19&"/"&$AA19)) -> - | V19: =IF($Y19=0,"-",IF(AND($Y19<80,$Z19<80,$AA19<80),"Không đạt",IF($Y19<95,"Đạt","Xuất sắc"))) -> - | W19: =IF($Y19=0,"Vắng",IF($AA19<>0,"Kiểm tra lần 1/2/3",IF($Z19<>0,"Kiểm tra lần 1/2",""))) -> Vắng
B20: =ROW()-13 -> 7 | G20: =B20 -> 7 | H20: =C20 -> 0 | I20: =D20 -> 0 | K20: =E20 -> 0 | P20: =$B20 -> 7 | Q20: =C20 -> 0 | R20: =D20 -> 0 | T20: =E20 -> 0 | U20: =IF($Y20=0,"-",IF(ISBLANK($AA20),IF(ISBLANK($Z20),$Y20,$Y20&"/"&$Z20),$Y20&"/"&$Z20&"/"&$AA20)) -> - | V20: =IF($Y20=0,"-",IF(AND($Y20<80,$Z20<80,$AA20<80),"Không đạt",IF($Y20<95,"Đạt","Xuất sắc"))) -> - | W20: =IF($Y20=0,"Vắng",IF($AA20<>0,"Kiểm tra lần 1/2/3",IF($Z20<>0,"Kiểm tra lần 1/2",""))) -> Vắng
B21: =ROW()-13 -> 8 | G21: =B21 -> 8 | H21: =C21 -> 0 | I21: =D21 -> 0 | K21: =E21 -> 0 | P21: =$B21 -> 8 | Q21: =C21 -> 0 | R21: =D21 -> 0 | T21: =E21 -> 0 | U21: =IF($Y21=0,"-",IF(ISBLANK($AA21),IF(ISBLANK($Z21),$Y21,$Y21&"/"&$Z21),$Y21&"/"&$Z21&"/"&$AA21)) -> - | V21: =IF($Y21=0,"-",IF(AND($Y21<80,$Z21<80,$AA21<80),"Không đạt",IF($Y21<95,"Đạt","Xuất sắc"))) -> - | W21: =IF($Y21=0,"Vắng",IF($AA21<>0,"Kiểm tra lần 1/2/3",IF($Z21<>0,"Kiểm tra lần 1/2",""))) -> Vắng
B22: =ROW()-13 -> 9 | G22: =B22 -> 9 | H22: =C22 -> 0 | I22: =D22 -> 0 | K22: =E22 -> 0 | P22: =$B22 -> 9 | Q22: =C22 -> 0 | R22: =D22 -> 0 | T22: =E22 -> 0 | U22: =IF($Y22=0,"-",IF(ISBLANK($AA22),IF(ISBLANK($Z22),$Y22,$Y22&"/"&$Z22),$Y22&"/"&$Z22&"/"&$AA22)) -> - | V22: =IF($Y22=0,"-",IF(AND($Y22<80,$Z22<80,$AA22<80),"Không đạt",IF($Y22<95,"Đạt","Xuất sắc"))) -> - | W22: =IF($Y22=0,"Vắng",IF($AA22<>0,"Kiểm tra lần 1/2/3",IF($Z22<>0,"Kiểm tra lần 1/2",""))) -> Vắng
B23: =ROW()-13 -> 10 | G23: =B23 -> 10 | H23: =C23 -> 0 | I23: =D23 -> 0 | K23: =E23 -> 0 | P23: =$B23 -> 10 | Q23: =C23 -> 0 | R23: =D23 -> 0 | T23: =E23 -> 0 | U23: =IF($Y23=0,"-",IF(ISBLANK($AA23),IF(ISBLANK($Z23),$Y23,$Y23&"/"&$Z23),$Y23&"/"&$Z23&"/"&$AA23)) -> - | V23: =IF($Y23=0,"-",IF(AND($Y23<80,$Z23<80,$AA23<80),"Không đạt",IF($Y23<95,"Đạt","Xuất sắc"))) -> - | W23: =IF($Y23=0,"Vắng",IF($AA23<>0,"Kiểm tra lần 1/2/3",IF($Z23<>0,"Kiểm tra lần 1/2",""))) -> Vắng
B24: =ROW()-13 -> 11 | G24: =B24 -> 11 | H24: =C24 -> 0 | I24: =D24 -> 0 | K24: =E24 -> 0 | P24: =$B24 -> 11 | Q24: =C24 -> 0 | R24: =D24 -> 0 | T24: =E24 -> 0 | U24: =IF($Y24=0,"-",IF(ISBLANK($AA24),IF(ISBLANK($Z24),$Y24,$Y24&"/"&$Z24),$Y24&"/"&$Z24&"/"&$AA24)) -> - | V24: =IF($Y24=0,"-",IF(AND($Y24<80,$Z24<80,$AA24<80),"Không đạt",IF($Y24<95,"Đạt","Xuất sắc"))) -> - | W24: =IF($Y24=0,"Vắng",IF($AA24<>0,"Kiểm tra lần 1/2/3",IF($Z24<>0,"Kiểm tra lần 1/2",""))) -> Vắng
B25: =ROW()-13 -> 12 | G25: =B25 -> 12 | H25: =C25 -> 0 | I25: =D25 -> 0 | K25: =E25 -> 0 | P25: =$B25 -> 12 | Q25: =C25 -> 0 | R25: =D25 -> 0 | T25: =E25 -> 0 | U25: =IF($Y25=0,"-",IF(ISBLANK($AA25),IF(ISBLANK($Z25),$Y25,$Y25&"/"&$Z25),$Y25&"/"&$Z25&"/"&$AA25)) -> - | V25: =IF($Y25=0,"-",IF(AND($Y25<80,$Z25<80,$AA25<80),"Không đạt",IF($Y25<95,"Đạt","Xuất sắc"))) -> - | W25: =IF($Y25=0,"Vắng",IF($AA25<>0,"Kiểm tra lần 1/2/3",IF($Z25<>0,"Kiểm tra lần 1/2",""))) -> Vắng
... B29: =ROW()-13 -> 16 | G29: =B29 -> 16 | H29: =C29 -> 0 | I29: =D29 -> 0 | K29: =E29 -> 0 | P29: =$B29 -> 16 | Q29: =C29 -> 0 | R29: =D29 -> 0 | T29: =E29 -> 0 | U29: =IF($Y29=0,"-",IF(ISBLANK($AA29),IF(ISBLANK($Z29),$Y29,$Y29&"/"&$Z29),$Y29&"/"&$Z29&"/"&$AA29)) -> - | V29: =IF($Y29=0,"-",IF(AND($Y29<80,$Z29<80,$AA29<80),"Không đạt",IF($Y29<95,"Đạt","Xuất sắc"))) -> - | W29: =IF($Y29=0,"Vắng",IF($AA29<>0,"Kiểm tra lần 1/2/3",IF($Z29<>0,"Kiểm tra lần 1/2",""))) -> Vắng
C30: Trưởng Trung tâm đào tạo | F30: Người lập | H30: Chữ ký giáo viên: | P30: Giáo viên hướng dẫn: | S30: Trưởng bộ môn: | V30: Trưởng TTĐT:
G32: Lưu ý:
G33: - Giáo viên điểm danh theo ngày và đánh dấu: X: có mặt; V: vắng mặt
C34: Nguyễn Chí Kiên | F34: Nguyễn Cao Bình | G34: - Trang thiết bị thực hành (áp dụng đối với nội dung thực hành Nghiệp vụ điều khiển/vận hành thiết bị): | P34: Họ tên: | S34: Họ tên: | V34: Họ tên: Nguyễn Chí Kiên
G35: …………………………………………………………………………………............................................ | P35: Ngày: | S35: Ngày: | V35: Ngày :

Sheet 4
E2: DANH SÁCH HỌC VIÊN | J2: Biểu mẫu | N2: Mã số: V.TMM-F10 | S2: Biểu mẫu | W2: Mã số: V.TMM-F05a
J3: ĐIỂM DANH HỌC VIÊN | N3: Ban hành: 04 | S3: KẾT QUẢ ĐÀO TẠO | W3: Ban hành: 04
N4: Hiệu lực: 28/12/2024 | W4: Hiệu lực: 28/12/2024
N5: Trang: 1/1 | W5: Trang: 1/1
B7: - Môn/Khóa học: | D7: Pháp luật về hàng không dân dụng | G7: - Môn/Khóa học: | I7: =D7 -> Pháp luật về hàng không dân dụng | P7: - Môn/Khóa học: | R7: =I7 -> Pháp luật về hàng không dân dụng | Y7: Xóa bớt HV bằng cách xóa cả dòng
B8: - Loại hình/hình thức đào tạo: Phục hồi/Trực tiếp | G8: =B8 -> - Loại hình/hình thức đào tạo: Phục hồi/Trực tiếp | P8: =G8 -> - Loại hình/hình thức đào tạo: Phục hồi/Trực tiếp | Y8: Thêm HV bằng cách copy cả dòng-->bấm phải chuột-->insert copied cells
B9: - Thời gian: | G9: =B9 -> - Thời gian: | I9: =D9 -> 0 | P9: =G9 -> - Thời gian: | R9: =I9 -> 0 | Y9: Điểm trung bình xếp loại, ghi chú, số học viên tham dự tự động điền sau khi nhập điểm LT, TH
B10: - Địa điểm: | D10: TTĐT MB | G10: =B10 -> - Địa điểm: | I10: =D10 -> TTĐT MB | P10: =G10 -> - Địa điểm: | R10: =I10 -> TTĐT MB | Y10: Bôi tất cả các dòng có HV-->Custom Sort theo cột V, cột W
B11: - Giáo viên: | G11: - Số học viên tham dự/tổng số học viên: | K11: =COUNTIF($L$14:$L43,"x")&"/"&COUNTA($L$14:$L43) -> 0/0 | P11: =G11 -> - Số học viên tham dự/tổng số học viên: | T11: =K11 -> 0/0 | Y11: Nhập điểm các lần thi ở đây
B12: STT | C12: Mã NV | D12: Họ tên | E12: Đơn vị | F12: Ghi chú | G12: STT | H12: Mã nhân viên | I12: Họ tên | K12: Đơn vị | L12: Ngày | M12: Ngày | N12: Ngày | O12: Ghi chú | P12: STT | Q12: Mã nhân viên | R12: Họ tên | T12: Đơn vị | U12: Điểm | V12: Xếp loại | W12: Ghi chú | Y12: L1 | Z12: L2 | AA12: L3
L13: =I9 -> 0
B14: =ROW()-13 -> 1 | G14: =B14 -> 1 | H14: =C14 -> 0 | I14: =D14 -> 0 | K14: =E14 -> 0 | P14: =$B14 -> 1 | Q14: =C14 -> 0 | R14: =D14 -> 0 | T14: =E14 -> 0 | U14: =IF($Y14=0,"-",IF(ISBLANK($AA14),IF(ISBLANK($Z14),$Y14,$Y14&"/"&$Z14),$Y14&"/"&$Z14&"/"&$AA14)) -> - | V14: =IF($Y14=0,"-",IF(AND($Y14<80,$Z14<80,$AA14<80),"Không đạt",IF($Y14<95,"Đạt","Xuất sắc"))) -> - | W14: =IF($Y14=0,"Vắng",IF($AA14<>0,"Kiểm tra lần 1/2/3",IF($Z14<>0,"Kiểm tra lần 1/2",""))) -> Vắng
B15: =ROW()-13 -> 2 | G15: =B15 -> 2 | H15: =C15 -> 0 | I15: =D15 -> 0 | K15: =E15 -> 0 | P15: =$B15 -> 2 | Q15: =C15 -> 0 | R15: =D15 -> 0 | T15: =E15 -> 0 | U15: =IF($Y15=0,"-",IF(ISBLANK($AA15),IF(ISBLANK($Z15),$Y15,$Y15&"/"&$Z15),$Y15&"/"&$Z15&"/"&$AA15)) -> - | V15: =IF($Y15=0,"-",IF(AND($Y15<80,$Z15<80,$AA15<80),"Không đạt",IF($Y15<95,"Đạt","Xuất sắc"))) -> - | W15: =IF($Y15=0,"Vắng",IF($AA15<>0,"Kiểm tra lần 1/2/3",IF($Z15<>0,"Kiểm tra lần 1/2",""))) -> Vắng
B16: =ROW()-13 -> 3 | G16: =B16 -> 3 | H16: =C16 -> 0 | I16: =D16 -> 0 | K16: =E16 -> 0 | P16: =$B16 -> 3 | Q16: =C16 -> 0 | R16: =D16 -> 0 | T16: =E16 -> 0 | U16: =IF($Y16=0,"-",IF(ISBLANK($AA16),IF(ISBLANK($Z16),$Y16,$Y16&"/"&$Z16),$Y16&"/"&$Z16&"/"&$AA16)) -> - | V16: =IF($Y16=0,"-",IF(AND($Y16<80,$Z16<80,$AA16<80),"Không đạt",IF($Y16<95,"Đạt","Xuất sắc"))) -> - | W16: =IF($Y16=0,"Vắng",IF($AA16<>0,"Kiểm tra lần 1/2/3",IF($Z16<>0,"Kiểm tra lần 1/2",""))) -> Vắng
B17: =ROW()-13 -> 4 | G17: =B17 -> 4 | H17: =C17 -> 0 | I17: =D17 -> 0 | K17: =E17 -> 0 | P17: =$B17 -> 4 | Q17: =C17 -> 0 | R17: =D17 -> 0 | T17: =E17 -> 0 | U17: =IF($Y17=0,"-",IF(ISBLANK($AA17),IF(ISBLANK($Z17),$Y17,$Y17&"/"&$Z17),$Y17&"/"&$Z17&"/"&$AA17)) -> - | V17: =IF($Y17=0,"-",IF(AND($Y17<80,$Z17<80,$AA17<80),"Không đạt",IF($Y17<95,"Đạt","Xuất sắc"))) -> - | W17: =IF($Y17=0,"Vắng",IF($AA17<>0,"Kiểm tra lần 1/2/3",IF($Z17<>0,"Kiểm tra lần 1/2",""))) -> Vắng
B18: =ROW()-13 -> 5 | G18: =B18 -> 5 | H18: =C18 -> 0 | I18: =D18 -> 0 | K18: =E18 -> 0 | P18: =$B18 -> 5 | Q18: =C18 -> 0 | R18: =D18 -> 0 | T18: =E18 -> 0 | U18: =IF($Y18=0,"-",IF(ISBLANK($AA18),IF(ISBLANK($Z18),$Y18,$Y18&"/"&$Z18),$Y18&"/"&$Z18&"/"&$AA18)) -> - | V18: =IF($Y18=0,"-",IF(AND($Y18<80,$Z18<80,$AA18<80),"Không đạt",IF($Y18<95,"Đạt","Xuất sắc"))) -> - | W18: =IF($Y18=0,"Vắng",IF($AA18<>0,"Kiểm tra lần 1/2/3",IF($Z18<>0,"Kiểm tra lần 1/2",""))) -> Vắng
B19: =ROW()-13 -> 6 | G19: =B19 -> 6 | H19: =C19 -> 0 | I19: =D19 -> 0 | K19: =E19 -> 0 | P19: =$B19 -> 6 | Q19: =C19 -> 0 | R19: =D19 -> 0 | T19: =E19 -> 0 | U19: =IF($Y19=0,"-",IF(ISBLANK($AA19),IF(ISBLANK($Z19),$Y19,$Y19&"/"&$Z19),$Y19&"/"&$Z19&"/"&$AA19)) -> - | V19: =IF($Y19=0,"-",IF(AND($Y19<80,$Z19<80,$AA19<80),"Không đạt",IF($Y19<95,"Đạt","Xuất sắc"))) -> - | W19: =IF($Y19=0,"Vắng",IF($AA19<>0,"Kiểm tra lần 1/2/3",IF($Z19<>0,"Kiểm tra lần 1/2",""))) -> Vắng
B20: =ROW()-13 -> 7 | G20: =B20 -> 7 | H20: =C20 -> 0 | I20: =D20 -> 0 | K20: =E20 -> 0 | P20: =$B20 -> 7 | Q20: =C20 -> 0 | R20: =D20 -> 0 | T20: =E20 -> 0 | U20: =IF($Y20=0,"-",IF(ISBLANK($AA20),IF(ISBLANK($Z20),$Y20,$Y20&"/"&$Z20),$Y20&"/"&$Z20&"/"&$AA20)) -> - | V20: =IF($Y20=0,"-",IF(AND($Y20<80,$Z20<80,$AA20<80),"Không đạt",IF($Y20<95,"Đạt","Xuất sắc"))) -> - | W20: =IF($Y20=0,"Vắng",IF($AA20<>0,"Kiểm tra lần 1/2/3",IF($Z20<>0,"Kiểm tra lần 1/2",""))) -> Vắng
B21: =ROW()-13 -> 8 | G21: =B21 -> 8 | H21: =C21 -> 0 | I21: =D21 -> 0 | K21: =E21 -> 0 | P21: =$B21 -> 8 | Q21: =C21 -> 0 | R21: =D21 -> 0 | T21: =E21 -> 0 | U21: =IF($Y21=0,"-",IF(ISBLANK($AA21),IF(ISBLANK($Z21),$Y21,$Y21&"/"&$Z21),$Y21&"/"&$Z21&"/"&$AA21)) -> - | V21: =IF($Y21=0,"-",IF(AND($Y21<80,$Z21<80,$AA21<80),"Không đạt",IF($Y21<95,"Đạt","Xuất sắc"))) -> - | W21: =IF($Y21=0,"Vắng",IF($AA21<>0,"Kiểm tra lần 1/2/3",IF($Z21<>0,"Kiểm tra lần 1/2",""))) -> Vắng
B22: =ROW()-13 -> 9 | G22: =B22 -> 9 | H22: =C22 -> 0 | I22: =D22 -> 0 | K22: =E22 -> 0 | P22: =$B22 -> 9 | Q22: =C22 -> 0 | R22: =D22 -> 0 | T22: =E22 -> 0 | U22: =IF($Y22=0,"-",IF(ISBLANK($AA22),IF(ISBLANK($Z22),$Y22,$Y22&"/"&$Z22),$Y22&"/"&$Z22&"/"&$AA22)) -> - | V22: =IF($Y22=0,"-",IF(AND($Y22<80,$Z22<80,$AA22<80),"Không đạt",IF($Y22<95,"Đạt","Xuất sắc"))) -> - | W22: =IF($Y22=0,"Vắng",IF($AA22<>0,"Kiểm tra lần 1/2/3",IF($Z22<>0,"Kiểm tra lần 1/2",""))) -> Vắng
B23: =ROW()-13 -> 10 | G23: =B23 -> 10 | H23: =C23 -> 0 | I23: =D23 -> 0 | K23: =E23 -> 0 | P23: =$B23 -> 10 | Q23: =C23 -> 0 | R23: =D23 -> 0 | T23: =E23 -> 0 | U23: =IF($Y23=0,"-",IF(ISBLANK($AA23),IF(ISBLANK($Z23),$Y23,$Y23&"/"&$Z23),$Y23&"/"&$Z23&"/"&$AA23)) -> - | V23: =IF($Y23=0,"-",IF(AND($Y23<80,$Z23<80,$AA23<80),"Không đạt",IF($Y23<95,"Đạt","Xuất sắc"))) -> - | W23: =IF($Y23=0,"Vắng",IF($AA23<>0,"Kiểm tra lần 1/2/3",IF($Z23<>0,"Kiểm tra lần 1/2",""))) -> Vắng
B24: =ROW()-13 -> 11 | G24: =B24 -> 11 | H24: =C24 -> 0 | I24: =D24 -> 0 | K24: =E24 -> 0 | P24: =$B24 -> 11 | Q24: =C24 -> 0 | R24: =D24 -> 0 | T24: =E24 -> 0 | U24: =IF($Y24=0,"-",IF(ISBLANK($AA24),IF(ISBLANK($Z24),$Y24,$Y24&"/"&$Z24),$Y24&"/"&$Z24&"/"&$AA24)) -> - | V24: =IF($Y24=0,"-",IF(AND($Y24<80,$Z24<80,$AA24<80),"Không đạt",IF($Y24<95,"Đạt","Xuất sắc"))) -> - | W24: =IF($Y24=0,"Vắng",IF($AA24<>0,"Kiểm tra lần 1/2/3",IF($Z24<>0,"Kiểm tra lần 1/2",""))) -> Vắng
B25: =ROW()-13 -> 12 | G25: =B25 -> 12 | H25: =C25 -> 0 | I25: =D25 -> 0 | K25: =E25 -> 0 | P25: =$B25 -> 12 | Q25: =C25 -> 0 | R25: =D25 -> 0 | T25: =E25 -> 0 | U25: =IF($Y25=0,"-",IF(ISBLANK($AA25),IF(ISBLANK($Z25),$Y25,$Y25&"/"&$Z25),$Y25&"/"&$Z25&"/"&$AA25)) -> - | V25: =IF($Y25=0,"-",IF(AND($Y25<80,$Z25<80,$AA25<80),"Không đạt",IF($Y25<95,"Đạt","Xuất sắc"))) -> - | W25: =IF($Y25=0,"Vắng",IF($AA25<>0,"Kiểm tra lần 1/2/3",IF($Z25<>0,"Kiểm tra lần 1/2",""))) -> Vắng
... B29: =ROW()-13 -> 16 | G29: =B29 -> 16 | H29: =C29 -> 0 | I29: =D29 -> 0 | K29: =E29 -> 0 | P29: =$B29 -> 16 | Q29: =C29 -> 0 | R29: =D29 -> 0 | T29: =E29 -> 0 | U29: =IF($Y29=0,"-",IF(ISBLANK($AA29),IF(ISBLANK($Z29),$Y29,$Y29&"/"&$Z29),$Y29&"/"&$Z29&"/"&$AA29)) -> - | V29: =IF($Y29=0,"-",IF(AND($Y29<80,$Z29<80,$AA29<80),"Không đạt",IF($Y29<95,"Đạt","Xuất sắc"))) -> - | W29: =IF($Y29=0,"Vắng",IF($AA29<>0,"Kiểm tra lần 1/2/3",IF($Z29<>0,"Kiểm tra lần 1/2",""))) -> Vắng
C30: Trưởng Trung tâm đào tạo | F30: Người lập | H30: Chữ ký giáo viên: | P30: Giáo viên hướng dẫn: | S30: Trưởng bộ môn: | V30: Trưởng TTĐT:
G32: Lưu ý:
G33: - Giáo viên điểm danh theo ngày và đánh dấu: X: có mặt; V: vắng mặt
C34: Nguyễn Chí Kiên | F34: Nguyễn Cao Bình | G34: - Trang thiết bị thực hành (áp dụng đối với nội dung thực hành Nghiệp vụ điều khiển/vận hành thiết bị): | P34: Họ tên: | S34: Họ tên: | V34: Họ tên: Nguyễn Chí Kiên
G35: …………………………………………………………………………………............................................ | P35: Ngày: | S35: Ngày: | V35: Ngày :

Sheet 5
E2: DANH SÁCH HỌC VIÊN | J2: Biểu mẫu | N2: Mã số: V.TMM-F10 | S2: Biểu mẫu | W2: Mã số: V.TMM-F05a
J3: ĐIỂM DANH HỌC VIÊN | N3: Ban hành: 04 | S3: KẾT QUẢ ĐÀO TẠO | W3: Ban hành: 04
N4: Hiệu lực: 28/12/2024 | W4: Hiệu lực: 28/12/2024
N5: Trang: 1/1 | W5: Trang: 1/1
B7: - Môn/Khóa học: | D7: An ninh hàng không dành cho nhân viên phục vụ kỹ thuật thương mại mặt đất của các đơn vị cung cấp dịch vụ hàng không tại cảng hàng không, sân bay | G7: - Môn/Khóa học: | I7: =D7 -> An ninh hàng không dành cho nhân viên phục vụ kỹ thuật thương mại mặt đất của các đơn vị cung cấp dịch vụ hàng không tại cảng hàng không, sân bay | P7: - Môn/Khóa học: | R7: =I7 -> An ninh hàng không dành cho nhân viên phục vụ kỹ thuật thương mại mặt đất của các đơn vị cung cấp dịch vụ hàng không tại cảng hàng không, sân bay | Y7: Xóa bớt HV bằng cách xóa cả dòng
B8: - Loại hình/hình thức đào tạo: Phục hồi/Trực tiếp | G8: =B8 -> - Loại hình/hình thức đào tạo: Phục hồi/Trực tiếp | P8: =G8 -> - Loại hình/hình thức đào tạo: Phục hồi/Trực tiếp | Y8: Thêm HV bằng cách copy cả dòng-->bấm phải chuột-->insert copied cells
B9: - Thời gian: | G9: =B9 -> - Thời gian: | I9: =D9 -> 0 | P9: =G9 -> - Thời gian: | R9: =I9 -> 0 | Y9: Điểm trung bình xếp loại, ghi chú, số học viên tham dự tự động điền sau khi nhập điểm LT, TH
B10: - Địa điểm: | D10: TTĐT MB | G10: =B10 -> - Địa điểm: | I10: =D10 -> TTĐT MB | P10: =G10 -> - Địa điểm: | R10: =I10 -> TTĐT MB | Y10: Bôi tất cả các dòng có HV-->Custom Sort theo cột V, cột W
B11: - Giáo viên: | G11: - Số học viên tham dự/tổng số học viên: | K11: =COUNTIF($L$14:$L43,"x")&"/"&COUNTA($L$14:$L43) -> 0/0 | P11: =G11 -> - Số học viên tham dự/tổng số học viên: | T11: =K11 -> 0/0 | Y11: Nhập điểm các lần thi ở đây
B12: STT | C12: Mã NV | D12: Họ tên | E12: Đơn vị | F12: Ghi chú | G12: STT | H12: Mã nhân viên | I12: Họ tên | K12: Đơn vị | L12: Ngày | M12: Ngày | N12: Ngày | O12: Ghi chú | P12: STT | Q12: Mã nhân viên | R12: Họ tên | T12: Đơn vị | U12: Điểm | V12: Xếp loại | W12: Ghi chú | Y12: L1 | Z12: L2 | AA12: L3
L13: =I9 -> 0
B14: =ROW()-13 -> 1 | G14: =B14 -> 1 | H14: =C14 -> 0 | I14: =D14 -> 0 | K14: =E14 -> 0 | P14: =$B14 -> 1 | Q14: =C14 -> 0 | R14: =D14 -> 0 | T14: =E14 -> 0 | U14: =IF($Y14=0,"-",IF(ISBLANK($AA14),IF(ISBLANK($Z14),$Y14,$Y14&"/"&$Z14),$Y14&"/"&$Z14&"/"&$AA14)) -> - | V14: =IF($Y14=0,"-",IF(AND($Y14<80,$Z14<80,$AA14<80),"Không đạt",IF($Y14<95,"Đạt","Xuất sắc"))) -> - | W14: =IF($Y14=0,"Vắng",IF($AA14<>0,"Kiểm tra lần 1/2/3",IF($Z14<>0,"Kiểm tra lần 1/2",""))) -> Vắng
B15: =ROW()-13 -> 2 | G15: =B15 -> 2 | H15: =C15 -> 0 | I15: =D15 -> 0 | K15: =E15 -> 0 | P15: =$B15 -> 2 | Q15: =C15 -> 0 | R15: =D15 -> 0 | T15: =E15 -> 0 | U15: =IF($Y15=0,"-",IF(ISBLANK($AA15),IF(ISBLANK($Z15),$Y15,$Y15&"/"&$Z15),$Y15&"/"&$Z15&"/"&$AA15)) -> - | V15: =IF($Y15=0,"-",IF(AND($Y15<80,$Z15<80,$AA15<80),"Không đạt",IF($Y15<95,"Đạt","Xuất sắc"))) -> - | W15: =IF($Y15=0,"Vắng",IF($AA15<>0,"Kiểm tra lần 1/2/3",IF($Z15<>0,"Kiểm tra lần 1/2",""))) -> Vắng
B16: =ROW()-13 -> 3 | G16: =B16 -> 3 | H16: =C16 -> 0 | I16: =D16 -> 0 | K16: =E16 -> 0 | P16: =$B16 -> 3 | Q16: =C16 -> 0 | R16: =D16 -> 0 | T16: =E16 -> 0 | U16: =IF($Y16=0,"-",IF(ISBLANK($AA16),IF(ISBLANK($Z16),$Y16,$Y16&"/"&$Z16),$Y16&"/"&$Z16&"/"&$AA16)) -> - | V16: =IF($Y16=0,"-",IF(AND($Y16<80,$Z16<80,$AA16<80),"Không đạt",IF($Y16<95,"Đạt","Xuất sắc"))) -> - | W16: =IF($Y16=0,"Vắng",IF($AA16<>0,"Kiểm tra lần 1/2/3",IF($Z16<>0,"Kiểm tra lần 1/2",""))) -> Vắng
B17: =ROW()-13 -> 4 | G17: =B17 -> 4 | H17: =C17 -> 0 | I17: =D17 -> 0 | K17: =E17 -> 0 | P17: =$B17 -> 4 | Q17: =C17 -> 0 | R17: =D17 -> 0 | T17: =E17 -> 0 | U17: =IF($Y17=0,"-",IF(ISBLANK($AA17),IF(ISBLANK($Z17),$Y17,$Y17&"/"&$Z17),$Y17&"/"&$Z17&"/"&$AA17)) -> - | V17: =IF($Y17=0,"-",IF(AND($Y17<80,$Z17<80,$AA17<80),"Không đạt",IF($Y17<95,"Đạt","Xuất sắc"))) -> - | W17: =IF($Y17=0,"Vắng",IF($AA17<>0,"Kiểm tra lần 1/2/3",IF($Z17<>0,"Kiểm tra lần 1/2",""))) -> Vắng
B18: =ROW()-13 -> 5 | G18: =B18 -> 5 | H18: =C18 -> 0 | I18: =D18 -> 0 | K18: =E18 -> 0 | P18: =$B18 -> 5 | Q18: =C18 -> 0 | R18: =D18 -> 0 | T18: =E18 -> 0 | U18: =IF($Y18=0,"-",IF(ISBLANK($AA18),IF(ISBLANK($Z18),$Y18,$Y18&"/"&$Z18),$Y18&"/"&$Z18&"/"&$AA18)) -> - | V18: =IF($Y18=0,"-",IF(AND($Y18<80,$Z18<80,$AA18<80),"Không đạt",IF($Y18<95,"Đạt","Xuất sắc"))) -> - | W18: =IF($Y18=0,"Vắng",IF($AA18<>0,"Kiểm tra lần 1/2/3",IF($Z18<>0,"Kiểm tra lần 1/2",""))) -> Vắng
B19: =ROW()-13 -> 6 | G19: =B19 -> 6 | H19: =C19 -> 0 | I19: =D19 -> 0 | K19: =E19 -> 0 | P19: =$B19 -> 6 | Q19: =C19 -> 0 | R19: =D19 -> 0 | T19: =E19 -> 0 | U19: =IF($Y19=0,"-",IF(ISBLANK($AA19),IF(ISBLANK($Z19),$Y19,$Y19&"/"&$Z19),$Y19&"/"&$Z19&"/"&$AA19)) -> - | V19: =IF($Y19=0,"-",IF(AND($Y19<80,$Z19<80,$AA19<80),"Không đạt",IF($Y19<95,"Đạt","Xuất sắc"))) -> - | W19: =IF($Y19=0,"Vắng",IF($AA19<>0,"Kiểm tra lần 1/2/3",IF($Z19<>0,"Kiểm tra lần 1/2",""))) -> Vắng
B20: =ROW()-13 -> 7 | G20: =B20 -> 7 | H20: =C20 -> 0 | I20: =D20 -> 0 | K20: =E20 -> 0 | P20: =$B20 -> 7 | Q20: =C20 -> 0 | R20: =D20 -> 0 | T20: =E20 -> 0 | U20: =IF($Y20=0,"-",IF(ISBLANK($AA20),IF(ISBLANK($Z20),$Y20,$Y20&"/"&$Z20),$Y20&"/"&$Z20&"/"&$AA20)) -> - | V20: =IF($Y20=0,"-",IF(AND($Y20<80,$Z20<80,$AA20<80),"Không đạt",IF($Y20<95,"Đạt","Xuất sắc"))) -> - | W20: =IF($Y20=0,"Vắng",IF($AA20<>0,"Kiểm tra lần 1/2/3",IF($Z20<>0,"Kiểm tra lần 1/2",""))) -> Vắng
B21: =ROW()-13 -> 8 | G21: =B21 -> 8 | H21: =C21 -> 0 | I21: =D21 -> 0 | K21: =E21 -> 0 | P21: =$B21 -> 8 | Q21: =C21 -> 0 | R21: =D21 -> 0 | T21: =E21 -> 0 | U21: =IF($Y21=0,"-",IF(ISBLANK($AA21),IF(ISBLANK($Z21),$Y21,$Y21&"/"&$Z21),$Y21&"/"&$Z21&"/"&$AA21)) -> - | V21: =IF($Y21=0,"-",IF(AND($Y21<80,$Z21<80,$AA21<80),"Không đạt",IF($Y21<95,"Đạt","Xuất sắc"))) -> - | W21: =IF($Y21=0,"Vắng",IF($AA21<>0,"Kiểm tra lần 1/2/3",IF($Z21<>0,"Kiểm tra lần 1/2",""))) -> Vắng
B22: =ROW()-13 -> 9 | G22: =B22 -> 9 | H22: =C22 -> 0 | I22: =D22 -> 0 | K22: =E22 -> 0 | P22: =$B22 -> 9 | Q22: =C22 -> 0 | R22: =D22 -> 0 | T22: =E22 -> 0 | U22: =IF($Y22=0,"-",IF(ISBLANK($AA22),IF(ISBLANK($Z22),$Y22,$Y22&"/"&$Z22),$Y22&"/"&$Z22&"/"&$AA22)) -> - | V22: =IF($Y22=0,"-",IF(AND($Y22<80,$Z22<80,$AA22<80),"Không đạt",IF($Y22<95,"Đạt","Xuất sắc"))) -> - | W22: =IF($Y22=0,"Vắng",IF($AA22<>0,"Kiểm tra lần 1/2/3",IF($Z22<>0,"Kiểm tra lần 1/2",""))) -> Vắng
B23: =ROW()-13 -> 10 | G23: =B23 -> 10 | H23: =C23 -> 0 | I23: =D23 -> 0 | K23: =E23 -> 0 | P23: =$B23 -> 10 | Q23: =C23 -> 0 | R23: =D23 -> 0 | T23: =E23 -> 0 | U23: =IF($Y23=0,"-",IF(ISBLANK($AA23),IF(ISBLANK($Z23),$Y23,$Y23&"/"&$Z23),$Y23&"/"&$Z23&"/"&$AA23)) -> - | V23: =IF($Y23=0,"-",IF(AND($Y23<80,$Z23<80,$AA23<80),"Không đạt",IF($Y23<95,"Đạt","Xuất sắc"))) -> - | W23: =IF($Y23=0,"Vắng",IF($AA23<>0,"Kiểm tra lần 1/2/3",IF($Z23<>0,"Kiểm tra lần 1/2",""))) -> Vắng
B24: =ROW()-13 -> 11 | G24: =B24 -> 11 | H24: =C24 -> 0 | I24: =D24 -> 0 | K24: =E24 -> 0 | P24: =$B24 -> 11 | Q24: =C24 -> 0 | R24: =D24 -> 0 | T24: =E24 -> 0 | U24: =IF($Y24=0,"-",IF(ISBLANK($AA24),IF(ISBLANK($Z24),$Y24,$Y24&"/"&$Z24),$Y24&"/"&$Z24&"/"&$AA24)) -> - | V24: =IF($Y24=0,"-",IF(AND($Y24<80,$Z24<80,$AA24<80),"Không đạt",IF($Y24<95,"Đạt","Xuất sắc"))) -> - | W24: =IF($Y24=0,"Vắng",IF($AA24<>0,"Kiểm tra lần 1/2/3",IF($Z24<>0,"Kiểm tra lần 1/2",""))) -> Vắng
B25: =ROW()-13 -> 12 | G25: =B25 -> 12 | H25: =C25 -> 0 | I25: =D25 -> 0 | K25: =E25 -> 0 | P25: =$B25 -> 12 | Q25: =C25 -> 0 | R25: =D25 -> 0 | T25: =E25 -> 0 | U25: =IF($Y25=0,"-",IF(ISBLANK($AA25),IF(ISBLANK($Z25),$Y25,$Y25&"/"&$Z25),$Y25&"/"&$Z25&"/"&$AA25)) -> - | V25: =IF($Y25=0,"-",IF(AND($Y25<80,$Z25<80,$AA25<80),"Không đạt",IF($Y25<95,"Đạt","Xuất sắc"))) -> - | W25: =IF($Y25=0,"Vắng",IF($AA25<>0,"Kiểm tra lần 1/2/3",IF($Z25<>0,"Kiểm tra lần 1/2",""))) -> Vắng
... B29: =ROW()-13 -> 16 | G29: =B29 -> 16 | H29: =C29 -> 0 | I29: =D29 -> 0 | K29: =E29 -> 0 | P29: =$B29 -> 16 | Q29: =C29 -> 0 | R29: =D29 -> 0 | T29: =E29 -> 0 | U29: =IF($Y29=0,"-",IF(ISBLANK($AA29),IF(ISBLANK($Z29),$Y29,$Y29&"/"&$Z29),$Y29&"/"&$Z29&"/"&$AA29)) -> - | V29: =IF($Y29=0,"-",IF(AND($Y29<80,$Z29<80,$AA29<80),"Không đạt",IF($Y29<95,"Đạt","Xuất sắc"))) -> - | W29: =IF($Y29=0,"Vắng",IF($AA29<>0,"Kiểm tra lần 1/2/3",IF($Z29<>0,"Kiểm tra lần 1/2",""))) -> Vắng
C30: Trưởng Trung tâm đào tạo | F30: Người lập | H30: Chữ ký giáo viên: | P30: Giáo viên hướng dẫn: | S30: Trưởng bộ môn: | V30: Trưởng TTĐT:
G32: Lưu ý:
G33: - Giáo viên điểm danh theo ngày và đánh dấu: X: có mặt; V: vắng mặt
C34: Nguyễn Chí Kiên | F34: Nguyễn Cao Bình | G34: - Trang thiết bị thực hành (áp dụng đối với nội dung thực hành Nghiệp vụ điều khiển/vận hành thiết bị): | P34: Họ tên: | S34: Họ tên: | V34: Họ tên: Nguyễn Chí Kiên
G35: …………………………………………………………………………………............................................ | P35: Ngày: | S35: Ngày: | V35: Ngày :

Sheet 6
E2: DANH SÁCH HỌC VIÊN | J2: Biểu mẫu | N2: Mã số: V.TMM-F10 | S2: Biểu mẫu | W2: Mã số: V.TMM-F05a
J3: ĐIỂM DANH HỌC VIÊN | N3: Ban hành: 04 | S3: KẾT QUẢ ĐÀO TẠO | W3: Ban hành: 04
N4: Hiệu lực: 28/12/2024 | W4: Hiệu lực: 28/12/2024
N5: Trang: 1/1 | W5: Trang: 1/1
B7: - Môn/Khóa học: | D7: Hàng nguy hiểm dành cho người thực hiện nhiệm vụ có tiếp xúc trực tiếp với hành khách tại sân bay | G7: - Môn/Khóa học: | I7: =D7 -> Hàng nguy hiểm dành cho người thực hiện nhiệm vụ có tiếp xúc trực tiếp với hành khách tại sân bay | P7: - Môn/Khóa học: | R7: =I7 -> Hàng nguy hiểm dành cho người thực hiện nhiệm vụ có tiếp xúc trực tiếp với hành khách tại sân bay | Y7: Xóa bớt HV bằng cách xóa cả dòng
B8: - Loại hình/hình thức đào tạo: Phục hồi/Trực tiếp | G8: =B8 -> - Loại hình/hình thức đào tạo: Phục hồi/Trực tiếp | P8: =G8 -> - Loại hình/hình thức đào tạo: Phục hồi/Trực tiếp | Y8: Thêm HV bằng cách copy cả dòng-->bấm phải chuột-->insert copied cells
B9: - Thời gian: | G9: =B9 -> - Thời gian: | I9: =D9 -> 0 | P9: =G9 -> - Thời gian: | R9: =I9 -> 0 | Y9: Điểm trung bình xếp loại, ghi chú, số học viên tham dự tự động điền sau khi nhập điểm LT, TH
B10: - Địa điểm: | D10: TTĐT MB | G10: =B10 -> - Địa điểm: | I10: =D10 -> TTĐT MB | P10: =G10 -> - Địa điểm: | R10: =I10 -> TTĐT MB | Y10: Bôi tất cả các dòng có HV-->Custom Sort theo cột V, cột W
B11: - Giáo viên: | G11: - Số học viên tham dự/tổng số học viên: | K11: =COUNTIF($L$14:$L43,"x")&"/"&COUNTA($L$14:$L43) -> 0/0 | P11: =G11 -> - Số học viên tham dự/tổng số học viên: | T11: =K11 -> 0/0 | Y11: Nhập điểm các lần thi ở đây
B12: STT | C12: Mã NV | D12: Họ tên | E12: Đơn vị | F12: Ghi chú | G12: STT | H12: Mã nhân viên | I12: Họ tên | K12: Đơn vị | L12: Ngày | M12: Ngày | N12: Ngày | O12: Ghi chú | P12: STT | Q12: Mã nhân viên | R12: Họ tên | T12: Đơn vị | U12: Điểm | V12: Xếp loại | W12: Ghi chú | Y12: L1 | Z12: L2 | AA12: L3
L13: =I9 -> 0
B14: =ROW()-13 -> 1 | G14: =B14 -> 1 | H14: =C14 -> 0 | I14: =D14 -> 0 | K14: =E14 -> 0 | P14: =$B14 -> 1 | Q14: =C14 -> 0 | R14: =D14 -> 0 | T14: =E14 -> 0 | U14: =IF($Y14=0,"-",IF(ISBLANK($AA14),IF(ISBLANK($Z14),$Y14,$Y14&"/"&$Z14),$Y14&"/"&$Z14&"/"&$AA14)) -> - | V14: =IF($Y14=0,"-",IF(AND($Y14<80,$Z14<80,$AA14<80),"Không đạt",IF($Y14<95,"Đạt","Xuất sắc"))) -> - | W14: =IF($Y14=0,"Vắng",IF($AA14<>0,"Kiểm tra lần 1/2/3",IF($Z14<>0,"Kiểm tra lần 1/2",""))) -> Vắng
B15: =ROW()-13 -> 2 | G15: =B15 -> 2 | H15: =C15 -> 0 | I15: =D15 -> 0 | K15: =E15 -> 0 | P15: =$B15 -> 2 | Q15: =C15 -> 0 | R15: =D15 -> 0 | T15: =E15 -> 0 | U15: =IF($Y15=0,"-",IF(ISBLANK($AA15),IF(ISBLANK($Z15),$Y15,$Y15&"/"&$Z15),$Y15&"/"&$Z15&"/"&$AA15)) -> - | V15: =IF($Y15=0,"-",IF(AND($Y15<80,$Z15<80,$AA15<80),"Không đạt",IF($Y15<95,"Đạt","Xuất sắc"))) -> - | W15: =IF($Y15=0,"Vắng",IF($AA15<>0,"Kiểm tra lần 1/2/3",IF($Z15<>0,"Kiểm tra lần 1/2",""))) -> Vắng
B16: =ROW()-13 -> 3 | G16: =B16 -> 3 | H16: =C16 -> 0 | I16: =D16 -> 0 | K16: =E16 -> 0 | P16: =$B16 -> 3 | Q16: =C16 -> 0 | R16: =D16 -> 0 | T16: =E16 -> 0 | U16: =IF($Y16=0,"-",IF(ISBLANK($AA16),IF(ISBLANK($Z16),$Y16,$Y16&"/"&$Z16),$Y16&"/"&$Z16&"/"&$AA16)) -> - | V16: =IF($Y16=0,"-",IF(AND($Y16<80,$Z16<80,$AA16<80),"Không đạt",IF($Y16<95,"Đạt","Xuất sắc"))) -> - | W16: =IF($Y16=0,"Vắng",IF($AA16<>0,"Kiểm tra lần 1/2/3",IF($Z16<>0,"Kiểm tra lần 1/2",""))) -> Vắng
B17: =ROW()-13 -> 4 | G17: =B17 -> 4 | H17: =C17 -> 0 | I17: =D17 -> 0 | K17: =E17 -> 0 | P17: =$B17 -> 4 | Q17: =C17 -> 0 | R17: =D17 -> 0 | T17: =E17 -> 0 | U17: =IF($Y17=0,"-",IF(ISBLANK($AA17),IF(ISBLANK($Z17),$Y17,$Y17&"/"&$Z17),$Y17&"/"&$Z17&"/"&$AA17)) -> - | V17: =IF($Y17=0,"-",IF(AND($Y17<80,$Z17<80,$AA17<80),"Không đạt",IF($Y17<95,"Đạt","Xuất sắc"))) -> - | W17: =IF($Y17=0,"Vắng",IF($AA17<>0,"Kiểm tra lần 1/2/3",IF($Z17<>0,"Kiểm tra lần 1/2",""))) -> Vắng
B18: =ROW()-13 -> 5 | G18: =B18 -> 5 | H18: =C18 -> 0 | I18: =D18 -> 0 | K18: =E18 -> 0 | P18: =$B18 -> 5 | Q18: =C18 -> 0 | R18: =D18 -> 0 | T18: =E18 -> 0 | U18: =IF($Y18=0,"-",IF(ISBLANK($AA18),IF(ISBLANK($Z18),$Y18,$Y18&"/"&$Z18),$Y18&"/"&$Z18&"/"&$AA18)) -> - | V18: =IF($Y18=0,"-",IF(AND($Y18<80,$Z18<80,$AA18<80),"Không đạt",IF($Y18<95,"Đạt","Xuất sắc"))) -> - | W18: =IF($Y18=0,"Vắng",IF($AA18<>0,"Kiểm tra lần 1/2/3",IF($Z18<>0,"Kiểm tra lần 1/2",""))) -> Vắng
B19: =ROW()-13 -> 6 | G19: =B19 -> 6 | H19: =C19 -> 0 | I19: =D19 -> 0 | K19: =E19 -> 0 | P19: =$B19 -> 6 | Q19: =C19 -> 0 | R19: =D19 -> 0 | T19: =E19 -> 0 | U19: =IF($Y19=0,"-",IF(ISBLANK($AA19),IF(ISBLANK($Z19),$Y19,$Y19&"/"&$Z19),$Y19&"/"&$Z19&"/"&$AA19)) -> - | V19: =IF($Y19=0,"-",IF(AND($Y19<80,$Z19<80,$AA19<80),"Không đạt",IF($Y19<95,"Đạt","Xuất sắc"))) -> - | W19: =IF($Y19=0,"Vắng",IF($AA19<>0,"Kiểm tra lần 1/2/3",IF($Z19<>0,"Kiểm tra lần 1/2",""))) -> Vắng
B20: =ROW()-13 -> 7 | G20: =B20 -> 7 | H20: =C20 -> 0 | I20: =D20 -> 0 | K20: =E20 -> 0 | P20: =$B20 -> 7 | Q20: =C20 -> 0 | R20: =D20 -> 0 | T20: =E20 -> 0 | U20: =IF($Y20=0,"-",IF(ISBLANK($AA20),IF(ISBLANK($Z20),$Y20,$Y20&"/"&$Z20),$Y20&"/"&$Z20&"/"&$AA20)) -> - | V20: =IF($Y20=0,"-",IF(AND($Y20<80,$Z20<80,$AA20<80),"Không đạt",IF($Y20<95,"Đạt","Xuất sắc"))) -> - | W20: =IF($Y20=0,"Vắng",IF($AA20<>0,"Kiểm tra lần 1/2/3",IF($Z20<>0,"Kiểm tra lần 1/2",""))) -> Vắng
B21: =ROW()-13 -> 8 | G21: =B21 -> 8 | H21: =C21 -> 0 | I21: =D21 -> 0 | K21: =E21 -> 0 | P21: =$B21 -> 8 | Q21: =C21 -> 0 | R21: =D21 -> 0 | T21: =E21 -> 0 | U21: =IF($Y21=0,"-",IF(ISBLANK($AA21),IF(ISBLANK($Z21),$Y21,$Y21&"/"&$Z21),$Y21&"/"&$Z21&"/"&$AA21)) -> - | V21: =IF($Y21=0,"-",IF(AND($Y21<80,$Z21<80,$AA21<80),"Không đạt",IF($Y21<95,"Đạt","Xuất sắc"))) -> - | W21: =IF($Y21=0,"Vắng",IF($AA21<>0,"Kiểm tra lần 1/2/3",IF($Z21<>0,"Kiểm tra lần 1/2",""))) -> Vắng
B22: =ROW()-13 -> 9 | G22: =B22 -> 9 | H22: =C22 -> 0 | I22: =D22 -> 0 | K22: =E22 -> 0 | P22: =$B22 -> 9 | Q22: =C22 -> 0 | R22: =D22 -> 0 | T22: =E22 -> 0 | U22: =IF($Y22=0,"-",IF(ISBLANK($AA22),IF(ISBLANK($Z22),$Y22,$Y22&"/"&$Z22),$Y22&"/"&$Z22&"/"&$AA22)) -> - | V22: =IF($Y22=0,"-",IF(AND($Y22<80,$Z22<80,$AA22<80),"Không đạt",IF($Y22<95,"Đạt","Xuất sắc"))) -> - | W22: =IF($Y22=0,"Vắng",IF($AA22<>0,"Kiểm tra lần 1/2/3",IF($Z22<>0,"Kiểm tra lần 1/2",""))) -> Vắng
B23: =ROW()-13 -> 10 | G23: =B23 -> 10 | H23: =C23 -> 0 | I23: =D23 -> 0 | K23: =E23 -> 0 | P23: =$B23 -> 10 | Q23: =C23 -> 0 | R23: =D23 -> 0 | T23: =E23 -> 0 | U23: =IF($Y23=0,"-",IF(ISBLANK($AA23),IF(ISBLANK($Z23),$Y23,$Y23&"/"&$Z23),$Y23&"/"&$Z23&"/"&$AA23)) -> - | V23: =IF($Y23=0,"-",IF(AND($Y23<80,$Z23<80,$AA23<80),"Không đạt",IF($Y23<95,"Đạt","Xuất sắc"))) -> - | W23: =IF($Y23=0,"Vắng",IF($AA23<>0,"Kiểm tra lần 1/2/3",IF($Z23<>0,"Kiểm tra lần 1/2",""))) -> Vắng
B24: =ROW()-13 -> 11 | G24: =B24 -> 11 | H24: =C24 -> 0 | I24: =D24 -> 0 | K24: =E24 -> 0 | P24: =$B24 -> 11 | Q24: =C24 -> 0 | R24: =D24 -> 0 | T24: =E24 -> 0 | U24: =IF($Y24=0,"-",IF(ISBLANK($AA24),IF(ISBLANK($Z24),$Y24,$Y24&"/"&$Z24),$Y24&"/"&$Z24&"/"&$AA24)) -> - | V24: =IF($Y24=0,"-",IF(AND($Y24<80,$Z24<80,$AA24<80),"Không đạt",IF($Y24<95,"Đạt","Xuất sắc"))) -> - | W24: =IF($Y24=0,"Vắng",IF($AA24<>0,"Kiểm tra lần 1/2/3",IF($Z24<>0,"Kiểm tra lần 1/2",""))) -> Vắng
B25: =ROW()-13 -> 12 | G25: =B25 -> 12 | H25: =C25 -> 0 | I25: =D25 -> 0 | K25: =E25 -> 0 | P25: =$B25 -> 12 | Q25: =C25 -> 0 | R25: =D25 -> 0 | T25: =E25 -> 0 | U25: =IF($Y25=0,"-",IF(ISBLANK($AA25),IF(ISBLANK($Z25),$Y25,$Y25&"/"&$Z25),$Y25&"/"&$Z25&"/"&$AA25)) -> - | V25: =IF($Y25=0,"-",IF(AND($Y25<80,$Z25<80,$AA25<80),"Không đạt",IF($Y25<95,"Đạt","Xuất sắc"))) -> - | W25: =IF($Y25=0,"Vắng",IF($AA25<>0,"Kiểm tra lần 1/2/3",IF($Z25<>0,"Kiểm tra lần 1/2",""))) -> Vắng
... B29: =ROW()-13 -> 16 | G29: =B29 -> 16 | H29: =C29 -> 0 | I29: =D29 -> 0 | K29: =E29 -> 0 | P29: =$B29 -> 16 | Q29: =C29 -> 0 | R29: =D29 -> 0 | T29: =E29 -> 0 | U29: =IF($Y29=0,"-",IF(ISBLANK($AA29),IF(ISBLANK($Z29),$Y29,$Y29&"/"&$Z29),$Y29&"/"&$Z29&"/"&$AA29)) -> - | V29: =IF($Y29=0,"-",IF(AND($Y29<80,$Z29<80,$AA29<80),"Không đạt",IF($Y29<95,"Đạt","Xuất sắc"))) -> - | W29: =IF($Y29=0,"Vắng",IF($AA29<>0,"Kiểm tra lần 1/2/3",IF($Z29<>0,"Kiểm tra lần 1/2",""))) -> Vắng
C30: Trưởng Trung tâm đào tạo | F30: Người lập | H30: Chữ ký giáo viên: | P30: Giáo viên hướng dẫn: | S30: Trưởng bộ môn: | V30: Trưởng TTĐT:
G32: Lưu ý:
G33: - Giáo viên điểm danh theo ngày và đánh dấu: X: có mặt; V: vắng mặt
C34: Nguyễn Chí Kiên | F34: Nguyễn Cao Bình | G34: - Trang thiết bị thực hành (áp dụng đối với nội dung thực hành Nghiệp vụ điều khiển/vận hành thiết bị): | P34: Họ tên: | S34: Họ tên: | V34: Họ tên: Nguyễn Chí Kiên
G35: …………………………………………………………………………………............................................ | P35: Ngày: | S35: Ngày: | V35: Ngày :

Sheet 7
E2: DANH SÁCH HỌC VIÊN | J2: Biểu mẫu | N2: Mã số: V.TMM-F10 | S2: Biểu mẫu | W2: Mã số: V.TMM-F05a
J3: ĐIỂM DANH HỌC VIÊN | N3: Ban hành: 04 | S3: KẾT QUẢ ĐÀO TẠO | W3: Ban hành: 04
N4: Hiệu lực: 28/12/2024 | W4: Hiệu lực: 28/12/2024
N5: Trang: 1/1 | W5: Trang: 1/1
B7: - Môn/Khóa học: | D7: HNH dành cho người chịu trách nhiệm chấp nhận hành lý của hành khách và tổ bay, kiểm soát khu vực cửa khởi hành | G7: - Môn/Khóa học: | I7: =D7 -> HNH dành cho người chịu trách nhiệm chấp nhận hành lý của hành khách và tổ bay, kiểm soát khu vực cửa khởi hành | P7: - Môn/Khóa học: | R7: =I7 -> HNH dành cho người chịu trách nhiệm chấp nhận hành lý của hành khách và tổ bay, kiểm soát khu vực cửa khởi hành | Y7: Xóa bớt HV bằng cách xóa cả dòng
B8: - Loại hình/hình thức đào tạo: Phục hồi/Trực tiếp | G8: =B8 -> - Loại hình/hình thức đào tạo: Phục hồi/Trực tiếp | P8: =G8 -> - Loại hình/hình thức đào tạo: Phục hồi/Trực tiếp | Y8: Thêm HV bằng cách copy cả dòng-->bấm phải chuột-->insert copied cells
B9: - Thời gian: | G9: =B9 -> - Thời gian: | I9: =D9 -> 0 | P9: =G9 -> - Thời gian: | R9: =I9 -> 0 | Y9: Điểm trung bình xếp loại, ghi chú, số học viên tham dự tự động điền sau khi nhập điểm LT, TH
B10: - Địa điểm: | D10: TTĐT MB | G10: =B10 -> - Địa điểm: | I10: =D10 -> TTĐT MB | P10: =G10 -> - Địa điểm: | R10: =I10 -> TTĐT MB | Y10: Bôi tất cả các dòng có HV-->Custom Sort theo cột V, cột W
B11: - Giáo viên: | G11: - Số học viên tham dự/tổng số học viên: | K11: =COUNTIF($L$14:$L43,"x")&"/"&COUNTA($L$14:$L43) -> 0/0 | P11: =G11 -> - Số học viên tham dự/tổng số học viên: | T11: =K11 -> 0/0 | Y11: Nhập điểm các lần thi ở đây
B12: STT | C12: Mã NV | D12: Họ tên | E12: Đơn vị | F12: Ghi chú | G12: STT | H12: Mã nhân viên | I12: Họ tên | K12: Đơn vị | L12: Ngày | M12: Ngày | N12: Ngày | O12: Ghi chú | P12: STT | Q12: Mã nhân viên | R12: Họ tên | T12: Đơn vị | U12: Điểm | V12: Xếp loại | W12: Ghi chú | Y12: L1 | Z12: L2 | AA12: L3
L13: =I9 -> 0
B14: =ROW()-13 -> 1 | G14: =B14 -> 1 | H14: =C14 -> 0 | I14: =D14 -> 0 | K14: =E14 -> 0 | P14: =$B14 -> 1 | Q14: =C14 -> 0 | R14: =D14 -> 0 | T14: =E14 -> 0 | U14: =IF($Y14=0,"-",IF(ISBLANK($AA14),IF(ISBLANK($Z14),$Y14,$Y14&"/"&$Z14),$Y14&"/"&$Z14&"/"&$AA14)) -> - | V14: =IF($Y14=0,"-",IF(AND($Y14<80,$Z14<80,$AA14<80),"Không đạt",IF($Y14<95,"Đạt","Xuất sắc"))) -> - | W14: =IF($Y14=0,"Vắng",IF($AA14<>0,"Kiểm tra lần 1/2/3",IF($Z14<>0,"Kiểm tra lần 1/2",""))) -> Vắng
B15: =ROW()-13 -> 2 | G15: =B15 -> 2 | H15: =C15 -> 0 | I15: =D15 -> 0 | K15: =E15 -> 0 | P15: =$B15 -> 2 | Q15: =C15 -> 0 | R15: =D15 -> 0 | T15: =E15 -> 0 | U15: =IF($Y15=0,"-",IF(ISBLANK($AA15),IF(ISBLANK($Z15),$Y15,$Y15&"/"&$Z15),$Y15&"/"&$Z15&"/"&$AA15)) -> - | V15: =IF($Y15=0,"-",IF(AND($Y15<80,$Z15<80,$AA15<80),"Không đạt",IF($Y15<95,"Đạt","Xuất sắc"))) -> - | W15: =IF($Y15=0,"Vắng",IF($AA15<>0,"Kiểm tra lần 1/2/3",IF($Z15<>0,"Kiểm tra lần 1/2",""))) -> Vắng
B16: =ROW()-13 -> 3 | G16: =B16 -> 3 | H16: =C16 -> 0 | I16: =D16 -> 0 | K16: =E16 -> 0 | P16: =$B16 -> 3 | Q16: =C16 -> 0 | R16: =D16 -> 0 | T16: =E16 -> 0 | U16: =IF($Y16=0,"-",IF(ISBLANK($AA16),IF(ISBLANK($Z16),$Y16,$Y16&"/"&$Z16),$Y16&"/"&$Z16&"/"&$AA16)) -> - | V16: =IF($Y16=0,"-",IF(AND($Y16<80,$Z16<80,$AA16<80),"Không đạt",IF($Y16<95,"Đạt","Xuất sắc"))) -> - | W16: =IF($Y16=0,"Vắng",IF($AA16<>0,"Kiểm tra lần 1/2/3",IF($Z16<>0,"Kiểm tra lần 1/2",""))) -> Vắng
B17: =ROW()-13 -> 4 | G17: =B17 -> 4 | H17: =C17 -> 0 | I17: =D17 -> 0 | K17: =E17 -> 0 | P17: =$B17 -> 4 | Q17: =C17 -> 0 | R17: =D17 -> 0 | T17: =E17 -> 0 | U17: =IF($Y17=0,"-",IF(ISBLANK($AA17),IF(ISBLANK($Z17),$Y17,$Y17&"/"&$Z17),$Y17&"/"&$Z17&"/"&$AA17)) -> - | V17: =IF($Y17=0,"-",IF(AND($Y17<80,$Z17<80,$AA17<80),"Không đạt",IF($Y17<95,"Đạt","Xuất sắc"))) -> - | W17: =IF($Y17=0,"Vắng",IF($AA17<>0,"Kiểm tra lần 1/2/3",IF($Z17<>0,"Kiểm tra lần 1/2",""))) -> Vắng
