Workbook
Name Index: 'Muc luc'!$A$1

Sheet Muc luc
A1: DANH SACH CAC SHEET | C1: Ấn vào tên lớp để nhảy ra sheet danh sách | F1: Ấn vào logo VIAGS để trở về mục lục
A2: STT | B2: Lớp học | C2: Ngày học | D2: Địa điểm | E2: Giáo viên
A3: 1 | B3: ='1'!$D$7 -> 0 | C3: ='1'!$D$9 -> Từ 17/8/2026 | D3: ='1'!$D$10 -> VNBA | E3: ='1'!$D$11 -> 0
A4: 2 | B4: ='2'!$D$7 -> 0 | C4: ='2'!$D9 -> C17/8/2026 | D4: ='2'!$D$10 -> VNBA | E4: ='2'!$D$11 -> 0
A5: 3 | B5: ='3'!$D$7 -> 0 | C5: ='3'!$D9 -> 18/8/2026 | D5: ='3'!$D$10 -> VNBA | E5: ='3'!$D$11 -> 0
A6: 4 | B6: ='4'!$D$7 -> 0 | C6: ='4'!$D9 -> 19/8/2026 | D6: ='4'!$D$10 -> TTĐT | E6: ='4'!$D$11 -> 0
A7: 5 | B7: ='5'!$D$7 -> 0 | C7: ='5'!$D$9 -> S18/8/2026 | D7: ='5'!$D$10 -> VNBA | E7: ='5'!$D$11 -> 0
A8: 6 | B8: ='6'!$D$7 -> 0 | C8: ='6'!$D$9 -> C18/8/2026 | D8: ='6'!$D$10 -> VNBA | E8: ='6'!$D$11 -> 0
A9: 7 | B9: ='7'!$D$7 -> 0 | C9: ='7'!$D$9 -> S18/8/2026 | D9: ='7'!$D$10 -> TTĐT | E9: ='7'!$D$11 -> 0
A10: 8 | B10: ='8'!$D$7 -> 0 | C10: ='8'!$D$9 -> S18/8/2026 | D10: ='8'!$D$10 -> TTĐT | E10: ='8'!$D$11 -> 0
A11: 9 | B11: ='9'!$D$7 -> 0 | C11: ='9'!$D$9 -> S17/8/2026 | D11: ='9'!$D$10 -> TTĐT | E11: ='9'!$D$11 -> 0
A12: 10 | B12: ='10'!$D$7 -> 0 | C12: ='10'!$D$9 -> C17/8/2026 | D12: ='10'!$D$10 -> TTĐT | E12: ='10'!$D$11 -> 0
A13: 11 | B13: ='11'!$D$7 -> 0 | C13: ='11'!$D$9 -> S18/8/2026 | D13: ='11'!$D$10 -> TTĐT | E13: ='11'!$D$11 -> 0
A14: 12 | B14: ='12'!$D$7 -> 0 | C14: ='12'!$D$9 -> S17/8/2026 | D14: ='12'!$D$10 -> TTĐT | E14: ='12'!$D$11 -> 0
A15: 13 | B15: ='13'!$D$7 -> 0 | C15: ='13'!$D$9 -> S21/8/2026 | D15: ='13'!$D$10 -> TTĐT | E15: ='13'!$D$11 -> 0
A16: 14 | B16: ='14'!$D$7 -> 0 | C16: ='14'!$D$9 -> 19/8/2026 | D16: ='14'!$D$10 -> TTĐT | E16: ='14'!$D$11 -> 0
A17: 15 | B17: ='15'!$D$7 -> 0 | C17: ='15'!$D$9 -> 20/8/2026 | D17: ='15'!$D$10 -> TTĐT | E17: ='15'!$D$11 -> 0
A18: 16 | B18: ='16'!$D$7 -> 0 | C18: ='16'!$D$9 -> C21/8/2026 | D18: ='16'!$D$10 -> TTĐT | E18: ='16'!$D$11 -> 0
A19: 17 | B19: ='17'!$D$7 -> 0 | C19: ='17'!$D$9 -> C17/8/2026 | D19: ='17'!$D$10 -> TTĐT | E19: ='17'!$D11 -> 0
A20: 18 | B20: ='18'!$D$7 -> 0 | C20: ='18'!$D$9 -> S17/8/2026 | D20: ='18'!$D$10 -> TTĐT | E20: ='18'!$D$11 -> 0
A21: 19 | B21: ='19'!$D$7 -> 0 | C21: ='19'!$D$9 -> 18/8/2026 | D21: ='19'!$D$10 -> VNBA | E21: ='19'!$D$11 -> 0
A22: 20 | B22: ='20'!$D$7 -> 0 | C22: ='20'!$D$9 -> C20/8/2026 | D22: ='20'!$D$10 -> TTĐT | E22: ='20'!$D$11 -> 0
A23: 21 | B23: ='21'!$D$7 -> 0 | C23: ='21'!$D$9 -> 17/8/2026 | D23: ='21'!$D$10 -> VNBA | E23: ='21'!$D$11 -> 0
A24: 22 | B24: ='22'!$D$7 -> 0 | C24: ='22'!$D$9 -> 17-19/8/2026 | D24: ='22'!$D$10 -> TTĐT | E24: ='22'!$D$11 -> 0
A25: 23 | B25: ='23'!$D$7 -> 0 | C25: ='23'!$D$9 -> 20-S21/8/2026 | D25: ='23'!$D$10 -> TTĐT | E25: ='23'!$D$11 -> 0
A26: 24 | B26: ='24'!$D$7 -> 0 | C26: ='24'!$D$9 -> S18/8/2026 | D26: ='24'!$D$10 -> TTĐT | E26: ='24'!$D$11 -> 0
A27: 25 | B27: ='25'!$D$7 -> 0 | C27: ='25'!$D$9 -> C18/8/2026 | D27: ='25'!$D$10 -> TTĐT | E27: ='25'!$D$11 -> 0
A28: 26 | B28: ='26'!$D$7 -> 0 | C28: ='26'!$D$9 -> 20-S21/8/2026 | D28: ='26'!$D$10 -> VNBA | E28: ='26'!$D$11 -> 0
A29: 27 | B29: ='27'!$D$7 -> 0 | C29: ='27'!$D$9 -> C18/8/2026 | D29: ='27'!$D$10 -> TTĐT | E29: ='27'!$D$11 -> 0
A30: 28 | B30: ='28'!$D$7 -> 0 | C30: ='28'!$D$9 -> C20/8/2026 | D30: ='28'!$D$10 -> TTĐT | E30: ='28'!$D$11 -> 0
A31: 29 | B31: ='29'!$D$7 -> 0 | C31: ='29'!$D$9 -> 19/8/2026 | D31: ='29'!$D$10 -> TTĐT | E31: ='29'!$D$11 -> 0
A32: 30 | B32: ='30'!$D$7 -> 0 | C32: ='30'!$D$9 -> 20/8/2026 | D32: ='30'!$D$10 -> TTĐT | E32: ='30'!$D$11 -> 0
A33: 31 | B33: ='31'!$D$7 -> 0 | C33: ='31'!$D$9 -> S18/8/2026 | D33: ='31'!$D$10 -> TTĐT | E33: ='31'!$D$11 -> 0
A34: 32 | B34: ='32'!$D$7 -> 0 | C34: ='32'!$D$9 -> S18/8/2026 | D34: ='32'!$D$10 -> TTĐT | E34: ='32'!$D$11 -> 0
A35: 33 | B35: ='33'!$D$7 -> 0 | C35: ='33'!$D$9 -> C18/8/2026 | D35: ='33'!$D$10 -> TTĐT | E35: ='33'!$D$11 -> 0
A36: 34 | B36: ='34'!$D$7 -> 0 | C36: ='34'!$D$9 -> C18/8/2026 | D36: ='34'!$D$10 -> TTĐT | E36: ='34'!$D$11 -> 0
A37: 35 | B37: ='35'!$D$7 -> 0 | C37: ='35'!$D$9 -> C17/8/2026 | D37: ='35'!$D$10 -> VNBA | E37: ='35'!$D$11 -> 0
A38: 36 | B38: ='36'!$D$7 -> 0 | C38: ='36'!$D$9 -> C18/8/2026 | D38: ='36'!$D$10 -> VNBA | E38: ='36'!$D$11 -> 0
A39: 37 | B39: ='37'!$D$7 -> 0 | C39: ='37'!$D$9 -> C21/8/2026 | D39: ='37'!$D$10 -> VNBA | E39: ='37'!$D$11 -> 0
A40: 38 | B40: ='38'!$D$7 -> 0 | C40: ='38'!$D$9 -> 19/8/2026 | D40: ='38'!$D$10 -> TTĐT | E40: ='38'!$D$11 -> 0
...

Sheet 1
E2: DANH SÁCH HỌC VIÊN | J2: Biểu mẫu | N2: Mã số: V.TMM-F10
J3: ĐIỂM DANH HỌC VIÊN | N3: Ban hành: 04
N4: Hiệu lực: 28/12/2024
N5: Trang: 1/1
B7: - Môn/Khóa học: | G7: - Môn/Khóa học: | I7: =D7 -> 0
B8: - Loại hình/hình thức đào tạo: Ban đầu/Trực tiếp | G8: =B8 -> - Loại hình/hình thức đào tạo: Ban đầu/Trực tiếp
B9: - Thời gian: | D9: Từ 17/8/2026 | G9: =B9 -> - Thời gian: | I9: =D9 -> Từ 17/8/2026
B10: - Địa điểm: | D10: VNBA | G10: =B10 -> - Địa điểm: | I10: =D10 -> VNBA
B11: - Giáo viên: | G11: - Số học viên tham dự/tổng số học viên: | K11: =COUNTIF($L$14:$L32,"x")&"/"&COUNTA($L$14:$L32) -> 0/0
B12: STT | C12: Mã NV | D12: Họ tên | E12: Đơn vị | F12: Ghi chú | G12: STT | H12: Mã nhân viên | I12: Họ tên | K12: Đơn vị | L12: Ngày | M12: Ngày | N12: Ngày | O12: Ghi chú
L13: =I9 -> Từ 17/8/2026
B14: =ROW()-13 -> 1 | G14: =B14 -> 1 | H14: =C14 -> 0 | I14: =D14 -> 0 | K14: =E14 -> 0
B15: =ROW()-13 -> 2 | G15: =B15 -> 2 | H15: =C15 -> 0 | I15: =D15 -> 0 | K15: =E15 -> 0
B16: =ROW()-13 -> 3 | G16: =B16 -> 3 | H16: =C16 -> 0 | I16: =D16 -> 0 | K16: =E16 -> 0
B17: =ROW()-13 -> 4 | G17: =B17 -> 4 | H17: =C17 -> 0 | I17: =D17 -> 0 | K17: =E17 -> 0
B18: =ROW()-13 -> 5 | G18: =B18 -> 5 | H18: =C18 -> 0 | I18: =D18 -> 0 | K18: =E18 -> 0
C19: P.Trưởng Trung tâm đào tạo | F19: Người lập | H19: Chữ ký giáo viên:
G21: Lưu ý:
G22: - Giáo viên điểm danh theo ngày và đánh dấu: X: có mặt; V: vắng mặt
C23: Ngô Trung Thành | F23: Nguyễn Cao Bình | G23: - Trang thiết bị thực hành (áp dụng đối với nội dung thực hành Nghiệp vụ điều khiển/vận hành thiết bị):
G24: …………………………………………………………………………………............................................

Sheet 2
E2: DANH SÁCH HỌC VIÊN | J2: Biểu mẫu | N2: Mã số: V.TMM-F10
J3: ĐIỂM DANH HỌC VIÊN | N3: Ban hành: 04
N4: Hiệu lực: 28/12/2024
N5: Trang: 1/1
B7: - Môn/Khóa học: | G7: - Môn/Khóa học: | I7: =D7 -> 0
B8: - Loại hình/hình thức đào tạo: Ban đầu/Trực tiếp | G8: =B8 -> - Loại hình/hình thức đào tạo: Ban đầu/Trực tiếp
B9: - Thời gian: | D9: C17/8/2026 | G9: =B9 -> - Thời gian: | I9: =D9 -> C17/8/2026
B10: - Địa điểm: | D10: VNBA | G10: =B10 -> - Địa điểm: | I10: =D10 -> VNBA
B11: - Giáo viên: | G11: - Số học viên tham dự/tổng số học viên: | K11: =COUNTIF($L$14:$L31,"x")&"/"&COUNTA($L$14:$L31) -> 0/0
B12: STT | C12: Mã NV | D12: Họ tên | E12: Đơn vị | F12: Ghi chú | G12: STT | H12: Mã nhân viên | I12: Họ tên | K12: Đơn vị | L12: Ngày | M12: Ngày | N12: Ngày | O12: Ghi chú
L13: =I9 -> C17/8/2026
B14: =ROW()-13 -> 1 | G14: =B14 -> 1 | H14: =C14 -> 0 | I14: =D14 -> 0 | K14: =E14 -> 0
B15: =ROW()-13 -> 2 | G15: =B15 -> 2 | H15: =C15 -> 0 | I15: =D15 -> 0 | K15: =E15 -> 0
B16: =ROW()-13 -> 3 | G16: =B16 -> 3 | H16: =C16 -> 0 | I16: =D16 -> 0 | K16: =E16 -> 0
B17: =ROW()-13 -> 4 | G17: =B17 -> 4 | H17: =C17 -> 0 | I17: =D17 -> 0 | K17: =E17 -> 0
C18: P.Trưởng Trung tâm đào tạo | F18: Người lập | H18: Chữ ký giáo viên:
G20: Lưu ý:
G21: - Giáo viên điểm danh theo ngày và đánh dấu: X: có mặt; V: vắng mặt
C22: Ngô Trung Thành | F22: Nguyễn Cao Bình | G22: - Trang thiết bị thực hành (áp dụng đối với nội dung thực hành Nghiệp vụ điều khiển/vận hành thiết bị):
G23: …………………………………………………………………………………............................................

Sheet 3
E2: DANH SÁCH HỌC VIÊN | J2: Biểu mẫu | N2: Mã số: V.TMM-F10
J3: ĐIỂM DANH HỌC VIÊN | N3: Ban hành: 04
N4: Hiệu lực: 28/12/2024
N5: Trang: 1/1
B7: - Môn/Khóa học: | G7: - Môn/Khóa học: | I7: =D7 -> 0
B8: - Loại hình/hình thức đào tạo: Ban đầu/Trực tiếp | G8: =B8 -> - Loại hình/hình thức đào tạo: Ban đầu/Trực tiếp
B9: - Thời gian: | D9: 18/8/2026 | G9: =B9 -> - Thời gian: | I9: =D9 -> 18/8/2026
B10: - Địa điểm: | D10: VNBA | G10: =B10 -> - Địa điểm: | I10: =D10 -> VNBA
B11: - Giáo viên: | G11: - Số học viên tham dự/tổng số học viên: | K11: =COUNTIF($L$14:$L31,"x")&"/"&COUNTA($L$14:$L31) -> 0/0
B12: STT | C12: Mã NV | D12: Họ tên | E12: Đơn vị | F12: Ghi chú | G12: STT | H12: Mã nhân viên | I12: Họ tên | K12: Đơn vị | L12: Ngày | M12: Ngày | N12: Ngày | O12: Ghi chú
L13: =I9 -> 18/8/2026
B14: =ROW()-13 -> 1 | G14: =B14 -> 1 | H14: =C14 -> 0 | I14: =D14 -> 0 | K14: =E14 -> 0
B15: =ROW()-13 -> 2 | G15: =B15 -> 2 | H15: =C15 -> 0 | I15: =D15 -> 0 | K15: =E15 -> 0
B16: =ROW()-13 -> 3 | G16: =B16 -> 3 | H16: =C16 -> 0 | I16: =D16 -> 0 | K16: =E16 -> 0
B17: =ROW()-13 -> 4 | G17: =B17 -> 4 | H17: =C17 -> 0 | I17: =D17 -> 0 | K17: =E17 -> 0
C18: P.Trưởng Trung tâm đào tạo | F18: Người lập | H18: Chữ ký giáo viên:
G20: Lưu ý:
G21: - Giáo viên điểm danh theo ngày và đánh dấu: X: có mặt; V: vắng mặt
C22: Ngô Trung Thành | F22: Nguyễn Cao Bình | G22: - Trang thiết bị thực hành (áp dụng đối với nội dung thực hành Nghiệp vụ điều khiển/vận hành thiết bị):
G23: …………………………………………………………………………………............................................

Sheet 4
E2: DANH SÁCH HỌC VIÊN | J2: Biểu mẫu | N2: Mã số: V.TMM-F10
J3: ĐIỂM DANH HỌC VIÊN | N3: Ban hành: 04
N4: Hiệu lực: 28/12/2024
N5: Trang: 1/1
B7: - Môn/Khóa học: | G7: - Môn/Khóa học: | I7: =D7 -> 0
B8: - Loại hình/hình thức đào tạo: Ban đầu/Elearning+Trực tiếp | G8: =B8 -> - Loại hình/hình thức đào tạo: Ban đầu/Elearning+Trực tiếp
B9: - Thời gian: | D9: 19/8/2026 | G9: =B9 -> - Thời gian: | I9: =D9 -> 19/8/2026
B10: - Địa điểm: | D10: TTĐT | G10: =B10 -> - Địa điểm: | I10: =D10 -> TTĐT
B11: - Giáo viên: | G11: - Số học viên tham dự/tổng số học viên: | K11: =COUNTIF($L$14:$L38,"x")&"/"&COUNTA($L$14:$L38) -> 0/0
B12: STT | C12: Mã NV | D12: Họ tên | E12: Đơn vị | F12: Ghi chú | G12: STT | H12: Mã nhân viên | I12: Họ tên | K12: Đơn vị | L12: Ngày | M12: Ngày | N12: Ngày | O12: Ghi chú
L13: =I9 -> 19/8/2026
B14: =ROW()-13 -> 1 | G14: =B14 -> 1 | H14: =C14 -> 0 | I14: =D14 -> 0 | K14: =E14 -> 0
B15: =ROW()-13 -> 2 | G15: =B15 -> 2 | H15: =C15 -> 0 | I15: =D15 -> 0 | K15: =E15 -> 0
B16: =ROW()-13 -> 3 | G16: =B16 -> 3 | H16: =C16 -> 0 | I16: =D16 -> 0 | K16: =E16 -> 0
B17: =ROW()-13 -> 4 | G17: =B17 -> 4 | H17: =C17 -> 0 | I17: =D17 -> 0 | K17: =E17 -> 0
B18: =ROW()-13 -> 5 | G18: =B18 -> 5 | H18: =C18 -> 0 | I18: =D18 -> 0 | K18: =E18 -> 0
B19: =ROW()-13 -> 6 | G19: =B19 -> 6 | H19: =C19 -> 0 | I19: =D19 -> 0 | K19: =E19 -> 0
B20: =ROW()-13 -> 7 | G20: =B20 -> 7 | H20: =C20 -> 0 | I20: =D20 -> 0 | K20: =E20 -> 0
B21: =ROW()-13 -> 8 | G21: =B21 -> 8 | H21: =C21 -> 0 | I21: =D21 -> 0 | K21: =E21 -> 0
B22: =ROW()-13 -> 9 | G22: =B22 -> 9 | H22: =C22 -> 0 | I22: =D22 -> 0 | K22: =E22 -> 0
B23: =ROW()-13 -> 10 | G23: =B23 -> 10 | H23: =C23 -> 0 | I23: =D23 -> 0 | K23: =E23 -> 0
B24: =ROW()-13 -> 11 | G24: =B24 -> 11 | H24: =C24 -> 0 | I24: =D24 -> 0 | K24: =E24 -> 0
C25: P.Trưởng Trung tâm đào tạo | F25: Người lập | H25: Chữ ký giáo viên:
G27: Lưu ý:
G28: - Giáo viên điểm danh theo ngày và đánh dấu: X: có mặt; V: vắng mặt
C29: Ngô Trung Thành | F29: Nguyễn Cao Bình | G29: - Trang thiết bị thực hành (áp dụng đối với nội dung thực hành Nghiệp vụ điều khiển/vận hành thiết bị):
G30: …………………………………………………………………………………............................................

Sheet 5
E2: DANH SÁCH HỌC VIÊN | J2: Biểu mẫu | N2: Mã số: V.TMM-F10
J3: ĐIỂM DANH HỌC VIÊN | N3: Ban hành: 04
N4: Hiệu lực: 28/12/2024
N5: Trang: 1/1
B7: - Môn/Khóa học: | G7: - Môn/Khóa học: | I7: =D7 -> 0
B8: - Loại hình/hình thức đào tạo: Ban đầu/Trực tiếp | G8: =B8 -> - Loại hình/hình thức đào tạo: Ban đầu/Trực tiếp
B9: - Thời gian: | D9: S18/8/2026 | G9: =B9 -> - Thời gian: | I9: =D9 -> S18/8/2026
B10: - Địa điểm: | D10: VNBA | G10: =B10 -> - Địa điểm: | I10: =D10 -> VNBA
B11: - Giáo viên: | G11: - Số học viên tham dự/tổng số học viên: | K11: =COUNTIF($L$14:$L29,"x")&"/"&COUNTA($L$14:$L29) -> 0/0
B12: STT | C12: Mã NV | D12: Họ tên | E12: Đơn vị | F12: Ghi chú | G12: STT | H12: Mã nhân viên | I12: Họ tên | K12: Đơn vị | L12: Ngày | M12: Ngày | N12: Ngày | O12: Ghi chú
L13: =I9 -> S18/8/2026
B14: =ROW()-13 -> 1 | G14: =B14 -> 1 | H14: =C14 -> 0 | I14: =D14 -> 0 | K14: =E14 -> 0
B15: =ROW()-13 -> 2 | G15: =B15 -> 2 | H15: =C15 -> 0 | I15: =D15 -> 0 | K15: =E15 -> 0
C16: P.Trưởng Trung tâm đào tạo | F16: Người lập | H16: Chữ ký giáo viên:
G18: Lưu ý:
G19: - Giáo viên điểm danh theo ngày và đánh dấu: X: có mặt; V: vắng mặt
C20: Ngô Trung Thành | F20: Nguyễn Cao Bình | G20: - Trang thiết bị thực hành (áp dụng đối với nội dung thực hành Nghiệp vụ điều khiển/vận hành thiết bị):
G21: …………………………………………………………………………………............................................

Sheet 6
E2: DANH SÁCH HỌC VIÊN | J2: Biểu mẫu | N2: Mã số: V.TMM-F10
J3: ĐIỂM DANH HỌC VIÊN | N3: Ban hành: 04
N4: Hiệu lực: 28/12/2024
N5: Trang: 1/1
B7: - Môn/Khóa học: | G7: - Môn/Khóa học: | I7: =D7 -> 0
B8: - Loại hình/hình thức đào tạo: Ban đầu/Trực tiếp | G8: =B8 -> - Loại hình/hình thức đào tạo: Ban đầu/Trực tiếp
B9: - Thời gian: | D9: C18/8/2026 | G9: =B9 -> - Thời gian: | I9: =D9 -> C18/8/2026
B10: - Địa điểm: | D10: VNBA | G10: =B10 -> - Địa điểm: | I10: =D10 -> VNBA
B11: - Giáo viên: | G11: - Số học viên tham dự/tổng số học viên: | K11: =COUNTIF($L$16:$L29,"x")&"/"&COUNTA($L$16:$L29) -> 0/0
B12: STT | C12: Mã NV | D12: Họ tên | E12: Đơn vị | F12: Ghi chú | G12: STT | H12: Mã nhân viên | I12: Họ tên | K12: Đơn vị | L12: Ngày | M12: Ngày | N12: Ngày | O12: Ghi chú
L13: =I9 -> C18/8/2026
B14: =ROW()-13 -> 1 | G14: =B14 -> 1 | H14: =C14 -> 0 | I14: =D14 -> 0 | K14: =E14 -> 0
B15: =ROW()-13 -> 2 | G15: =B15 -> 2 | H15: =C15 -> 0 | I15: =D15 -> 0 | K15: =E15 -> 0
C16: P.Trưởng Trung tâm đào tạo | F16: Người lập | H16: Chữ ký giáo viên:
G18: Lưu ý:
G19: - Giáo viên điểm danh theo ngày và đánh dấu: X: có mặt; V: vắng mặt
C20: Ngô Trung Thành | F20: Nguyễn Cao Bình | G20: - Trang thiết bị thực hành (áp dụng đối với nội dung thực hành Nghiệp vụ điều khiển/vận hành thiết bị):
G21: …………………………………………………………………………………............................................

Sheet 7
E2: DANH SÁCH HỌC VIÊN | J2: Biểu mẫu | N2: Mã số: V.TMM-F10
J3: ĐIỂM DANH HỌC VIÊN | N3: Ban hành: 04
N4: Hiệu lực: 28/12/2024
N5: Trang: 1/1
B7: - Môn/Khóa học: | G7: - Môn/Khóa học: | I7: =D7 -> 0
B8: - Loại hình/hình thức đào tạo: Định kỳ/Elearning+Trực tiếp | G8: =B8 -> - Loại hình/hình thức đào tạo: Định kỳ/Elearning+Trực tiếp
B9: - Thời gian: | D9: S18/8/2026 | G9: =B9 -> - Thời gian: | I9: =D9 -> S18/8/2026
B10: - Địa điểm: | D10: TTĐT | G10: =B10 -> - Địa điểm: | I10: =D10 -> TTĐT
B11: - Giáo viên: | G11: - Số học viên tham dự/tổng số học viên: | K11: =COUNTIF($L$14:$L47,"x")&"/"&COUNTA($L$14:$L47) -> 0/0
B12: STT | C12: Mã NV | D12: Họ tên | E12: Đơn vị | F12: Ghi chú | G12: STT | H12: Mã nhân viên | I12: Họ tên | K12: Đơn vị | L12: Ngày | M12: Ngày | N12: Ngày | O12: Ghi chú
L13: =I9 -> S18/8/2026
B14: =ROW()-13 -> 1 | G14: =B14 -> 1 | H14: =C14 -> 0 | I14: =D14 -> 0 | K14: =E14 -> 0
B15: =ROW()-13 -> 2 | G15: =B15 -> 2 | H15: =C15 -> 0 | I15: =D15 -> 0 | K15: =E15 -> 0
B16: =ROW()-13 -> 3 | G16: =B16 -> 3 | H16: =C16 -> 0 | I16: =D16 -> 0 | K16: =E16 -> 0
B17: =ROW()-13 -> 4 | G17: =B17 -> 4 | H17: =C17 -> 0 | I17: =D17 -> 0 | K17: =E17 -> 0
B18: =ROW()-13 -> 5 | G18: =B18 -> 5 | H18: =C18 -> 0 | I18: =D18 -> 0 | K18: =E18 -> 0
B19: =ROW()-13 -> 6 | G19: =B19 -> 6 | H19: =C19 -> 0 | I19: =D19 -> 0 | K19: =E19 -> 0
B20: =ROW()-13 -> 7 | G20: =B20 -> 7 | H20: =C20 -> 0 | I20: =D20 -> 0 | K20: =E20 -> 0
B21: =ROW()-13 -> 8 | G21: =B21 -> 8 | H21: =C21 -> 0 | I21: =D21 -> 0 | K21: =E21 -> 0
B22: =ROW()-13 -> 9 | G22: =B22 -> 9 | H22: =C22 -> 0 | I22: =D22 -> 0 | K22: =E22 -> 0
B23: =ROW()-13 -> 10 | G23: =B23 -> 10 | H23: =C23 -> 0 | I23: =D23 -> 0 | K23: =E23 -> 0
B24: =ROW()-13 -> 11 | G24: =B24 -> 11 | H24: =C24 -> 0 | I24: =D24 -> 0 | K24: =E24 -> 0
B25: =ROW()-13 -> 12 | G25: =B25 -> 12 | H25: =C25 -> 0 | I25: =D25 -> 0 | K25: =E25 -> 0
... B33: =ROW()-13 -> 20 | G33: =B33 -> 20 | H33: =C33 -> 0 | I33: =D33 -> 0 | K33: =E33 -> 0
C34: P.Trưởng Trung tâm đào tạo | F34: Người lập | H34: Chữ ký giáo viên:
G36: Lưu ý:
G37: - Giáo viên điểm danh theo ngày và đánh dấu: X: có mặt; V: vắng mặt
C38: Ngô Trung Thành | F38: Nguyễn Cao Bình | G38: - Trang thiết bị thực hành (áp dụng đối với nội dung thực hành Nghiệp vụ điều khiển/vận hành thiết bị):
G39: …………………………………………………………………………………............................................

Sheet 8
E2: DANH SÁCH HỌC VIÊN | J2: Biểu mẫu | N2: Mã số: V.TMM-F10
J3: ĐIỂM DANH HỌC VIÊN | N3: Ban hành: 04
N4: Hiệu lực: 28/12/2024
N5: Trang: 1/1
B7: - Môn/Khóa học: | G7: - Môn/Khóa học: | I7: =D7 -> 0
B8: - Loại hình/hình thức đào tạo: Định kỳ/Elearning+Trực tiếp | G8: =B8 -> - Loại hình/hình thức đào tạo: Định kỳ/Elearning+Trực tiếp
B9: - Thời gian: | D9: S18/8/2026 | G9: =B9 -> - Thời gian: | I9: =D9 -> S18/8/2026
B10: - Địa điểm: | D10: TTĐT | G10: =B10 -> - Địa điểm: | I10: =D10 -> TTĐT
B11: - Giáo viên: | G11: - Số học viên tham dự/tổng số học viên: | K11: =COUNTIF($L$14:$L47,"x")&"/"&COUNTA($L$14:$L47) -> 17/20
B12: STT | C12: Mã NV | D12: Họ tên | E12: Đơn vị | F12: Ghi chú | G12: STT | H12: Mã nhân viên | I12: Họ tên | K12: Đơn vị | L12: Ngày | M12: Ngày | N12: Ngày | O12: Ghi chú
L13: =I9 -> S18/8/2026
B14: =ROW()-13 -> 1 | G14: =B14 -> 1 | H14: =C14 -> 0 | I14: =D14 -> 0 | K14: =E14 -> 0 | L14: x
B15: =ROW()-13 -> 2 | G15: =B15 -> 2 | H15: =C15 -> 0 | I15: =D15 -> 0 | K15: =E15 -> 0 | L15: x
B16: =ROW()-13 -> 3 | G16: =B16 -> 3 | H16: =C16 -> 0 | I16: =D16 -> 0 | K16: =E16 -> 0 | L16: x
B17: =ROW()-13 -> 4 | G17: =B17 -> 4 | H17: =C17 -> 0 | I17: =D17 -> 0 | K17: =E17 -> 0 | L17: x
B18: =ROW()-13 -> 5 | G18: =B18 -> 5 | H18: =C18 -> 0 | I18: =D18 -> 0 | K18: =E18 -> 0 | L18: v | O18: trùng lịch
B19: =ROW()-13 -> 6 | G19: =B19 -> 6 | H19: =C19 -> 0 | I19: =D19 -> 0 | K19: =E19 -> 0 | L19: v
B20: =ROW()-13 -> 7 | G20: =B20 -> 7 | H20: =C20 -> 0 | I20: =D20 -> 0 | K20: =E20 -> 0 | L20: x
B21: =ROW()-13 -> 8 | G21: =B21 -> 8 | H21: =C21 -> 0 | I21: =D21 -> 0 | K21: =E21 -> 0 | L21: x
B22: =ROW()-13 -> 9 | G22: =B22 -> 9 | H22: =C22 -> 0 | I22: =D22 -> 0 | K22: =E22 -> 0 | L22: x
B23: =ROW()-13 -> 10 | G23: =B23 -> 10 | H23: =C23 -> 0 | I23: =D23 -> 0 | K23: =E23 -> 0 | L23: x
B24: =ROW()-13 -> 11 | G24: =B24 -> 11 | H24: =C24 -> 0 | I24: =D24 -> 0 | K24: =E24 -> 0 | L24: X
B25: =ROW()-13 -> 12 | G25: =B25 -> 12 | H25: =C25 -> 0 | I25: =D25 -> 0 | K25: =E25 -> 0 | L25: x
B26: =ROW()-13 -> 13 | G26: =B26 -> 13 | H26: =C26 -> 0 | I26: =D26 -> 0 | K26: =E26 -> 0 | L26: x
B27: =ROW()-13 -> 14 | G27: =B27 -> 14 | H27: =C27 -> 0 | I27: =D27 -> 0 | K27: =E27 -> 0 | L27: x
B28: =ROW()-13 -> 15 | G28: =B28 -> 15 | H28: =C28 -> 0 | I28: =D28 -> 0 | K28: =E28 -> 0 | L28: x
B29: =ROW()-13 -> 16 | G29: =B29 -> 16 | H29: =C29 -> 0 | I29: =D29 -> 0 | K29: =E29 -> 0 | L29: v | O29: ốm
B30: =ROW()-13 -> 17 | G30: =B30 -> 17 | H30: =C30 -> 0 | I30: =D30 -> 0 | K30: =E30 -> 0 | L30: x
B31: =ROW()-13 -> 18 | G31: =B31 -> 18 | H31: =C31 -> 0 | I31: =D31 -> 0 | K31: =E31 -> 0 | L31: x
B32: =ROW()-13 -> 19 | G32: =B32 -> 19 | H32: =C32 -> 0 | I32: =D32 -> 0 | K32: =E32 -> 0 | L32: x
B33: =ROW()-13 -> 20 | G33: =B33 -> 20 | H33: =C33 -> 0 | I33: =D33 -> 0 | K33: =E33 -> 0 | L33: x
C34: P.Trưởng Trung tâm đào tạo | F34: Người lập | H34: Chữ ký giáo viên:
G36: Lưu ý:
G37: - Giáo viên điểm danh theo ngày và đánh dấu: X: có mặt; V: vắng mặt
C38: Ngô Trung Thành | F38: Nguyễn Cao Bình | G38: - Trang thiết bị thực hành (áp dụng đối với nội dung thực hành Nghiệp vụ điều khiển/vận hành thiết bị):
G39: …………………………………………………………………………………............................................

Sheet 9
E2: DANH SÁCH HỌC VIÊN | J2: Biểu mẫu | N2: Mã số: V.TMM-F10
J3: ĐIỂM DANH HỌC VIÊN | N3: Ban hành: 04
N4: Hiệu lực: 28/12/2024
N5: Trang: 1/1
B7: - Môn/Khóa học: | G7: - Môn/Khóa học: | I7: =D7 -> 0
B8: - Loại hình/hình thức đào tạo: Định kỳ/Elearning+Trực tiếp | G8: =B8 -> - Loại hình/hình thức đào tạo: Định kỳ/Elearning+Trực tiếp
B9: - Thời gian: | D9: S17/8/2026 | G9: =B9 -> - Thời gian: | I9: =D9 -> S17/8/2026
B10: - Địa điểm: | D10: TTĐT | G10: =B10 -> - Địa điểm: | I10: =D10 -> TTĐT
B11: - Giáo viên: | G11: - Số học viên tham dự/tổng số học viên: | K11: =COUNTIF($L$14:$L42,"x")&"/"&COUNTA($L$14:$L42) -> 15/15
B12: STT | C12: Mã NV | D12: Họ tên | E12: Đơn vị | F12: Ghi chú | G12: STT | H12: Mã nhân viên | I12: Họ tên | K12: Đơn vị | L12: Ngày | M12: Ngày | N12: Ngày | O12: Ghi chú
L13: =I9 -> S17/8/2026
B14: =ROW()-13 -> 1 | G14: =B14 -> 1 | H14: =C14 -> 0 | I14: =D14 -> 0 | K14: =E14 -> 0 | L14: X
B15: =ROW()-13 -> 2 | G15: =B15 -> 2 | H15: =C15 -> 0 | I15: =D15 -> 0 | K15: =E15 -> 0 | L15: X
B16: =ROW()-13 -> 3 | G16: =B16 -> 3 | H16: =C16 -> 0 | I16: =D16 -> 0 | K16: =E16 -> 0 | L16: X
B17: =ROW()-13 -> 4 | G17: =B17 -> 4 | H17: =C17 -> 0 | I17: =D17 -> 0 | K17: =E17 -> 0 | L17: X
B18: =ROW()-13 -> 5 | G18: =B18 -> 5 | H18: =C18 -> 0 | I18: =D18 -> 0 | K18: =E18 -> 0 | L18: X
B19: =ROW()-13 -> 6 | G19: =B19 -> 6 | H19: =C19 -> 0 | I19: =D19 -> 0 | K19: =E19 -> 0 | L19: X
B20: =ROW()-13 -> 7 | G20: =B20 -> 7 | H20: =C20 -> 0 | I20: =D20 -> 0 | K20: =E20 -> 0 | L20: X
B21: =ROW()-13 -> 8 | G21: =B21 -> 8 | H21: =C21 -> 0 | I21: =D21 -> 0 | K21: =E21 -> 0 | L21: X
B22: =ROW()-13 -> 9 | G22: =B22 -> 9 | H22: =C22 -> 0 | I22: =D22 -> 0 | K22: =E22 -> 0 | L22: X
B23: =ROW()-13 -> 10 | G23: =B23 -> 10 | H23: =C23 -> 0 | I23: =D23 -> 0 | K23: =E23 -> 0 | L23: X
B24: =ROW()-13 -> 11 | G24: =B24 -> 11 | H24: =C24 -> 0 | I24: =D24 -> 0 | K24: =E24 -> 0 | L24: X
B25: =ROW()-13 -> 12 | G25: =B25 -> 12 | H25: =C25 -> 0 | I25: =D25 -> 0 | K25: =E25 -> 0 | L25: X
... B28: =ROW()-13 -> 15 | G28: =B28 -> 15 | H28: =C28 -> 0 | I28: =D28 -> 0 | K28: =E28 -> 0 | L28: X
C29: P.Trưởng Trung tâm đào tạo | F29: Người lập | H29: Chữ ký giáo viên:
G31: Lưu ý:
G32: - Giáo viên điểm danh theo ngày và đánh dấu: X: có mặt; V: vắng mặt
C33: Ngô Trung Thành | F33: Nguyễn Cao Bình | G33: - Trang thiết bị thực hành (áp dụng đối với nội dung thực hành Nghiệp vụ điều khiển/vận hành thiết bị):
G34: …………………………………………………………………………………............................................
H37: nGUYỄN vIỆT ANH

Sheet 10
E2: DANH SÁCH HỌC VIÊN | J2: Biểu mẫu | N2: Mã số: V.TMM-F10
J3: ĐIỂM DANH HỌC VIÊN | N3: Ban hành: 04
N4: Hiệu lực: 28/12/2024
N5: Trang: 1/1
B7: - Môn/Khóa học: | G7: - Môn/Khóa học: | I7: =D7 -> 0
B8: - Loại hình/hình thức đào tạo: Định kỳ/Elearning+Trực tiếp | G8: =B8 -> - Loại hình/hình thức đào tạo: Định kỳ/Elearning+Trực tiếp
B9: - Thời gian: | D9: C17/8/2026 | G9: =B9 -> - Thời gian: | I9: =D9 -> C17/8/2026
B10: - Địa điểm: | D10: TTĐT | G10: =B10 -> - Địa điểm: | I10: =D10 -> TTĐT
B11: - Giáo viên: | G11: - Số học viên tham dự/tổng số học viên: | K11: =COUNTIF($L$14:$L42,"x")&"/"&COUNTA($L$14:$L42) -> 14/14
B12: STT | C12: Mã NV | D12: Họ tên | E12: Đơn vị | F12: Ghi chú | G12: STT | H12: Mã nhân viên | I12: Họ tên | K12: Đơn vị | L12: Ngày | M12: Ngày | N12: Ngày | O12: Ghi chú
L13: =I9 -> C17/8/2026
B14: =ROW()-13 -> 1 | G14: =B14 -> 1 | H14: =C14 -> 0 | I14: =D14 -> 0 | K14: =E14 -> 0 | L14: X
B15: =ROW()-13 -> 2 | G15: =B15 -> 2 | H15: =C15 -> 0 | I15: =D15 -> 0 | K15: =E15 -> 0 | L15: X
B16: =ROW()-13 -> 3 | G16: =B16 -> 3 | H16: =C16 -> 0 | I16: =D16 -> 0 | K16: =E16 -> 0 | L16: X
B17: =ROW()-13 -> 4 | G17: =B17 -> 4 | H17: =C17 -> 0 | I17: =D17 -> 0 | K17: =E17 -> 0
B18: =ROW()-13 -> 5 | G18: =B18 -> 5 | H18: =C18 -> 0 | I18: =D18 -> 0 | K18: =E18 -> 0 | L18: X
B19: =ROW()-13 -> 6 | G19: =B19 -> 6 | H19: =C19 -> 0 | I19: =D19 -> 0 | K19: =E19 -> 0 | L19: X
B20: =ROW()-13 -> 7 | G20: =B20 -> 7 | H20: =C20 -> 0 | I20: =D20 -> 0 | K20: =E20 -> 0 | L20: X
B21: =ROW()-13 -> 8 | G21: =B21 -> 8 | H21: =C21 -> 0 | I21: =D21 -> 0 | K21: =E21 -> 0 | L21: X
B22: =ROW()-13 -> 9 | G22: =B22 -> 9 | H22: =C22 -> 0 | I22: =D22 -> 0 | K22: =E22 -> 0 | L22: X
B23: =ROW()-13 -> 10 | G23: =B23 -> 10 | H23: =C23 -> 0 | I23: =D23 -> 0 | K23: =E23 -> 0 | L23: X
B24: =ROW()-13 -> 11 | G24: =B24 -> 11 | H24: =C24 -> 0 | I24: =D24 -> 0 | K24: =E24 -> 0 | L24: X
B25: =ROW()-13 -> 12 | G25: =B25 -> 12 | H25: =C25 -> 0 | I25: =D25 -> 0 | K25: =E25 -> 0 | L25: X
B26: =ROW()-13 -> 13 | G26: =B26 -> 13 | H26: =C26 -> 0 | I26: =D26 -> 0 | K26: =E26 -> 0 | L26: X
B27: =ROW()-13 -> 14 | G27: =B27 -> 14 | H27: =C27 -> 0 | I27: =D27 -> 0 | K27: =E27 -> 0 | L27: X
B28: =ROW()-13 -> 15 | G28: =B28 -> 15 | H28: =C28 -> 0 | I28: =D28 -> 0 | K28: =E28 -> 0 | L28: X
C29: P.Trưởng Trung tâm đào tạo | F29: Người lập | H29: Chữ ký giáo viên:
G31: Lưu ý:
G32: - Giáo viên điểm danh theo ngày và đánh dấu: X: có mặt; V: vắng mặt
C33: Ngô Trung Thành | F33: Nguyễn Cao Bình | G33: - Trang thiết bị thực hành (áp dụng đối với nội dung thực hành Nghiệp vụ điều khiển/vận hành thiết bị):
G34: …………………………………………………………………………………............................................

Sheet 11
E2: DANH SÁCH HỌC VIÊN | J2: Biểu mẫu | N2: Mã số: V.TMM-F10
J3: ĐIỂM DANH HỌC VIÊN | N3: Ban hành: 04
N4: Hiệu lực: 28/12/2024
N5: Trang: 1/1
B7: - Môn/Khóa học: | G7: - Môn/Khóa học: | I7: =D7 -> 0
B8: - Loại hình/hình thức đào tạo: Định kỳ/Elearning+Trực tiếp | G8: =B8 -> - Loại hình/hình thức đào tạo: Định kỳ/Elearning+Trực tiếp
B9: - Thời gian: | D9: S18/8/2026 | G9: =B9 -> - Thời gian: | I9: =D9 -> S18/8/2026
B10: - Địa điểm: | D10: TTĐT | G10: =B10 -> - Địa điểm: | I10: =D10 -> TTĐT
B11: - Giáo viên: | G11: - Số học viên tham dự/tổng số học viên: | K11: =COUNTIF($L$14:$L36,"x")&"/"&COUNTA($L$14:$L36) -> 0/0
B12: STT | C12: Mã NV | D12: Họ tên | E12: Đơn vị | F12: Ghi chú | G12: STT | H12: Mã nhân viên | I12: Họ tên | K12: Đơn vị | L12: Ngày | M12: Ngày | N12: Ngày | O12: Ghi chú
L13: =I9 -> S18/8/2026
B14: =ROW()-13 -> 1 | G14: =B14 -> 1 | H14: =C14 -> 0 | I14: =D14 -> 0 | K14: =E14 -> 0
B15: =ROW()-13 -> 2 | G15: =B15 -> 2 | H15: =C15 -> 0 | I15: =D15 -> 0 | K15: =E15 -> 0
B16: =ROW()-13 -> 3 | G16: =B16 -> 3 | H16: =C16 -> 0 | I16: =D16 -> 0 | K16: =E16 -> 0
B17: =ROW()-13 -> 4 | G17: =B17 -> 4 | H17: =C17 -> 0 | I17: =D17 -> 0 | K17: =E17 -> 0
B18: =ROW()-13 -> 5 | G18: =B18 -> 5 | H18: =C18 -> 0 | I18: =D18 -> 0 | K18: =E18 -> 0
B19: =ROW()-13 -> 6 | G19: =B19 -> 6 | H19: =C19 -> 0 | I19: =D19 -> 0 | K19: =E19 -> 0
B20: =ROW()-13 -> 7 | G20: =B20 -> 7 | H20: =C20 -> 0 | I20: =D20 -> 0 | K20: =E20 -> 0
B21: =ROW()-13 -> 8 | G21: =B21 -> 8 | H21: =C21 -> 0 | I21: =D21 -> 0 | K21: =E21 -> 0
B22: =ROW()-13 -> 9 | G22: =B22 -> 9 | H22: =C22 -> 0 | I22: =D22 -> 0 | K22: =E22 -> 0
C23: P.Trưởng Trung tâm đào tạo | F23: Người lập | H23: Chữ ký giáo viên:
G25: Lưu ý:
G26: - Giáo viên điểm danh theo ngày và đánh dấu: X: có mặt; V: vắng mặt
C27: Ngô Trung Thành | F27: Nguyễn Cao Bình | G27: - Trang thiết bị thực hành (áp dụng đối với nội dung thực hành Nghiệp vụ điều khiển/vận hành thiết bị):
G28: …………………………………………………………………………………............................................

Sheet 12
E2: DANH SÁCH HỌC VIÊN | J2: Biểu mẫu | N2: Mã số: V.TMM-F10
J3: ĐIỂM DANH HỌC VIÊN | N3: Ban hành: 04
N4: Hiệu lực: 28/12/2024
N5: Trang: 1/1
B7: - Môn/Khóa học: | G7: - Môn/Khóa học: | I7: =D7 -> 0
B8: - Loại hình/hình thức đào tạo: Định kỳ/Elearning+Trực tiếp | G8: =B8 -> - Loại hình/hình thức đào tạo: Định kỳ/Elearning+Trực tiếp
B9: - Thời gian: | D9: S17/8/2026 | G9: =B9 -> - Thời gian: | I9: =D9 -> S17/8/2026
B10: - Địa điểm: | D10: TTĐT | G10: =B10 -> - Địa điểm: | I10: =D10 -> TTĐT
B11: - Giáo viên: | G11: - Số học viên tham dự/tổng số học viên: | K11: =COUNTIF($L$14:$L44,"x")&"/"&COUNTA($L$14:$L44) -> 16/16
B12: STT | C12: Mã NV | D12: Họ tên | E12: Đơn vị | F12: Ghi chú | G12: STT | H12: Mã nhân viên | I12: Họ tên | K12: Đơn vị | L12: Ngày | M12: Ngày | N12: Ngày | O12: Ghi chú
L13: =I9 -> S17/8/2026
B14: =ROW()-13 -> 1 | G14: =B14 -> 1 | H14: =C14 -> 0 | I14: =D14 -> 0 | K14: =E14 -> 0 | L14: x
B15: =ROW()-13 -> 2 | G15: =B15 -> 2 | H15: =C15 -> 0 | I15: =D15 -> 0 | K15: =E15 -> 0 | L15: x
B16: =ROW()-13 -> 3 | G16: =B16 -> 3 | H16: =C16 -> 0 | I16: =D16 -> 0 | K16: =E16 -> 0 | L16: x
B17: =ROW()-13 -> 4 | G17: =B17 -> 4 | H17: =C17 -> 0 | I17: =D17 -> 0 | K17: =E17 -> 0 | L17: x
B18: =ROW()-13 -> 5 | G18: =B18 -> 5 | H18: =C18 -> 0 | I18: =D18 -> 0 | K18: =E18 -> 0 | L18: x
B19: =ROW()-13 -> 6 | G19: =B19 -> 6 | H19: =C19 -> 0 | I19: =D19 -> 0 | K19: =E19 -> 0 | L19: x
B20: =ROW()-13 -> 7 | G20: =B20 -> 7 | H20: =C20 -> 0 | I20: =D20 -> 0 | K20: =E20 -> 0 | L20: x
B21: =ROW()-13 -> 8 | G21: =B21 -> 8 | H21: =C21 -> 0 | I21: =D21 -> 0 | K21: =E21 -> 0 | L21: x
B22: =ROW()-13 -> 9 | G22: =B22 -> 9 | H22: =C22 -> 0 | I22: =D22 -> 0 | K22: =E22 -> 0 | L22: x
B23: =ROW()-13 -> 10 | G23: =B23 -> 10 | H23: =C23 -> 0 | I23: =D23 -> 0 | K23: =E23 -> 0 | L23: x
B24: =ROW()-13 -> 11 | G24: =B24 -> 11 | H24: =C24 -> 0 | I24: =D24 -> 0 | K24: =E24 -> 0 | L24: x
B25: =ROW()-13 -> 12 | G25: =B25 -> 12 | H25: =C25 -> 0 | I25: =D25 -> 0 | K25: =E25 -> 0 | L25: x
... B29: =ROW()-13 -> 16 | G29: =B29 -> 16 | H29: =C29 -> 0 | I29: =D29 -> 0 | K29: =E29 -> 0 | L29: x
B30: =ROW()-13 -> 17 | G30: =B30 -> 17 | H30: =C30 -> 0 | I30: =D30 -> 0 | K30: =E30 -> 0
C31: P.Trưởng Trung tâm đào tạo | F31: Người lập | H31: Chữ ký giáo viên:
G33: Lưu ý:
G34: - Giáo viên điểm danh theo ngày và đánh dấu: X: có mặt; V: vắng mặt
C35: Ngô Trung Thành | F35: Nguyễn Cao Bình | G35: - Trang thiết bị thực hành (áp dụng đối với nội dung thực hành Nghiệp vụ điều khiển/vận hành thiết bị):
G36: …………………………………………………………………………………............................................

Sheet 13
E2: DANH SÁCH HỌC VIÊN | J2: Biểu mẫu | N2: Mã số: V.TMM-F10
J3: ĐIỂM DANH HỌC VIÊN | N3: Ban hành: 04
N4: Hiệu lực: 28/12/2024
N5: Trang: 1/1
B7: - Môn/Khóa học: | G7: - Môn/Khóa học: | I7: =D7 -> 0
B8: - Loại hình/hình thức đào tạo: Định kỳ/Trực tiếp | G8: =B8 -> - Loại hình/hình thức đào tạo: Định kỳ/Trực tiếp
B9: - Thời gian: | D9: S21/8/2026 | G9: =B9 -> - Thời gian: | I9: =D9 -> S21/8/2026
B10: - Địa điểm: | D10: TTĐT | G10: =B10 -> - Địa điểm: | I10: =D10 -> TTĐT
B11: - Giáo viên: | G11: - Số học viên tham dự/tổng số học viên: | K11: =COUNTIF($L$14:$L37,"x")&"/"&COUNTA($L$14:$L37) -> 0/0
B12: STT | C12: Mã NV | D12: Họ tên | E12: Đơn vị | F12: Ghi chú | G12: STT | H12: Mã nhân viên | I12: Họ tên | K12: Đơn vị | L12: Ngày | M12: Ngày | N12: Ngày | O12: Ghi chú
L13: =I9 -> S21/8/2026
B14: =ROW()-13 -> 1 | G14: =B14 -> 1 | H14: =C14 -> 0 | I14: =D14 -> 0 | K14: =E14 -> 0
B15: =ROW()-13 -> 2 | G15: =B15 -> 2 | H15: =C15 -> 0 | I15: =D15 -> 0 | K15: =E15 -> 0
B16: =ROW()-13 -> 3 | G16: =B16 -> 3 | H16: =C16 -> 0 | I16: =D16 -> 0 | K16: =E16 -> 0
B17: =ROW()-13 -> 4 | G17: =B17 -> 4 | H17: =C17 -> 0 | I17: =D17 -> 0 | K17: =E17 -> 0
B18: =ROW()-13 -> 5 | G18: =B18 -> 5 | H18: =C18 -> 0 | I18: =D18 -> 0 | K18: =E18 -> 0
B19: =ROW()-13 -> 6 | G19: =B19 -> 6 | H19: =C19 -> 0 | I19: =D19 -> 0 | K19: =E19 -> 0
B20: =ROW()-13 -> 7 | G20: =B20 -> 7 | H20: =C20 -> 0 | I20: =D20 -> 0 | K20: =E20 -> 0
B21: =ROW()-13 -> 8 | G21: =B21 -> 8 | H21: =C21 -> 0 | I21: =D21 -> 0 | K21: =E21 -> 0
B22: =ROW()-13 -> 9 | G22: =B22 -> 9 | H22: =C22 -> 0 | I22: =D22 -> 0 | K22: =E22 -> 0
B23: =ROW()-13 -> 10 | G23: =B23 -> 10 | H23: =C23 -> 0 | I23: =D23 -> 0 | K23: =E23 -> 0
C24: P.Trưởng Trung tâm đào tạo | F24: Người lập | H24: Chữ ký giáo viên:
G26: Lưu ý:
G27: - Giáo viên điểm danh theo ngày và đánh dấu: X: có mặt; V: vắng mặt
C28: Ngô Trung Thành | F28: Nguyễn Cao Bình | G28: - Trang thiết bị thực hành (áp dụng đối với nội dung thực hành Nghiệp vụ điều khiển/vận hành thiết bị):
G29: …………………………………………………………………………………............................................

Sheet 14
E2: DANH SÁCH HỌC VIÊN | J2: Biểu mẫu | N2: Mã số: V.TMM-F10
J3: ĐIỂM DANH HỌC VIÊN | N3: Ban hành: 04
N4: Hiệu lực: 28/12/2024
N5: Trang: 1/1
B7: - Môn/Khóa học: | G7: - Môn/Khóa học: | I7: =D7 -> 0
B8: - Loại hình/hình thức đào tạo: Định kỳ/Trực tiếp | G8: =B8 -> - Loại hình/hình thức đào tạo: Định kỳ/Trực tiếp
B9: - Thời gian: | D9: 19/8/2026 | G9: =B9 -> - Thời gian: | I9: =D9 -> 19/8/2026
B10: - Địa điểm: | D10: TTĐT | G10: =B10 -> - Địa điểm: | I10: =D10 -> TTĐT
B11: - Giáo viên: | G11: - Số học viên tham dự/tổng số học viên: | K11: =COUNTIF($L$14:$L37,"x")&"/"&COUNTA($L$14:$L37) -> 0/0
B12: STT | C12: Mã NV | D12: Họ tên | E12: Đơn vị | F12: Ghi chú | G12: STT | H12: Mã nhân viên | I12: Họ tên | K12: Đơn vị | L12: Ngày | M12: Ngày | N12: Ngày | O12: Ghi chú
L13: =I9 -> 19/8/2026
B14: =ROW()-13 -> 1 | G14: =B14 -> 1 | H14: =C14 -> 0 | I14: =D14 -> 0 | K14: =E14 -> 0
B15: =ROW()-13 -> 2 | G15: =B15 -> 2 | H15: =C15 -> 0 | I15: =D15 -> 0 | K15: =E15 -> 0
B16: =ROW()-13 -> 3 | G16: =B16 -> 3 | H16: =C16 -> 0 | I16: =D16 -> 0 | K16: =E16 -> 0
B17: =ROW()-13 -> 4 | G17: =B17 -> 4 | H17: =C17 -> 0 | I17: =D17 -> 0 | K17: =E17 -> 0
B18: =ROW()-13 -> 5 | G18: =B18 -> 5 | H18: =C18 -> 0 | I18: =D18 -> 0 | K18: =E18 -> 0
B19: =ROW()-13 -> 6 | G19: =B19 -> 6 | H19: =C19 -> 0 | I19: =D19 -> 0 | K19: =E19 -> 0
B20: =ROW()-13 -> 7 | G20: =B20 -> 7 | H20: =C20 -> 0 | I20: =D20 -> 0 | K20: =E20 -> 0
B21: =ROW()-13 -> 8 | G21: =B21 -> 8 | H21: =C21 -> 0 | I21: =D21 -> 0 | K21: =E21 -> 0
B22: =ROW()-13 -> 9 | G22: =B22 -> 9 | H22: =C22 -> 0 | I22: =D22 -> 0 | K22: =E22 -> 0
B23: =ROW()-13 -> 10 | G23: =B23 -> 10 | H23: =C23 -> 0 | I23: =D23 -> 0 | K23: =E23 -> 0
C24: P.Trưởng Trung tâm đào tạo | F24: Người lập | H24: Chữ ký giáo viên:
G26: Lưu ý:
G27: - Giáo viên điểm danh theo ngày và đánh dấu: X: có mặt; V: vắng mặt
C28: Ngô Trung Thành | F28: Nguyễn Cao Bình | G28: - Trang thiết bị thực hành (áp dụng đối với nội dung thực hành Nghiệp vụ điều khiển/vận hành thiết bị):
G29: …………………………………………………………………………………............................................

Sheet 15
E2: DANH SÁCH HỌC VIÊN | J2: Biểu mẫu | N2: Mã số: V.TMM-F10
J3: ĐIỂM DANH HỌC VIÊN | N3: Ban hành: 04
N4: Hiệu lực: 28/12/2024
N5: Trang: 1/1
B7: - Môn/Khóa học: | G7: - Môn/Khóa học: | I7: =D7 -> 0
B8: - Loại hình/hình thức đào tạo: Định kỳ/Trực tiếp | G8: =B8 -> - Loại hình/hình thức đào tạo: Định kỳ/Trực tiếp
B9: - Thời gian: | D9: 20/8/2026 | G9: =B9 -> - Thời gian: | I9: =D9 -> 20/8/2026
B10: - Địa điểm: | D10: TTĐT | G10: =B10 -> - Địa điểm: | I10: =D10 -> TTĐT
B11: - Giáo viên: | G11: - Số học viên tham dự/tổng số học viên: | K11: =COUNTIF($L$14:$L37,"x")&"/"&COUNTA($L$14:$L37) -> 0/0
B12: STT | C12: Mã NV | D12: Họ tên | E12: Đơn vị | F12: Ghi chú | G12: STT | H12: Mã nhân viên | I12: Họ tên | K12: Đơn vị | L12: Ngày | M12: Ngày | N12: Ngày | O12: Ghi chú
L13: =I9 -> 20/8/2026
B14: =ROW()-13 -> 1 | G14: =B14 -> 1 | H14: =C14 -> 0 | I14: =D14 -> 0 | K14: =E14 -> 0
B15: =ROW()-13 -> 2 | G15: =B15 -> 2 | H15: =C15 -> 0 | I15: =D15 -> 0 | K15: =E15 -> 0
B16: =ROW()-13 -> 3 | G16: =B16 -> 3 | H16: =C16 -> 0 | I16: =D16 -> 0 | K16: =E16 -> 0
B17: =ROW()-13 -> 4 | G17: =B17 -> 4 | H17: =C17 -> 0 | I17: =D17 -> 0 | K17: =E17 -> 0
B18: =ROW()-13 -> 5 | G18: =B18 -> 5 | H18: =C18 -> 0 | I18: =D18 -> 0 | K18: =E18 -> 0
B19: =ROW()-13 -> 6 | G19: =B19 -> 6 | H19: =C19 -> 0 | I19: =D19 -> 0 | K19: =E19 -> 0
B20: =ROW()-13 -> 7 | G20: =B20 -> 7 | H20: =C20 -> 0 | I20: =D20 -> 0 | K20: =E20 -> 0
B21: =ROW()-13 -> 8 | G21: =B21 -> 8 | H21: =C21 -> 0 | I21: =D21 -> 0 | K21: =E21 -> 0
B22: =ROW()-13 -> 9 | G22: =B22 -> 9 | H22: =C22 -> 0 | I22: =D22 -> 0 | K22: =E22 -> 0
B23: =ROW()-13 -> 10 | G23: =B23 -> 10 | H23: =C23 -> 0 | I23: =D23 -> 0 | K23: =E23 -> 0
C24: P.Trưởng Trung tâm đào tạo | F24: Người lập | H24: Chữ ký giáo viên:
G26: Lưu ý:
G27: - Giáo viên điểm danh theo ngày và đánh dấu: X: có mặt; V: vắng mặt
C28: Ngô Trung Thành | F28: Nguyễn Cao Bình | G28: - Trang thiết bị thực hành (áp dụng đối với nội dung thực hành Nghiệp vụ điều khiển/vận hành thiết bị):
G29: …………………………………………………………………………………............................................

Sheet 16
E2: DANH SÁCH HỌC VIÊN | J2: Biểu mẫu | N2: Mã số: V.TMM-F10
J3: ĐIỂM DANH HỌC VIÊN | N3: Ban hành: 04
N4: Hiệu lực: 28/12/2024
N5: Trang: 1/1
B7: - Môn/Khóa học: | G7: - Môn/Khóa học: | I7: =D7 -> 0
B8: - Loại hình/hình thức đào tạo: Định kỳ/Trực tiếp | G8: =B8 -> - Loại hình/hình thức đào tạo: Định kỳ/Trực tiếp
B9: - Thời gian: | D9: C21/8/2026 | G9: =B9 -> - Thời gian: | I9: =D9 -> C21/8/2026
B10: - Địa điểm: | D10: TTĐT | G10: =B10 -> - Địa điểm: | I10: =D10 -> TTĐT
B11: - Giáo viên: | G11: - Số học viên tham dự/tổng số học viên: | K11: =COUNTIF($L$14:$L35,"x")&"/"&COUNTA($L$14:$L35) -> 0/0
B12: STT | C12: Mã NV | D12: Họ tên | E12: Đơn vị | F12: Ghi chú | G12: STT | H12: Mã nhân viên | I12: Họ tên | K12: Đơn vị | L12: Ngày | M12: Ngày | N12: Ngày | O12: Ghi chú
L13: =I9 -> C21/8/2026
B14: =ROW()-13 -> 1 | G14: =B14 -> 1 | H14: =C14 -> 0 | I14: =D14 -> 0 | K14: =E14 -> 0
B15: =ROW()-13 -> 2 | G15: =B15 -> 2 | H15: =C15 -> 0 | I15: =D15 -> 0 | K15: =E15 -> 0
B16: =ROW()-13 -> 3 | G16: =B16 -> 3 | H16: =C16 -> 0 | I16: =D16 -> 0 | K16: =E16 -> 0
B17: =ROW()-13 -> 4 | G17: =B17 -> 4 | H17: =C17 -> 0 | I17: =D17 -> 0 | K17: =E17 -> 0
B18: =ROW()-13 -> 5 | G18: =B18 -> 5 | H18: =C18 -> 0 | I18: =D18 -> 0 | K18: =E18 -> 0
B19: =ROW()-13 -> 6 | G19: =B19 -> 6 | H19: =C19 -> 0 | I19: =D19 -> 0 | K19: =E19 -> 0
B20: =ROW()-13 -> 7 | G20: =B20 -> 7 | H20: =C20 -> 0 | I20: =D20 -> 0 | K20: =E20 -> 0
B21: =ROW()-13 -> 8 | G21: =B21 -> 8 | H21: =C21 -> 0 | I21: =D21 -> 0 | K21: =E21 -> 0
C22: P.Trưởng Trung tâm đào tạo | F22: Người lập | H22: Chữ ký giáo viên:
G24: Lưu ý:
G25: - Giáo viên điểm danh theo ngày và đánh dấu: X: có mặt; V: vắng mặt
C26: Ngô Trung Thành | F26: Nguyễn Cao Bình | G26: - Trang thiết bị thực hành (áp dụng đối với nội dung thực hành Nghiệp vụ điều khiển/vận hành thiết bị):
G27: …………………………………………………………………………………............................................

Sheet 17
E2: DANH SÁCH HỌC VIÊN | J2: Biểu mẫu | N2: Mã số: V.TMM-F10
J3: ĐIỂM DANH HỌC VIÊN | N3: Ban hành: 04
N4: Hiệu lực: 28/12/2024
N5: Trang: 1/1
B7: - Môn/Khóa học: | G7: - Môn/Khóa học: | I7: =D7 -> 0
B8: - Loại hình/hình thức đào tạo: Định kỳ/Trực tiếp | G8: =B8 -> - Loại hình/hình thức đào tạo: Định kỳ/Trực tiếp
B9: - Thời gian: | D9: C17/8/2026 | G9: =B9 -> - Thời gian: | I9: =D9 -> C17/8/2026
B10: - Địa điểm: | D10: TTĐT | G10: =B10 -> - Địa điểm: | I10: =D10 -> TTĐT
B11: - Giáo viên: | G11: - Số học viên tham dự/tổng số học viên: | K11: =COUNTIF($L$14:$L43,"x")&"/"&COUNTA($L$14:$L43) -> 11/14
B12: STT | C12: Mã NV | D12: Họ tên | E12: Đơn vị | F12: Ghi chú | G12: STT | H12: Mã nhân viên | I12: Họ tên | K12: Đơn vị | L12: Ngày | M12: Ngày | N12: Ngày | O12: Ghi chú
L13: =I9 -> C17/8/2026
B14: =ROW()-13 -> 1 | G14: =B14 -> 1 | H14: =C14 -> 0 | I14: =D14 -> 0 | K14: =E14 -> 0
B15: =ROW()-13 -> 2 | G15: =B15 -> 2 | H15: =C15 -> 0 | I15: =D15 -> 0 | K15: =E15 -> 0
B16: =ROW()-13 -> 3 | G16: =B16 -> 3 | H16: =C16 -> 0 | I16: =D16 -> 0 | K16: =E16 -> 0 | L16: x
B17: =ROW()-13 -> 4 | G17: =B17 -> 4 | H17: =C17 -> 0 | I17: =D17 -> 0 | K17: =E17 -> 0 | L17: x
B18: =ROW()-13 -> 5 | G18: =B18 -> 5 | H18: =C18 -> 0 | I18: =D18 -> 0 | K18: =E18 -> 0 | L18: V
B19: =ROW()-13 -> 6 | G19: =B19 -> 6 | H19: =C19 -> 0 | I19: =D19 -> 0 | K19: =E19 -> 0 | L19: x
B20: =ROW()-13 -> 7 | G20: =B20 -> 7 | H20: =C20 -> 0 | I20: =D20 -> 0 | K20: =E20 -> 0 | L20: x
B21: =ROW()-13 -> 8 | G21: =B21 -> 8 | H21: =C21 -> 0 | I21: =D21 -> 0 | K21: =E21 -> 0 | L21: x
B22: =ROW()-13 -> 9 | G22: =B22 -> 9 | H22: =C22 -> 0 | I22: =D22 -> 0 | K22: =E22 -> 0 | L22: x
B23: =ROW()-13 -> 10 | G23: =B23 -> 10 | H23: =C23 -> 0 | I23: =D23 -> 0 | K23: =E23 -> 0 | L23: x
B24: =ROW()-13 -> 11 | G24: =B24 -> 11 | H24: =C24 -> 0 | I24: =D24 -> 0 | K24: =E24 -> 0 | L24: x
B25: =ROW()-13 -> 12 | G25: =B25 -> 12 | H25: =C25 -> 0 | I25: =D25 -> 0 | K25: =E25 -> 0 | L25: V
B26: =ROW()-13 -> 13 | G26: =B26 -> 13 | H26: =C26 -> 0 | I26: =D26 -> 0 | K26: =E26 -> 0 | L26: x
B27: =ROW()-13 -> 14 | G27: =B27 -> 14 | H27: =C27 -> 0 | I27: =D27 -> 0 | K27: =E27 -> 0 | L27: x
... B29: =ROW()-13 -> 16 | G29: =B29 -> 16 | H29: =C29 -> 0 | I29: =D29 -> 0 | K29: =E29 -> 0 | L29: x
C30: P.Trưởng Trung tâm đào tạo | F30: Người lập | H30: Chữ ký giáo viên:
G32: Lưu ý:
G33: - Giáo viên điểm danh theo ngày và đánh dấu: X: có mặt; V: vắng mặt
C34: Ngô Trung Thành | F34: Nguyễn Cao Bình | G34: - Trang thiết bị thực hành (áp dụng đối với nội dung thực hành Nghiệp vụ điều khiển/vận hành thiết bị):
G35: …………………………………………………………………………………............................................

Sheet 18
E2: DANH SÁCH HỌC VIÊN | J2: Biểu mẫu | N2: Mã số: V.TMM-F10
J3: ĐIỂM DANH HỌC VIÊN | N3: Ban hành: 04
N4: Hiệu lực: 28/12/2024
N5: Trang: 1/1
B7: - Môn/Khóa học: | G7: - Môn/Khóa học: | I7: =D7 -> 0
B8: - Loại hình/hình thức đào tạo: Định kỳ/Trực tiếp | G8: =B8 -> - Loại hình/hình thức đào tạo: Định kỳ/Trực tiếp
B9: - Thời gian: | D9: S17/8/2026 | G9: =B9 -> - Thời gian: | I9: =D9 -> S17/8/2026
B10: - Địa điểm: | D10: TTĐT | G10: =B10 -> - Địa điểm: | I10: =D10 -> TTĐT
B11: - Giáo viên: | G11: - Số học viên tham dự/tổng số học viên: | K11: =COUNTIF($L$14:$L45,"x")&"/"&COUNTA($L$14:$L45) -> 17/17
B12: STT | C12: Mã NV | D12: Họ tên | E12: Đơn vị | F12: Ghi chú | G12: STT | H12: Mã nhân viên | I12: Họ tên | K12: Đơn vị | L12: Ngày | M12: Ngày | N12: Ngày | O12: Ghi chú
L13: =I9 -> S17/8/2026
B14: =ROW()-13 -> 1 | G14: =B14 -> 1 | H14: =C14 -> 0 | I14: =D14 -> 0 | K14: =E14 -> 0 | L14: X
B15: =ROW()-13 -> 2 | G15: =B15 -> 2 | H15: =C15 -> 0 | I15: =D15 -> 0 | K15: =E15 -> 0 | L15: X
B16: =ROW()-13 -> 3 | G16: =B16 -> 3 | H16: =C16 -> 0 | I16: =D16 -> 0 | K16: =E16 -> 0 | L16: X
B17: =ROW()-13 -> 4 | G17: =B17 -> 4 | H17: =C17 -> 0 | I17: =D17 -> 0 | K17: =E17 -> 0 | L17: X
B18: =ROW()-13 -> 5 | G18: =B18 -> 5 | H18: =C18 -> 0 | I18: =D18 -> 0 | K18: =E18 -> 0 | L18: X
B19: =ROW()-13 -> 6 | G19: =B19 -> 6 | H19: =C19 -> 0 | I19: =D19 -> 0 | K19: =E19 -> 0 | L19: X
B20: =ROW()-13 -> 7 | G20: =B20 -> 7 | H20: =C20 -> 0 | I20: =D20 -> 0 | K20: =E20 -> 0 | L20: X
B21: =ROW()-13 -> 8 | G21: =B21 -> 8 | H21: =C21 -> 0 | I21: =D21 -> 0 | K21: =E21 -> 0 | L21: X
B22: =ROW()-13 -> 9 | G22: =B22 -> 9 | H22: =C22 -> 0 | I22: =D22 -> 0 | K22: =E22 -> 0 | L22: X
B23: =ROW()-13 -> 10 | G23: =B23 -> 10 | H23: =C23 -> 0 | I23: =D23 -> 0 | K23: =E23 -> 0 | L23: X
B24: =ROW()-13 -> 11 | G24: =B24 -> 11 | H24: =C24 -> 0 | I24: =D24 -> 0 | K24: =E24 -> 0 | L24: X
B25: =ROW()-13 -> 12 | G25: =B25 -> 12 | H25: =C25 -> 0 | I25: =D25 -> 0 | K25: =E25 -> 0
B26: =ROW()-13 -> 13 | G26: =B26 -> 13 | H26: =C26 -> 0 | I26: =D26 -> 0 | K26: =E26 -> 0 | L26: X
B27: =ROW()-13 -> 14 | G27: =B27 -> 14 | H27: =C27 -> 0 | I27: =D27 -> 0 | K27: =E27 -> 0 | L27: X
B28: =ROW()-13 -> 15 | G28: =B28 -> 15 | H28: =C28 -> 0 | I28: =D28 -> 0 | K28: =E28 -> 0 | L28: X
B29: =ROW()-13 -> 16 | G29: =B29 -> 16 | H29: =C29 -> 0 | I29: =D29 -> 0 | K29: =E29 -> 0 | L29: X
B30: =ROW()-13 -> 17 | G30: =B30 -> 17 | H30: =C30 -> 0 | I30: =D30 -> 0 | K30: =E30 -> 0 | L30: X
B31: =ROW()-13 -> 18 | G31: =B31 -> 18 | H31: =C31 -> 0 | I31: =D31 -> 0 | K31: =E31 -> 0 | L31: X
C32: P.Trưởng Trung tâm đào tạo | F32: Người lập | H32: Chữ ký giáo viên:
G34: Lưu ý:
G35: - Giáo viên điểm danh theo ngày và đánh dấu: X: có mặt; V: vắng mặt
C36: Ngô Trung Thành | F36: Nguyễn Cao Bình | G36: - Trang thiết bị thực hành (áp dụng đối với nội dung thực hành Nghiệp vụ điều khiển/vận hành thiết bị):
G37: …………………………………………………………………………………............................................

Sheet 19
E2: DANH SÁCH HỌC VIÊN | J2: Biểu mẫu | N2: Mã số: V.TMM-F10
J3: ĐIỂM DANH HỌC VIÊN | N3: Ban hành: 04
N4: Hiệu lực: 28/12/2024
N5: Trang: 1/1
B7: - Môn/Khóa học: | G7: - Môn/Khóa học: | I7: =D7 -> 0
B8: - Loại hình/hình thức đào tạo: Ban đầu/Trực tiếp | G8: =B8 -> - Loại hình/hình thức đào tạo: Ban đầu/Trực tiếp
B9: - Thời gian: | D9: 18/8/2026 | G9: =B9 -> - Thời gian: | I9: =D9 -> 18/8/2026
B10: - Địa điểm: | D10: VNBA | G10: =B10 -> - Địa điểm: | I10: =D10 -> VNBA
B11: - Giáo viên: | G11: - Số học viên tham dự/tổng số học viên: | K11: =COUNTIF($L$14:$L31,"x")&"/"&COUNTA($L$14:$L31) -> 0/0
B12: STT | C12: Mã NV | D12: Họ tên | E12: Đơn vị | F12: Ghi chú | G12: STT | H12: Mã nhân viên | I12: Họ tên | K12: Đơn vị | L12: Ngày | M12: Ngày | N12: Ngày | O12: Ghi chú
L13: =I9 -> 18/8/2026
B14: =ROW()-13 -> 1 | G14: =B14 -> 1 | H14: =C14 -> 0 | I14: =D14 -> 0 | K14: =E14 -> 0
B15: =ROW()-13 -> 2 | G15: =B15 -> 2 | H15: =C15 -> 0 | I15: =D15 -> 0 | K15: =E15 -> 0
B16: =ROW()-13 -> 3 | G16: =B16 -> 3 | H16: =C16 -> 0 | I16: =D16 -> 0 | K16: =E16 -> 0
B17: =ROW()-13 -> 4 | G17: =B17 -> 4 | H17: =C17 -> 0 | I17: =D17 -> 0 | K17: =E17 -> 0
C18: P.Trưởng Trung tâm đào tạo | F18: Người lập | H18: Chữ ký giáo viên:
G20: Lưu ý:
G21: - Giáo viên điểm danh theo ngày và đánh dấu: X: có mặt; V: vắng mặt
C22: Ngô Trung Thành | F22: Nguyễn Cao Bình | G22: - Trang thiết bị thực hành (áp dụng đối với nội dung thực hành Nghiệp vụ điều khiển/vận hành thiết bị):
G23: …………………………………………………………………………………............................................

Sheet 20
E2: DANH SÁCH HỌC VIÊN | J2: Biểu mẫu | N2: Mã số: V.TMM-F10
J3: ĐIỂM DANH HỌC VIÊN | N3: Ban hành: 04
N4: Hiệu lực: 28/12/2024
N5: Trang: 1/1
B7: - Môn/Khóa học: | G7: - Môn/Khóa học: | I7: =D7 -> 0
A8: . | B8: - Loại hình/hình thức đào tạo: Định kỳ/Trực tiếp | G8: =B8 -> - Loại hình/hình thức đào tạo: Định kỳ/Trực tiếp
B9: - Thời gian: | D9: C20/8/2026 | G9: =B9 -> - Thời gian: | I9: =D9 -> C20/8/2026
B10: - Địa điểm: | D10: TTĐT | G10: =B10 -> - Địa điểm: | I10: =D10 -> TTĐT
B11: - Giáo viên: | G11: - Số học viên tham dự/tổng số học viên: | K11: =COUNTIF($L$14:$L38,"x")&"/"&COUNTA($L$14:$L38) -> 0/0
B12: STT | C12: Mã NV | D12: Họ tên | E12: Đơn vị | F12: Ghi chú | G12: STT | H12: Mã nhân viên | I12: Họ tên | K12: Đơn vị | L12: Ngày | M12: Ngày | N12: Ngày | O12: Ghi chú
L13: =I9 -> C20/8/2026
B14: =ROW()-13 -> 1 | G14: =B14 -> 1 | H14: =C14 -> 0 | I14: =D14 -> 0 | K14: =E14 -> 0
B15: =ROW()-13 -> 2 | G15: =B15 -> 2 | H15: =C15 -> 0 | I15: =D15 -> 0 | K15: =E15 -> 0
B16: =ROW()-13 -> 3 | G16: =B16 -> 3 | H16: =C16 -> 0 | I16: =D16 -> 0 | K16: =E16 -> 0
B17: =ROW()-13 -> 4 | G17: =B17 -> 4 | H17: =C17 -> 0 | I17: =D17 -> 0 | K17: =E17 -> 0
B18: =ROW()-13 -> 5 | G18: =B18 -> 5 | H18: =C18 -> 0 | I18: =D18 -> 0 | K18: =E18 -> 0
B19: =ROW()-13 -> 6 | G19: =B19 -> 6 | H19: =C19 -> 0 | I19: =D19 -> 0 | K19: =E19 -> 0
B20: =ROW()-13 -> 7 | G20: =B20 -> 7 | H20: =C20 -> 0 | I20: =D20 -> 0 | K20: =E20 -> 0
B21: =ROW()-13 -> 8 | G21: =B21 -> 8 | H21: =C21 -> 0 | I21: =D21 -> 0 | K21: =E21 -> 0
B22: =ROW()-13 -> 9 | G22: =B22 -> 9 | H22: =C22 -> 0 | I22: =D22 -> 0 | K22: =E22 -> 0
B23: =ROW()-13 -> 10 | G23: =B23 -> 10 | H23: =C23 -> 0 | I23: =D23 -> 0 | K23: =E23 -> 0
B24: =ROW()-13 -> 11 | G24: =B24 -> 11 | H24: =C24 -> 0 | I24: =D24 -> 0 | K24: =E24 -> 0
C25: P.Trưởng Trung tâm đào tạo | F25: Người lập | H25: Chữ ký giáo viên:
G27: Lưu ý:
G28: - Giáo viên điểm danh theo ngày và đánh dấu: X: có mặt; V: vắng mặt
C29: Ngô Trung Thành | F29: Nguyễn Cao Bình | G29: - Trang thiết bị thực hành (áp dụng đối với nội dung thực hành Nghiệp vụ điều khiển/vận hành thiết bị):
G30: …………………………………………………………………………………............................................

Sheet 21
E2: DANH SÁCH HỌC VIÊN | J2: Biểu mẫu | N2: Mã số: V.TMM-F10
J3: ĐIỂM DANH HỌC VIÊN | N3: Ban hành: 04
N4: Hiệu lực: 28/12/2024
N5: Trang: 1/1
B7: - Môn/Khóa học: | G7: - Môn/Khóa học: | I7: =D7 -> 0
B8: - Loại hình/hình thức đào tạo: Ban đầu/Trực tiếp | G8: =B8 -> - Loại hình/hình thức đào tạo: Ban đầu/Trực tiếp
B9: - Thời gian: | D9: 17/8/2026 | G9: =B9 -> - Thời gian: | I9: =D9 -> 17/8/2026
B10: - Địa điểm: | D10: VNBA | G10: =B10 -> - Địa điểm: | I10: =D10 -> VNBA
B11: - Giáo viên: | G11: - Số học viên tham dự/tổng số học viên: | K11: =COUNTIF($L$14:$L39,"x")&"/"&COUNTA($L$14:$L39) -> 0/0
B12: STT | C12: Mã NV | D12: Họ tên | E12: Đơn vị | F12: Ghi chú | G12: STT | H12: Mã nhân viên | I12: Họ tên | K12: Đơn vị | L12: Ngày | M12: Ngày | N12: Ngày | O12: Ghi chú
L13: =I9 -> 17/8/2026
B14: =ROW()-13 -> 1 | G14: =B14 -> 1 | H14: =C14 -> 0 | I14: =D14 -> 0 | K14: =E14 -> 0
B15: =ROW()-13 -> 2 | G15: =B15 -> 2 | H15: =C15 -> 0 | I15: =D15 -> 0 | K15: =E15 -> 0
B16: =ROW()-13 -> 3 | G16: =B16 -> 3 | H16: =C16 -> 0 | I16: =D16 -> 0 | K16: =E16 -> 0
B17: =ROW()-13 -> 4 | G17: =B17 -> 4 | H17: =C17 -> 0 | I17: =D17 -> 0 | K17: =E17 -> 0
B18: =ROW()-13 -> 5 | G18: =B18 -> 5 | H18: =C18 -> 0 | I18: =D18 -> 0 | K18: =E18 -> 0
B19: =ROW()-13 -> 6 | G19: =B19 -> 6 | H19: =C19 -> 0 | I19: =D19 -> 0 | K19: =E19 -> 0
B20: =ROW()-13 -> 7 | G20: =B20 -> 7 | H20: =C20 -> 0 | I20: =D20 -> 0 | K20: =E20 -> 0
B21: =ROW()-13 -> 8 | G21: =B21 -> 8 | H21: =C21 -> 0 | I21: =D21 -> 0 | K21: =E21 -> 0
B22: =ROW()-13 -> 9 | G22: =B22 -> 9 | H22: =C22 -> 0 | I22: =D22 -> 0 | K22: =E22 -> 0
B23: =ROW()-13 -> 10 | G23: =B23 -> 10 | H23: =C23 -> 0 | I23: =D23 -> 0 | K23: =E23 -> 0
B24: =ROW()-13 -> 11 | G24: =B24 -> 11 | H24: =C24 -> 0 | I24: =D24 -> 0 | K24: =E24 -> 0
B25: =ROW()-13 -> 12 | G25: =B25 -> 12 | H25: =C25 -> 0 | I25: =D25 -> 0 | K25: =E25 -> 0
C26: P.Trưởng Trung tâm đào tạo | F26: Người lập | H26: Chữ ký giáo viên:
G28: Lưu ý:
G29: - Giáo viên điểm danh theo ngày và đánh dấu: X: có mặt; V: vắng mặt
C30: Ngô Trung Thành | F30: Nguyễn Cao Bình | G30: - Trang thiết bị thực hành (áp dụng đối với nội dung thực hành Nghiệp vụ điều khiển/vận hành thiết bị):
G31: …………………………………………………………………………………............................................

Sheet 22
E2: DANH SÁCH HỌC VIÊN | J2: Biểu mẫu | N2: Mã số: V.TMM-F10
J3: ĐIỂM DANH HỌC VIÊN | N3: Ban hành: 04
N4: Hiệu lực: 28/12/2024
N5: Trang: 1/1
B7: - Môn/Khóa học: | G7: - Môn/Khóa học: | I7: =D7 -> 0
B8: - Loại hình/hình thức đào tạo: Định kỳ/Trực tiếp | G8: =B8 -> - Loại hình/hình thức đào tạo: Định kỳ/Trực tiếp
B9: - Thời gian: | D9: 17-19/8/2026 | G9: =B9 -> - Thời gian: | I9: =D9 -> 17-19/8/2026
B10: - Địa điểm: | D10: TTĐT | G10: =B10 -> - Địa điểm: | I10: =D10 -> TTĐT
B11: - Giáo viên: | G11: - Số học viên tham dự/tổng số học viên: | K11: =COUNTIF($L$14:$L38,"x")&"/"&COUNTA($L$14:$L38) -> 0/0
B12: STT | C12: Mã NV | D12: Họ tên | E12: Đơn vị | F12: Ghi chú | G12: STT | H12: Mã nhân viên | I12: Họ tên | K12: Đơn vị | L12: Ngày | M12: Ngày | N12: Ngày | O12: Ghi chú
L13: =I9 -> 17-19/8/2026
B14: =ROW()-13 -> 1 | G14: =B14 -> 1 | H14: =C14 -> 0 | I14: =D14 -> 0 | K14: =E14 -> 0
B15: =ROW()-13 -> 2 | G15: =B15 -> 2 | H15: =C15 -> 0 | I15: =D15 -> 0 | K15: =E15 -> 0
B16: =ROW()-13 -> 3 | G16: =B16 -> 3 | H16: =C16 -> 0 | I16: =D16 -> 0 | K16: =E16 -> 0
B17: =ROW()-13 -> 4 | G17: =B17 -> 4 | H17: =C17 -> 0 | I17: =D17 -> 0 | K17: =E17 -> 0
B18: =ROW()-13 -> 5 | G18: =B18 -> 5 | H18: =C18 -> 0 | I18: =D18 -> 0 | K18: =E18 -> 0
B19: =ROW()-13 -> 6 | G19: =B19 -> 6 | H19: =C19 -> 0 | I19: =D19 -> 0 | K19: =E19 -> 0
B20: =ROW()-13 -> 7 | G20: =B20 -> 7 | H20: =C20 -> 0 | I20: =D20 -> 0 | K20: =E20 -> 0
B21: =ROW()-13 -> 8 | G21: =B21 -> 8 | H21: =C21 -> 0 | I21: =D21 -> 0 | K21: =E21 -> 0
B22: =ROW()-13 -> 9 | G22: =B22 -> 9 | H22: =C22 -> 0 | I22: =D22 -> 0 | K22: =E22 -> 0
B23: =ROW()-13 -> 10 | G23: =B23 -> 10 | H23: =C23 -> 0 | I23: =D23 -> 0 | K23: =E23 -> 0
B24: =ROW()-13 -> 11 | G24: =B24 -> 11 | H24: =C24 -> 0 | I24: =D24 -> 0 | K24: =E24 -> 0
C25: P.Trưởng Trung tâm đào tạo | F25: Người lập | H25: Chữ ký giáo viên:
G27: Lưu ý:
G28: - Giáo viên điểm danh theo ngày và đánh dấu: X: có mặt; V: vắng mặt
C29: Ngô Trung Thành | F29: Nguyễn Cao Bình | G29: - Trang thiết bị thực hành (áp dụng đối với nội dung thực hành Nghiệp vụ điều khiển/vận hành thiết bị):
G30: …………………………………………………………………………………............................................

Sheet 23
E2: DANH SÁCH HỌC VIÊN | J2: Biểu mẫu | N2: Mã số: V.TMM-F10
J3: ĐIỂM DANH HỌC VIÊN | N3: Ban hành: 04
N4: Hiệu lực: 28/12/2024
N5: Trang: 1/1
B7: - Môn/Khóa học: | G7: - Môn/Khóa học: | I7: =D7 -> 0
B8: - Loại hình/hình thức đào tạo: Bồi dưỡng KT/Trực tiếp | G8: =B8 -> - Loại hình/hình thức đào tạo: Bồi dưỡng KT/Trực tiếp
B9: - Thời gian: | D9: 20-S21/8/2026 | G9: =B9 -> - Thời gian: | I9: =D9 -> 20-S21/8/2026
B10: - Địa điểm: | D10: TTĐT | G10: =B10 -> - Địa điểm: | I10: =D10 -> TTĐT
B11: - Giáo viên: | G11: - Số học viên tham dự/tổng số học viên: | K11: =COUNTIF($L$14:$L47,"x")&"/"&COUNTA($L$14:$L47) -> 0/0
B12: STT | C12: Mã NV | D12: Họ tên | E12: Đơn vị | F12: Ghi chú | G12: STT | H12: Mã nhân viên | I12: Họ tên | K12: Đơn vị | L12: Ngày | M12: Ngày | N12: Ngày | O12: Ghi chú
L13: =I9 -> 20-S21/8/2026
B14: =ROW()-13 -> 1 | G14: =B14 -> 1 | H14: =C14 -> 0 | I14: =D14 -> 0 | K14: =E14 -> 0
B15: =ROW()-13 -> 2 | G15: =B15 -> 2 | H15: =C15 -> 0 | I15: =D15 -> 0 | K15: =E15 -> 0
B16: =ROW()-13 -> 3 | G16: =B16 -> 3 | H16: =C16 -> 0 | I16: =D16 -> 0 | K16: =E16 -> 0
B17: =ROW()-13 -> 4 | G17: =B17 -> 4 | H17: =C17 -> 0 | I17: =D17 -> 0 | K17: =E17 -> 0
B18: =ROW()-13 -> 5 | G18: =B18 -> 5 | H18: =C18 -> 0 | I18: =D18 -> 0 | K18: =E18 -> 0
B19: =ROW()-13 -> 6 | G19: =B19 -> 6 | H19: =C19 -> 0 | I19: =D19 -> 0 | K19: =E19 -> 0
B20: =ROW()-13 -> 7 | G20: =B20 -> 7 | H20: =C20 -> 0 | I20: =D20 -> 0 | K20: =E20 -> 0
B21: =ROW()-13 -> 8 | G21: =B21 -> 8 | H21: =C21 -> 0 | I21: =D21 -> 0 | K21: =E21 -> 0
B22: =ROW()-13 -> 9 | G22: =B22 -> 9 | H22: =C22 -> 0 | I22: =D22 -> 0 | K22: =E22 -> 0
B23: =ROW()-13 -> 10 | G23: =B23 -> 10 | H23: =C23 -> 0 | I23: =D23 -> 0 | K23: =E23 -> 0
B24: =ROW()-13 -> 11 | G24: =B24 -> 11 | H24: =C24 -> 0 | I24: =D24 -> 0 | K24: =E24 -> 0
B25: =ROW()-13 -> 12 | G25: =B25 -> 12 | H25: =C25 -> 0 | I25: =D25 -> 0 | K25: =E25 -> 0
... B33: =ROW()-13 -> 20 | G33: =B33 -> 20 | H33: =C33 -> 0 | I33: =D33 -> 0 | K33: =E33 -> 0
C34: P.Trưởng Trung tâm đào tạo | F34: Người lập | H34: Chữ ký giáo viên:
G36: Lưu ý:
G37: - Giáo viên điểm danh theo ngày và đánh dấu: X: có mặt; V: vắng mặt
C38: Ngô Trung Thành | F38: Nguyễn Cao Bình | G38: - Trang thiết bị thực hành (áp dụng đối với nội dung thực hành Nghiệp vụ điều khiển/vận hành thiết bị):
G39: …………………………………………………………………………………............................................

Sheet 24
E2: DANH SÁCH HỌC VIÊN | J2: Biểu mẫu | N2: Mã số: V.TMM-F10
J3: ĐIỂM DANH HỌC VIÊN | N3: Ban hành: 04
N4: Hiệu lực: 28/12/2024
N5: Trang: 1/1
B7: - Môn/Khóa học: | G7: - Môn/Khóa học: | I7: =D7 -> 0
B8: - Loại hình/hình thức đào tạo: Định kỳ/Elearning+Trực tiếp | G8: =B8 -> - Loại hình/hình thức đào tạo: Định kỳ/Elearning+Trực tiếp
B9: - Thời gian: | D9: S18/8/2026 | G9: =B9 -> - Thời gian: | I9: =D9 -> S18/8/2026
B10: - Địa điểm: | D10: TTĐT | G10: =B10 -> - Địa điểm: | I10: =D10 -> TTĐT
B11: - Giáo viên: | G11: - Số học viên tham dự/tổng số học viên: | K11: =COUNTIF($L$14:$L47,"x")&"/"&COUNTA($L$14:$L47) -> 0/0
B12: STT | C12: Mã NV | D12: Họ tên | E12: Đơn vị | F12: Ghi chú | G12: STT | H12: Mã nhân viên | I12: Họ tên | K12: Đơn vị | L12: Ngày | M12: Ngày | N12: Ngày | O12: Ghi chú
L13: =I9 -> S18/8/2026
B14: =ROW()-13 -> 1 | G14: =B14 -> 1 | H14: =C14 -> 0 | I14: =D14 -> 0 | K14: =E14 -> 0
B15: =ROW()-13 -> 2 | G15: =B15 -> 2 | H15: =C15 -> 0 | I15: =D15 -> 0 | K15: =E15 -> 0
B16: =ROW()-13 -> 3 | G16: =B16 -> 3 | H16: =C16 -> 0 | I16: =D16 -> 0 | K16: =E16 -> 0
B17: =ROW()-13 -> 4 | G17: =B17 -> 4 | H17: =C17 -> 0 | I17: =D17 -> 0 | K17: =E17 -> 0
B18: =ROW()-13 -> 5 | G18: =B18 -> 5 | H18: =C18 -> 0 | I18: =D18 -> 0 | K18: =E18 -> 0
B19: =ROW()-13 -> 6 | G19: =B19 -> 6 | H19: =C19 -> 0 | I19: =D19 -> 0 | K19: =E19 -> 0
B20: =ROW()-13 -> 7 | G20: =B20 -> 7 | H20: =C20 -> 0 | I20: =D20 -> 0 | K20: =E20 -> 0
B21: =ROW()-13 -> 8 | G21: =B21 -> 8 | H21: =C21 -> 0 | I21: =D21 -> 0 | K21: =E21 -> 0
B22: =ROW()-13 -> 9 | G22: =B22 -> 9 | H22: =C22 -> 0 | I22: =D22 -> 0 | K22: =E22 -> 0
B23: =ROW()-13 -> 10 | G23: =B23 -> 10 | H23: =C23 -> 0 | I23: =D23 -> 0 | K23: =E23 -> 0
B24: =ROW()-13 -> 11 | G24: =B24 -> 11 | H24: =C24 -> 0 | I24: =D24 -> 0 | K24: =E24 -> 0
B25: =ROW()-13 -> 12 | G25: =B25 -> 12 | H25: =C25 -> 0 | I25: =D25 -> 0 | K25: =E25 -> 0
... B33: =ROW()-13 -> 20 | G33: =B33 -> 20 | H33: =C33 -> 0 | I33: =D33 -> 0 | K33: =E33 -> 0
C34: P.Trưởng Trung tâm đào tạo | F34: Người lập | H34: Chữ ký giáo viên:
G36: Lưu ý:
G37: - Giáo viên điểm danh theo ngày và đánh dấu: X: có mặt; V: vắng mặt
C38: Ngô Trung Thành | F38: Nguyễn Cao Bình | G38: - Trang thiết bị thực hành (áp dụng đối với nội dung thực hành Nghiệp vụ điều khiển/vận hành thiết bị):
G39: …………………………………………………………………………………............................................

Sheet 25
E2: DANH SÁCH HỌC VIÊN | J2: Biểu mẫu | N2: Mã số: V.TMM-F10
J3: ĐIỂM DANH HỌC VIÊN | N3: Ban hành: 04
N4: Hiệu lực: 28/12/2024
N5: Trang: 1/1
B7: - Môn/Khóa học: | G7: - Môn/Khóa học: | I7: =D7 -> 0
B8: - Loại hình/hình thức đào tạo: Định kỳ/Elearning+Trực tiếp | G8: =B8 -> - Loại hình/hình thức đào tạo: Định kỳ/Elearning+Trực tiếp
B9: - Thời gian: | D9: C18/8/2026 | G9: =B9 -> - Thời gian: | I9: =D9 -> C18/8/2026
B10: - Địa điểm: | D10: TTĐT | G10: =B10 -> - Địa điểm: | I10: =D10 -> TTĐT
B11: - Giáo viên: | G11: - Số học viên tham dự/tổng số học viên: | K11: =COUNTIF($L$14:$L47,"x")&"/"&COUNTA($L$14:$L47) -> 0/0
B12: STT | C12: Mã NV | D12: Họ tên | E12: Đơn vị | F12: Ghi chú | G12: STT | H12: Mã nhân viên | I12: Họ tên | K12: Đơn vị | L12: Ngày | M12: Ngày | N12: Ngày | O12: Ghi chú
L13: =I9 -> C18/8/2026
B14: =ROW()-13 -> 1 | G14: =B14 -> 1 | H14: =C14 -> 0 | I14: =D14 -> 0 | K14: =E14 -> 0
B15: =ROW()-13 -> 2 | G15: =B15 -> 2 | H15: =C15 -> 0 | I15: =D15 -> 0 | K15: =E15 -> 0
B16: =ROW()-13 -> 3 | G16: =B16 -> 3 | H16: =C16 -> 0 | I16: =D16 -> 0 | K16: =E16 -> 0
B17: =ROW()-13 -> 4 | G17: =B17 -> 4 | H17: =C17 -> 0 | I17: =D17 -> 0 | K17: =E17 -> 0
B18: =ROW()-13 -> 5 | G18: =B18 -> 5 | H18: =C18 -> 0 | I18: =D18 -> 0 | K18: =E18 -> 0
B19: =ROW()-13 -> 6 | G19: =B19 -> 6 | H19: =C19 -> 0 | I19: =D19 -> 0 | K19: =E19 -> 0
B20: =ROW()-13 -> 7 | G20: =B20 -> 7 | H20: =C20 -> 0 | I20: =D20 -> 0 | K20: =E20 -> 0
B21: =ROW()-13 -> 8 | G21: =B21 -> 8 | H21: =C21 -> 0 | I21: =D21 -> 0 | K21: =E21 -> 0
B22: =ROW()-13 -> 9 | G22: =B22 -> 9 | H22: =C22 -> 0 | I22: =D22 -> 0 | K22: =E22 -> 0
B23: =ROW()-13 -> 10 | G23: =B23 -> 10 | H23: =C23 -> 0 | I23: =D23 -> 0 | K23: =E23 -> 0
B24: =ROW()-13 -> 11 | G24: =B24 -> 11 | H24: =C24 -> 0 | I24: =D24 -> 0 | K24: =E24 -> 0
B25: =ROW()-13 -> 12 | G25: =B25 -> 12 | H25: =C25 -> 0 | I25: =D25 -> 0 | K25: =E25 -> 0
... B33: =ROW()-13 -> 20 | G33: =B33 -> 20 | H33: =C33 -> 0 | I33: =D33 -> 0 | K33: =E33 -> 0
C34: P.Trưởng Trung tâm đào tạo | F34: Người lập | H34: Chữ ký giáo viên:
G36: Lưu ý:
G37: - Giáo viên điểm danh theo ngày và đánh dấu: X: có mặt; V: vắng mặt
C38: Ngô Trung Thành | F38: Nguyễn Cao Bình | G38: - Trang thiết bị thực hành (áp dụng đối với nội dung thực hành Nghiệp vụ điều khiển/vận hành thiết bị):
G39: …………………………………………………………………………………............................................

Sheet 26
E2: DANH SÁCH HỌC VIÊN | J2: Biểu mẫu | N2: Mã số: V.TMM-F10
J3: ĐIỂM DANH HỌC VIÊN | N3: Ban hành: 04
N4: Hiệu lực: 28/12/2024
N5: Trang: 1/1
B7: - Môn/Khóa học: | G7: - Môn/Khóa học: | I7: =D7 -> 0
B8: - Loại hình/hình thức đào tạo: Bồi dưỡng KT/Trực tiếp | G8: =B8 -> - Loại hình/hình thức đào tạo: Bồi dưỡng KT/Trực tiếp
B9: - Thời gian: | D9: 20-S21/8/2026 | G9: =B9 -> - Thời gian: | I9: =D9 -> 20-S21/8/2026
B10: - Địa điểm: | D10: VNBA | G10: =B10 -> - Địa điểm: | I10: =D10 -> VNBA
B11: - Giáo viên: | G11: - Số học viên tham dự/tổng số học viên: | K11: =COUNTIF($L$14:$L35,"x")&"/"&COUNTA($L$14:$L35) -> 0/0
B12: STT | C12: Mã NV | D12: Họ tên | E12: Đơn vị | F12: Ghi chú | G12: STT | H12: Mã nhân viên | I12: Họ tên | K12: Đơn vị | L12: Ngày | M12: Ngày | N12: Ngày | O12: Ghi chú
L13: =I9 -> 20-S21/8/2026
B14: =ROW()-13 -> 1 | G14: =B14 -> 1 | H14: =C14 -> 0 | I14: =D14 -> 0 | K14: =E14 -> 0
B15: =ROW()-13 -> 2 | G15: =B15 -> 2 | H15: =C15 -> 0 | I15: =D15 -> 0 | K15: =E15 -> 0
B16: =ROW()-13 -> 3 | G16: =B16 -> 3 | H16: =C16 -> 0 | I16: =D16 -> 0 | K16: =E16 -> 0
B17: =ROW()-13 -> 4 | G17: =B17 -> 4 | H17: =C17 -> 0 | I17: =D17 -> 0 | K17: =E17 -> 0
B18: =ROW()-13 -> 5 | G18: =B18 -> 5 | H18: =C18 -> 0 | I18: =D18 -> 0 | K18: =E18 -> 0
